{
    "registryname":"fanqing",
    "localizedname":"反氢",
    "color":"000000",
    "parts": [
        {
            "x": 0,
            "y": 0,
            "z": 0,
            "elements": [
                "modularcontroller:fanqing_controller"
            ]
        },
        {
            "x": 16,
            "y": 1,
            "z": 17,

            "elements": [
                "qmd:accelerator_casing@0"
            ]
        },
        {
            "x": -30,
            "y": 4,
            "z": 34,

            "elements": [
                "qmd:particle_chamber_detector@4"
            ]
        },
        {
            "x": 17,
            "y": 1,
            "z": 17,

            "elements": [
                "qmd:accelerator_casing@0"
            ]
        },
        {
            "x": -29,
            "y": 4,
            "z": 34,

            "elements": [
                "qmd:particle_chamber_glass@0"
            ]
        },
        {
            "x": 18,
            "y": 1,
            "z": 17,

            "elements": [
                "qmd:accelerator_casing@0"
            ]
        },
        {
            "x": 19,
            "y": 1,
            "z": 17,

            "elements": [
                "qmd:accelerator_casing@0"
            ]
        },
        {
            "x": 20,
            "y": 1,
            "z": 17,

            "elements": [
                "qmd:accelerator_casing@0"
            ]
        },
        {
            "x": 21,
            "y": 1,
            "z": 17,

            "elements": [
                "qmd:accelerator_casing@0"
            ]
        },
        {
            "x": -10,
            "y": 2,
            "z": 17,

            "elements": [
                "qmd:accelerator_glass@0"
            ]
        },
        {
            "x": 22,
            "y": 1,
            "z": 17,

            "elements": [
                "qmd:accelerator_casing@0"
            ]
        },
        {
            "x": -9,
            "y": 2,
            "z": 17,

            "elements": [
                "qmd:accelerator_yoke@0"
            ]
        },
        {
            "x": 23,
            "y": 1,
            "z": 17,

            "elements": [
                "qmd:accelerator_casing@0"
            ]
        },
        {
            "x": -8,
            "y": 2,
            "z": 17,

            "elements": [
                "qmd:accelerator_yoke@0"
            ]
        },
        {
            "x": -23,
            "y": 4,
            "z": 34,

            "elements": [
                "qmd:accelerator_glass@0"
            ]
        },
        {
            "x": 23,
            "y": -1,
            "z": 0,

            "elements": [
                "qmd:particle_chamber_casing@1"
            ]
        },
        {
            "x": 24,
            "y": 1,
            "z": 17,

            "elements": [
                "qmd:accelerator_casing@0"
            ]
        },
        {
            "x": -7,
            "y": 2,
            "z": 17,

            "elements": [
                "qmd:accelerator_yoke@0"
            ]
        },
        {
            "x": 22,
            "y": -1,
            "z": 0,

            "elements": [
                "qmd:particle_chamber_casing@1"
            ]
        },
        {
            "x": 25,
            "y": 1,
            "z": 17,

            "elements": [
                "qmd:accelerator_casing@0"
            ]
        },
        {
            "x": -6,
            "y": 2,
            "z": 17,

            "elements": [
                "qmd:accelerator_cooler1@7"
            ]
        },
        {
            "x": 21,
            "y": -1,
            "z": 0,

            "elements": [
                "qmd:particle_chamber_casing@1"
            ]
        },
        {
            "x": 26,
            "y": 1,
            "z": 17,

            "elements": [
                "qmd:accelerator_casing@0"
            ]
        },
        {
            "x": -5,
            "y": 2,
            "z": 17,

            "elements": [
                "qmd:accelerator_cooler1@8"
            ]
        },
        {
            "x": 20,
            "y": -1,
            "z": 0,

            "elements": [
                "qmd:particle_chamber_casing@1"
            ]
        },
        {
            "x": 27,
            "y": 1,
            "z": 17,

            "elements": [
                "qmd:accelerator_casing@0"
            ]
        },
        {
            "x": -4,
            "y": 2,
            "z": 17,

            "elements": [
                "qmd:accelerator_cooler1@13"
            ]
        },
        {
            "x": -35,
            "y": 3,
            "z": 17,

            "elements": [
                "qmd:accelerator_glass@0"
            ]
        },
        {
            "x": -19,
            "y": 4,
            "z": 34,

            "elements": [
                "qmd:accelerator_glass@0"
            ]
        },
        {
            "x": 19,
            "y": -1,
            "z": 0,

            "elements": [
                "qmd:particle_chamber_casing@1"
            ]
        },
        {
            "x": 28,
            "y": 1,
            "z": 17,

            "elements": [
                "qmd:accelerator_casing@0"
            ]
        },
        {
            "x": -3,
            "y": 2,
            "z": 17,

            "elements": [
                "qmd:accelerator_cooler1@9"
            ]
        },
        {
            "x": -34,
            "y": 3,
            "z": 17,

            "elements": [
                "qmd:accelerator_cooler1@0"
            ]
        },
        {
            "x": 18,
            "y": -1,
            "z": 0,

            "elements": [
                "qmd:particle_chamber_casing@1"
            ]
        },
        {
            "x": 29,
            "y": 1,
            "z": 17,

            "elements": [
                "qmd:accelerator_casing@1"
            ]
        },
        {
            "x": -2,
            "y": 2,
            "z": 17,

            "elements": [
                "qmd:accelerator_cavity@0"
            ]
        },
        {
            "x": -33,
            "y": 3,
            "z": 17,

            "elements": [
                "qmd:accelerator_beam@0"
            ]
        },
        {
            "x": 17,
            "y": -1,
            "z": 0,

            "elements": [
                "qmd:particle_chamber_casing@1"
            ]
        },
        {
            "x": -1,
            "y": 2,
            "z": 17,

            "elements": [
                "qmd:accelerator_cooler1@0"
            ]
        },
        {
            "x": -32,
            "y": 3,
            "z": 17,

            "elements": [
                "qmd:accelerator_cooler1@0"
            ]
        },
        {
            "x": 16,
            "y": -1,
            "z": 0,

            "elements": [
                "qmd:particle_chamber_casing@1"
            ]
        },
        {
            "x": 0,
            "y": 2,
            "z": 17,

            "elements": [
                "qmd:accelerator_cooler1@9"
            ]
        },
        {
            "x": -31,
            "y": 3,
            "z": 17,

            "elements": [
                "qmd:accelerator_glass@0"
            ]
        },
        {
            "x": 15,
            "y": -1,
            "z": 0,

            "elements": [
                "qmd:particle_chamber_casing@1"
            ]
        },
        {
            "x": 15,
            "y": 0,
            "z": 0,

            "elements": [
                "qmd:particle_chamber_glass@0"
            ]
        },
        {
            "x": 1,
            "y": 2,
            "z": 17,

            "elements": [
                "qmd:accelerator_cooler1@0"
            ]
        },
        {
            "x": 16,
            "y": 0,
            "z": 0,

            "elements": [
                "qmd:particle_chamber_glass@0"
            ]
        },
        {
            "x": 2,
            "y": 2,
            "z": 17,

            "elements": [
                "qmd:accelerator_cavity@0"
            ]
        },
        {
            "x": 17,
            "y": 0,
            "z": 0,

            "elements": [
                "qmd:particle_chamber_glass@0"
            ]
        },
        {
            "x": 3,
            "y": 2,
            "z": 17,

            "elements": [
                "qmd:accelerator_cooler1@9"
            ]
        },
        {
            "x": 18,
            "y": 0,
            "z": 0,

            "elements": [
                "qmd:particle_chamber_glass@0"
            ]
        },
        {
            "x": 4,
            "y": 2,
            "z": 17,

            "elements": [
                "qmd:accelerator_cooler1@13"
            ]
        },
        {
            "x": -11,
            "y": 4,
            "z": 34,

            "elements": [
                "qmd:accelerator_glass@0"
            ]
        },
        {
            "x": 19,
            "y": 0,
            "z": 0,

            "elements": [
                "qmd:particle_chamber_glass@0"
            ]
        },
        {
            "x": 5,
            "y": 2,
            "z": 17,

            "elements": [
                "qmd:accelerator_cooler1@8"
            ]
        },
        {
            "x": 20,
            "y": 0,
            "z": 0,

            "elements": [
                "qmd:particle_chamber_glass@0"
            ]
        },
        {
            "x": -10,
            "y": 1,
            "z": 0,

            "elements": [
                "qmd:accelerator_casing@1"
            ]
        },
        {
            "x": 6,
            "y": 2,
            "z": 17,

            "elements": [
                "qmd:accelerator_cooler1@7"
            ]
        },
        {
            "x": 21,
            "y": 0,
            "z": 0,

            "elements": [
                "qmd:particle_chamber_glass@0"
            ]
        },
        {
            "x": -9,
            "y": 1,
            "z": 0,

            "elements": [
                "qmd:accelerator_casing@1"
            ]
        },
        {
            "x": 7,
            "y": 2,
            "z": 17,

            "elements": [
                "qmd:accelerator_yoke@0"
            ]
        },
        {
            "x": 22,
            "y": 0,
            "z": 0,

            "elements": [
                "qmd:particle_chamber_glass@0"
            ]
        },
        {
            "x": -8,
            "y": 1,
            "z": 0,

            "elements": [
                "qmd:accelerator_casing@1"
            ]
        },
        {
            "x": 8,
            "y": 2,
            "z": 17,

            "elements": [
                "qmd:accelerator_yoke@0"
            ]
        },
        {
            "x": -7,
            "y": 4,
            "z": 34,

            "elements": [
                "qmd:accelerator_glass@0"
            ]
        },
        {
            "x": 23,
            "y": 0,
            "z": 0,

            "elements": [
                "qmd:particle_chamber_glass@0"
            ]
        },
        {
            "x": -7,
            "y": 1,
            "z": 0,

            "elements": [
                "qmd:accelerator_casing@1"
            ]
        },
        {
            "x": 9,
            "y": 2,
            "z": 17,

            "elements": [
                "qmd:accelerator_yoke@0"
            ]
        },
        {
            "x": -37,
            "y": 5,
            "z": 34,

            "elements": [
                "qmd:particle_chamber_glass@0"
            ]
        },
        {
            "x": -6,
            "y": 1,
            "z": 0,

            "elements": [
                "qmd:accelerator_casing@1"
            ]
        },
        {
            "x": 10,
            "y": 2,
            "z": 17,

            "elements": [
                "qmd:accelerator_glass@0"
            ]
        },
        {
            "x": -5,
            "y": 1,
            "z": 0,

            "elements": [
                "qmd:accelerator_casing@1"
            ]
        },
        {
            "x": -35,
            "y": 5,
            "z": 34,

            "elements": [
                "qmd:particle_chamber_detector@4"
            ]
        },
        {
            "x": -4,
            "y": 1,
            "z": 0,

            "elements": [
                "qmd:accelerator_casing@1"
            ]
        },
        {
            "x": -34,
            "y": 5,
            "z": 34,

            "elements": [
                "qmd:particle_chamber_detector@3"
            ]
        },
        {
            "x": -3,
            "y": 1,
            "z": 0,

            "elements": [
                "qmd:accelerator_casing@1"
            ]
        },
        {
            "x": 13,
            "y": 2,
            "z": 17,

            "elements": [
                "qmd:accelerator_glass@0"
            ]
        },
        {
            "x": -33,
            "y": 5,
            "z": 34,

            "elements": [
                "qmd:particle_chamber_detector@2"
            ]
        },
        {
            "x": -2,
            "y": 1,
            "z": 0,

            "elements": [
                "qmd:accelerator_casing@1"
            ]
        },
        {
            "x": 14,
            "y": 2,
            "z": 17,

            "elements": [
                "qmd:accelerator_yoke@0"
            ]
        },
        {
            "x": -32,
            "y": 5,
            "z": 34,

            "elements": [
                "qmd:particle_chamber_detector@3"
            ]
        },
        {
            "x": -1,
            "y": 1,
            "z": 0,

            "elements": [
                "qmd:accelerator_casing@1"
            ]
        },
        {
            "x": 15,
            "y": 2,
            "z": 17,

            "elements": [
                "qmd:accelerator_yoke@0"
            ]
        },
        {
            "x": -31,
            "y": 5,
            "z": 34,

            "elements": [
                "qmd:particle_chamber_detector@4"
            ]
        },
        {
            "x": 0,
            "y": 1,
            "z": 0,

            "elements": [
                "qmd:accelerator_casing@1"
            ]
        },
        {
            "x": 0,
            "y": 0,
            "z": 0,

            "elements": [
                "modularmachinery:blockcontroller@2"
            ]
        },
        {
            "x": 16,
            "y": 2,
            "z": 17,

            "elements": [
                "qmd:accelerator_yoke@0"
            ]
        },
        {
            "x": 1,
            "y": 1,
            "z": 0,

            "elements": [
                "qmd:accelerator_casing@1"
            ]
        },
        {
            "x": 17,
            "y": 2,
            "z": 17,

            "elements": [
                "qmd:accelerator_cooler2@0"
            ]
        },
        {
            "x": -29,
            "y": 5,
            "z": 34,

            "elements": [
                "qmd:particle_chamber_glass@0"
            ]
        },
        {
            "x": 2,
            "y": 1,
            "z": 0,

            "elements": [
                "qmd:accelerator_casing@1"
            ]
        },
        {
            "x": 18,
            "y": 2,
            "z": 17,

            "elements": [
                "qmd:accelerator_cooler1@1"
            ]
        },
        {
            "x": 3,
            "y": 1,
            "z": 0,

            "elements": [
                "qmd:accelerator_casing@1"
            ]
        },
        {
            "x": 19,
            "y": 2,
            "z": 17,

            "elements": [
                "qmd:accelerator_cooler1@8"
            ]
        },
        {
            "x": 4,
            "y": 1,
            "z": 0,

            "elements": [
                "qmd:accelerator_casing@1"
            ]
        },
        {
            "x": 20,
            "y": 2,
            "z": 17,

            "elements": [
                "qmd:accelerator_cooler1@9"
            ]
        },
        {
            "x": 5,
            "y": 1,
            "z": 0,

            "elements": [
                "qmd:accelerator_casing@1"
            ]
        },
        {
            "x": 21,
            "y": 2,
            "z": 17,

            "elements": [
                "qmd:accelerator_cavity@0"
            ]
        },
        {
            "x": -10,
            "y": 3,
            "z": 17,

            "elements": [
                "qmd:accelerator_glass@0"
            ]
        },
        {
            "x": 6,
            "y": 1,
            "z": 0,

            "elements": [
                "qmd:accelerator_casing@1"
            ]
        },
        {
            "x": 22,
            "y": 2,
            "z": 17,

            "elements": [
                "qmd:accelerator_cooler1@9"
            ]
        },
        {
            "x": -9,
            "y": 3,
            "z": 17,

            "elements": [
                "qmd:accelerator_yoke@0"
            ]
        },
        {
            "x": 7,
            "y": 1,
            "z": 0,

            "elements": [
                "qmd:accelerator_casing@1"
            ]
        },
        {
            "x": 23,
            "y": 2,
            "z": 17,

            "elements": [
                "qmd:accelerator_cooler1@8"
            ]
        },
        {
            "x": -8,
            "y": 3,
            "z": 17,

            "elements": [
                "qmd:accelerator_beam@0"
            ]
        },
        {
            "x": -23,
            "y": 5,
            "z": 34,

            "elements": [
                "qmd:accelerator_glass@0"
            ]
        },
        {
            "x": 8,
            "y": 1,
            "z": 0,

            "elements": [
                "qmd:accelerator_casing@1"
            ]
        },
        {
            "x": 24,
            "y": 2,
            "z": 17,

            "elements": [
                "qmd:accelerator_cooler1@1"
            ]
        },
        {
            "x": -7,
            "y": 3,
            "z": 17,

            "elements": [
                "qmd:accelerator_yoke@0"
            ]
        },
        {
            "x": -22,
            "y": 5,
            "z": 34,

            "elements": [
                "qmd:accelerator_glass@0"
            ]
        },
        {
            "x": 9,
            "y": 1,
            "z": 0,

            "elements": [
                "qmd:accelerator_casing@1"
            ]
        },
        {
            "x": 25,
            "y": 2,
            "z": 17,

            "elements": [
                "qmd:accelerator_cooler2@0"
            ]
        },
        {
            "x": -6,
            "y": 3,
            "z": 17,

            "elements": [
                "qmd:accelerator_magnet@2"
            ]
        },
        {
            "x": -21,
            "y": 5,
            "z": 34,

            "elements": [
                "qmd:accelerator_glass@0"
            ]
        },
        {
            "x": 10,
            "y": 1,
            "z": 0,

            "elements": [
                "qmd:accelerator_casing@1"
            ]
        },
        {
            "x": 26,
            "y": 2,
            "z": 17,

            "elements": [
                "qmd:accelerator_yoke@0"
            ]
        },
        {
            "x": -5,
            "y": 3,
            "z": 17,

            "elements": [
                "qmd:accelerator_cooler1@1"
            ]
        },
        {
            "x": -20,
            "y": 5,
            "z": 34,

            "elements": [
                "qmd:accelerator_glass@0"
            ]
        },
        {
            "x": 27,
            "y": 2,
            "z": 17,

            "elements": [
                "qmd:accelerator_yoke@0"
            ]
        },
        {
            "x": -4,
            "y": 3,
            "z": 17,

            "elements": [
                "qmd:accelerator_cooler1@15"
            ]
        },
        {
            "x": -35,
            "y": 4,
            "z": 17,

            "elements": [
                "qmd:accelerator_glass@0"
            ]
        },
        {
            "x": -19,
            "y": 5,
            "z": 34,

            "elements": [
                "qmd:accelerator_glass@0"
            ]
        },
        {
            "x": 28,
            "y": 2,
            "z": 17,

            "elements": [
                "qmd:accelerator_yoke@0"
            ]
        },
        {
            "x": -3,
            "y": 3,
            "z": 17,

            "elements": [
                "qmd:accelerator_cooler1@0"
            ]
        },
        {
            "x": -34,
            "y": 4,
            "z": 17,

            "elements": [
                "qmd:accelerator_cooler1@9"
            ]
        },
        {
            "x": 29,
            "y": 2,
            "z": 17,

            "elements": [
                "qmd:accelerator_glass@0"
            ]
        },
        {
            "x": -2,
            "y": 3,
            "z": 17,

            "elements": [
                "qmd:accelerator_cavity@0"
            ]
        },
        {
            "x": -33,
            "y": 4,
            "z": 17,

            "elements": [
                "qmd:accelerator_cooler1@0"
            ]
        },
        {
            "x": -1,
            "y": 3,
            "z": 17,

            "elements": [
                "qmd:accelerator_cooler1@0"
            ]
        },
        {
            "x": -32,
            "y": 4,
            "z": 17,

            "elements": [
                "qmd:accelerator_cooler1@9"
            ]
        },
        {
            "x": 15,
            "y": 1,
            "z": 0,

            "elements": [
                "qmd:particle_chamber_glass@0"
            ]
        },
        {
            "x": 0,
            "y": 3,
            "z": 17,

            "elements": [
                "qmd:accelerator_cooler1@9"
            ]
        },
        {
            "x": -31,
            "y": 4,
            "z": 17,

            "elements": [
                "qmd:accelerator_glass@0"
            ]
        },
        {
            "x": 16,
            "y": 1,
            "z": 0,

            "elements": [
                "qmd:particle_chamber_glass@0"
            ]
        },
        {
            "x": 1,
            "y": 3,
            "z": 17,

            "elements": [
                "qmd:accelerator_cooler1@0"
            ]
        },
        {
            "x": 17,
            "y": 1,
            "z": 0,

            "elements": [
                "qmd:particle_chamber_glass@0"
            ]
        },
        {
            "x": 2,
            "y": 3,
            "z": 17,

            "elements": [
                "qmd:accelerator_cavity@0"
            ]
        },
        {
            "x": 18,
            "y": 1,
            "z": 0,

            "elements": [
                "qmd:particle_chamber_glass@0"
            ]
        },
        {
            "x": 3,
            "y": 3,
            "z": 17,

            "elements": [
                "qmd:accelerator_cooler1@0"
            ]
        },
        {
            "x": 19,
            "y": 1,
            "z": 0,

            "elements": [
                "qmd:particle_chamber_glass@0"
            ]
        },
        {
            "x": 4,
            "y": 3,
            "z": 17,

            "elements": [
                "qmd:accelerator_cooler1@15"
            ]
        },
        {
            "x": -11,
            "y": 5,
            "z": 34,

            "elements": [
                "qmd:accelerator_glass@0"
            ]
        },
        {
            "x": 20,
            "y": 1,
            "z": 0,

            "elements": [
                "qmd:particle_chamber_glass@0"
            ]
        },
        {
            "x": 5,
            "y": 3,
            "z": 17,

            "elements": [
                "qmd:accelerator_cooler1@1"
            ]
        },
        {
            "x": -10,
            "y": 5,
            "z": 34,

            "elements": [
                "qmd:accelerator_glass@0"
            ]
        },
        {
            "x": 21,
            "y": 1,
            "z": 0,

            "elements": [
                "qmd:particle_chamber_glass@0"
            ]
        },
        {
            "x": -10,
            "y": 2,
            "z": 0,

            "elements": [
                "qmd:accelerator_glass@0"
            ]
        },
        {
            "x": 6,
            "y": 3,
            "z": 17,

            "elements": [
                "qmd:accelerator_magnet@0"
            ]
        },
        {
            "x": -9,
            "y": 5,
            "z": 34,

            "elements": [
                "qmd:accelerator_glass@0"
            ]
        },
        {
            "x": 22,
            "y": 1,
            "z": 0,

            "elements": [
                "qmd:particle_chamber_glass@0"
            ]
        },
        {
            "x": -9,
            "y": 2,
            "z": 0,

            "elements": [
                "qmd:accelerator_glass@0"
            ]
        },
        {
            "x": 7,
            "y": 3,
            "z": 17,

            "elements": [
                "qmd:accelerator_yoke@0"
            ]
        },
        {
            "x": -8,
            "y": 5,
            "z": 34,

            "elements": [
                "qmd:accelerator_glass@0"
            ]
        },
        {
            "x": 23,
            "y": 1,
            "z": 0,

            "elements": [
                "qmd:particle_chamber_glass@0"
            ]
        },
        {
            "x": -8,
            "y": 2,
            "z": 0,

            "elements": [
                "qmd:accelerator_glass@0"
            ]
        },
        {
            "x": 8,
            "y": 3,
            "z": 17,

            "elements": [
                "qmd:accelerator_beam@0"
            ]
        },
        {
            "x": -7,
            "y": 5,
            "z": 34,

            "elements": [
                "qmd:accelerator_glass@0"
            ]
        },
        {
            "x": -7,
            "y": 2,
            "z": 0,

            "elements": [
                "qmd:accelerator_glass@0"
            ]
        },
        {
            "x": 9,
            "y": 3,
            "z": 17,

            "elements": [
                "qmd:accelerator_yoke@0"
            ]
        },
        {
            "x": -37,
            "y": 6,
            "z": 34,

            "elements": [
                "qmd:particle_chamber_glass@0"
            ]
        },
        {
            "x": -6,
            "y": 2,
            "z": 0,

            "elements": [
                "qmd:accelerator_glass@0"
            ]
        },
        {
            "x": 10,
            "y": 3,
            "z": 17,

            "elements": [
                "qmd:accelerator_glass@0"
            ]
        },
        {
            "x": -5,
            "y": 2,
            "z": 0,

            "elements": [
                "qmd:accelerator_glass@0"
            ]
        },
        {
            "x": -4,
            "y": 2,
            "z": 0,

            "elements": [
                "qmd:accelerator_glass@0"
            ]
        },
        {
            "x": -34,
            "y": 6,
            "z": 34,

            "elements": [
                "qmd:particle_chamber_detector@4"
            ]
        },
        {
            "x": -3,
            "y": 2,
            "z": 0,

            "elements": [
                "qmd:accelerator_glass@0"
            ]
        },
        {
            "x": 13,
            "y": 3,
            "z": 17,

            "elements": [
                "qmd:accelerator_glass@0"
            ]
        },
        {
            "x": -33,
            "y": 6,
            "z": 34,

            "elements": [
                "qmd:particle_chamber_detector@3"
            ]
        },
        {
            "x": -2,
            "y": 2,
            "z": 0,

            "elements": [
                "qmd:accelerator_glass@0"
            ]
        },
        {
            "x": 14,
            "y": 3,
            "z": 17,

            "elements": [
                "qmd:accelerator_yoke@0"
            ]
        },
        {
            "x": -32,
            "y": 6,
            "z": 34,

            "elements": [
                "qmd:particle_chamber_detector@4"
            ]
        },
        {
            "x": -1,
            "y": 2,
            "z": 0,

            "elements": [
                "qmd:accelerator_glass@0"
            ]
        },
        {
            "x": 15,
            "y": 3,
            "z": 17,

            "elements": [
                "qmd:accelerator_beam@0"
            ]
        },
        {
            "x": 0,
            "y": 2,
            "z": 0,

            "elements": [
                "qmd:accelerator_glass@0"
            ]
        },
        {
            "x": 16,
            "y": 3,
            "z": 17,

            "elements": [
                "qmd:accelerator_yoke@0"
            ]
        },
        {
            "x": 1,
            "y": 2,
            "z": 0,

            "elements": [
                "qmd:accelerator_glass@0"
            ]
        },
        {
            "x": 17,
            "y": 3,
            "z": 17,

            "elements": [
                "qmd:accelerator_cooler1@7"
            ]
        },
        {
            "x": -29,
            "y": 6,
            "z": 34,

            "elements": [
                "qmd:particle_chamber_glass@0"
            ]
        },
        {
            "x": 2,
            "y": 2,
            "z": 0,

            "elements": [
                "qmd:accelerator_glass@0"
            ]
        },
        {
            "x": 18,
            "y": 3,
            "z": 17,

            "elements": [
                "qmd:accelerator_magnet@2"
            ]
        },
        {
            "x": 3,
            "y": 2,
            "z": 0,

            "elements": [
                "qmd:accelerator_glass@0"
            ]
        },
        {
            "x": 19,
            "y": 3,
            "z": 17,

            "elements": [
                "qmd:accelerator_cooler1@1"
            ]
        },
        {
            "x": 4,
            "y": 2,
            "z": 0,

            "elements": [
                "qmd:accelerator_glass@0"
            ]
        },
        {
            "x": 20,
            "y": 3,
            "z": 17,

            "elements": [
                "qmd:accelerator_cooler1@0"
            ]
        },
        {
            "x": 5,
            "y": 2,
            "z": 0,

            "elements": [
                "qmd:accelerator_glass@0"
            ]
        },
        {
            "x": 21,
            "y": 3,
            "z": 17,

            "elements": [
                "qmd:accelerator_cavity@0"
            ]
        },
        {
            "x": -10,
            "y": 4,
            "z": 17,

            "elements": [
                "qmd:accelerator_glass@0"
            ]
        },
        {
            "x": 6,
            "y": 2,
            "z": 0,

            "elements": [
                "qmd:accelerator_glass@0"
            ]
        },
        {
            "x": 22,
            "y": 3,
            "z": 17,

            "elements": [
                "qmd:accelerator_cooler1@0"
            ]
        },
        {
            "x": -9,
            "y": 4,
            "z": 17,

            "elements": [
                "qmd:accelerator_yoke@0"
            ]
        },
        {
            "x": 7,
            "y": 2,
            "z": 0,

            "elements": [
                "qmd:accelerator_glass@0"
            ]
        },
        {
            "x": 23,
            "y": 3,
            "z": 17,

            "elements": [
                "qmd:accelerator_cooler1@1"
            ]
        },
        {
            "x": -8,
            "y": 4,
            "z": 17,

            "elements": [
                "qmd:accelerator_yoke@0"
            ]
        },
        {
            "x": 8,
            "y": 2,
            "z": 0,

            "elements": [
                "qmd:accelerator_glass@0"
            ]
        },
        {
            "x": 24,
            "y": 3,
            "z": 17,

            "elements": [
                "qmd:accelerator_magnet@2"
            ]
        },
        {
            "x": -7,
            "y": 4,
            "z": 17,

            "elements": [
                "qmd:accelerator_yoke@0"
            ]
        },
        {
            "x": 9,
            "y": 2,
            "z": 0,

            "elements": [
                "qmd:accelerator_glass@0"
            ]
        },
        {
            "x": 25,
            "y": 3,
            "z": 17,

            "elements": [
                "qmd:accelerator_cooler1@7"
            ]
        },
        {
            "x": -6,
            "y": 4,
            "z": 17,

            "elements": [
                "qmd:accelerator_cooler1@7"
            ]
        },
        {
            "x": 10,
            "y": 2,
            "z": 0,

            "elements": [
                "qmd:accelerator_glass@0"
            ]
        },
        {
            "x": 26,
            "y": 3,
            "z": 17,

            "elements": [
                "qmd:accelerator_yoke@0"
            ]
        },
        {
            "x": -5,
            "y": 4,
            "z": 17,

            "elements": [
                "qmd:accelerator_cooler1@8"
            ]
        },
        {
            "x": 27,
            "y": 3,
            "z": 17,

            "elements": [
                "qmd:accelerator_beam@0"
            ]
        },
        {
            "x": -4,
            "y": 4,
            "z": 17,

            "elements": [
                "qmd:accelerator_cooler1@13"
            ]
        },
        {
            "x": -35,
            "y": 5,
            "z": 17,

            "elements": [
                "qmd:accelerator_glass@0"
            ]
        },
        {
            "x": 28,
            "y": 3,
            "z": 17,

            "elements": [
                "qmd:accelerator_yoke@0"
            ]
        },
        {
            "x": -3,
            "y": 4,
            "z": 17,

            "elements": [
                "qmd:accelerator_cooler1@9"
            ]
        },
        {
            "x": -34,
            "y": 5,
            "z": 17,

            "elements": [
                "qmd:accelerator_glass@0"
            ]
        },
        {
            "x": 29,
            "y": 3,
            "z": 17,

            "elements": [
                "qmd:accelerator_glass@0"
            ]
        },
        {
            "x": -2,
            "y": 4,
            "z": 17,

            "elements": [
                "qmd:accelerator_cavity@0"
            ]
        },
        {
            "x": -33,
            "y": 5,
            "z": 17,

            "elements": [
                "qmd:accelerator_glass@0"
            ]
        },
        {
            "x": -1,
            "y": 4,
            "z": 17,

            "elements": [
                "qmd:accelerator_cooler1@0"
            ]
        },
        {
            "x": -32,
            "y": 5,
            "z": 17,

            "elements": [
                "qmd:accelerator_glass@0"
            ]
        },
        {
            "x": 15,
            "y": 2,
            "z": 0,

            "elements": [
                "qmd:particle_chamber_glass@0"
            ]
        },
        {
            "x": 0,
            "y": 4,
            "z": 17,

            "elements": [
                "qmd:accelerator_cooler1@9"
            ]
        },
        {
            "x": -31,
            "y": 5,
            "z": 17,

            "elements": [
                "qmd:accelerator_glass@0"
            ]
        },
        {
            "x": 16,
            "y": 2,
            "z": 0,

            "elements": [
                "qmd:particle_chamber_glass@0"
            ]
        },
        {
            "x": 1,
            "y": 4,
            "z": 17,

            "elements": [
                "qmd:accelerator_cooler1@0"
            ]
        },
        {
            "x": 17,
            "y": 2,
            "z": 0,

            "elements": [
                "qmd:particle_chamber_glass@0"
            ]
        },
        {
            "x": 2,
            "y": 4,
            "z": 17,

            "elements": [
                "qmd:accelerator_cavity@0"
            ]
        },
        {
            "x": 18,
            "y": 2,
            "z": 0,

            "elements": [
                "qmd:particle_chamber_glass@0"
            ]
        },
        {
            "x": 3,
            "y": 4,
            "z": 17,

            "elements": [
                "qmd:accelerator_cooler1@9"
            ]
        },
        {
            "x": 19,
            "y": 2,
            "z": 0,

            "elements": [
                "qmd:particle_chamber_glass@0"
            ]
        },
        {
            "x": 4,
            "y": 4,
            "z": 17,

            "elements": [
                "qmd:accelerator_cooler1@13"
            ]
        },
        {
            "x": 20,
            "y": 2,
            "z": 0,

            "elements": [
                "qmd:particle_chamber_glass@0"
            ]
        },
        {
            "x": 5,
            "y": 4,
            "z": 17,

            "elements": [
                "qmd:accelerator_cooler1@8"
            ]
        },
        {
            "x": 21,
            "y": 2,
            "z": 0,

            "elements": [
                "qmd:particle_chamber_glass@0"
            ]
        },
        {
            "x": -10,
            "y": 3,
            "z": 0,

            "elements": [
                "qmd:accelerator_glass@0"
            ]
        },
        {
            "x": 6,
            "y": 4,
            "z": 17,

            "elements": [
                "qmd:accelerator_cooler1@7"
            ]
        },
        {
            "x": 22,
            "y": 2,
            "z": 0,

            "elements": [
                "qmd:particle_chamber_glass@0"
            ]
        },
        {
            "x": -9,
            "y": 3,
            "z": 0,

            "elements": [
                "qmd:accelerator_glass@0"
            ]
        },
        {
            "x": 7,
            "y": 4,
            "z": 17,

            "elements": [
                "qmd:accelerator_yoke@0"
            ]
        },
        {
            "x": 23,
            "y": 2,
            "z": 0,

            "elements": [
                "qmd:particle_chamber_glass@0"
            ]
        },
        {
            "x": -8,
            "y": 3,
            "z": 0,

            "elements": [
                "qmd:accelerator_glass@0"
            ]
        },
        {
            "x": 8,
            "y": 4,
            "z": 17,

            "elements": [
                "qmd:accelerator_yoke@0"
            ]
        },
        {
            "x": -7,
            "y": 3,
            "z": 0,

            "elements": [
                "qmd:accelerator_glass@0"
            ]
        },
        {
            "x": 9,
            "y": 4,
            "z": 17,

            "elements": [
                "qmd:accelerator_yoke@0"
            ]
        },
        {
            "x": -37,
            "y": 7,
            "z": 34,

            "elements": [
                "qmd:particle_chamber_glass@0"
            ]
        },
        {
            "x": -6,
            "y": 3,
            "z": 0,

            "elements": [
                "qmd:accelerator_glass@0"
            ]
        },
        {
            "x": 10,
            "y": 4,
            "z": 17,

            "elements": [
                "qmd:accelerator_glass@0"
            ]
        },
        {
            "x": -36,
            "y": 7,
            "z": 34,

            "elements": [
                "qmd:particle_chamber_glass@0"
            ]
        },
        {
            "x": -5,
            "y": 3,
            "z": 0,

            "elements": [
                "qmd:accelerator_glass@0"
            ]
        },
        {
            "x": -35,
            "y": 7,
            "z": 34,

            "elements": [
                "qmd:particle_chamber_glass@0"
            ]
        },
        {
            "x": -4,
            "y": 3,
            "z": 0,

            "elements": [
                "qmd:accelerator_glass@0"
            ]
        },
        {
            "x": -34,
            "y": 7,
            "z": 34,

            "elements": [
                "qmd:particle_chamber_glass@0"
            ]
        },
        {
            "x": -3,
            "y": 3,
            "z": 0,

            "elements": [
                "qmd:accelerator_glass@0"
            ]
        },
        {
            "x": 13,
            "y": 4,
            "z": 17,

            "elements": [
                "qmd:accelerator_glass@0"
            ]
        },
        {
            "x": -33,
            "y": 7,
            "z": 34,

            "elements": [
                "qmd:particle_chamber_glass@0"
            ]
        },
        {
            "x": -2,
            "y": 3,
            "z": 0,

            "elements": [
                "qmd:accelerator_glass@0"
            ]
        },
        {
            "x": 14,
            "y": 4,
            "z": 17,

            "elements": [
                "qmd:accelerator_yoke@0"
            ]
        },
        {
            "x": -32,
            "y": 7,
            "z": 34,

            "elements": [
                "qmd:particle_chamber_glass@0"
            ]
        },
        {
            "x": -1,
            "y": 3,
            "z": 0,

            "elements": [
                "qmd:accelerator_glass@0"
            ]
        },
        {
            "x": 15,
            "y": 4,
            "z": 17,

            "elements": [
                "qmd:accelerator_yoke@0"
            ]
        },
        {
            "x": -31,
            "y": 7,
            "z": 34,

            "elements": [
                "qmd:particle_chamber_glass@0"
            ]
        },
        {
            "x": 0,
            "y": 3,
            "z": 0,

            "elements": [
                "qmd:accelerator_glass@0"
            ]
        },
        {
            "x": 16,
            "y": 4,
            "z": 17,

            "elements": [
                "qmd:accelerator_yoke@0"
            ]
        },
        {
            "x": -30,
            "y": 7,
            "z": 34,

            "elements": [
                "qmd:particle_chamber_glass@0"
            ]
        },
        {
            "x": 1,
            "y": 3,
            "z": 0,

            "elements": [
                "qmd:accelerator_glass@0"
            ]
        },
        {
            "x": 17,
            "y": 4,
            "z": 17,

            "elements": [
                "qmd:accelerator_cooler2@0"
            ]
        },
        {
            "x": -29,
            "y": 7,
            "z": 34,

            "elements": [
                "qmd:particle_chamber_glass@0"
            ]
        },
        {
            "x": 2,
            "y": 3,
            "z": 0,

            "elements": [
                "qmd:accelerator_glass@0"
            ]
        },
        {
            "x": 18,
            "y": 4,
            "z": 17,

            "elements": [
                "qmd:accelerator_cooler1@1"
            ]
        },
        {
            "x": 3,
            "y": 3,
            "z": 0,

            "elements": [
                "qmd:accelerator_glass@0"
            ]
        },
        {
            "x": 19,
            "y": 4,
            "z": 17,

            "elements": [
                "qmd:accelerator_cooler1@8"
            ]
        },
        {
            "x": 4,
            "y": 3,
            "z": 0,

            "elements": [
                "qmd:accelerator_glass@0"
            ]
        },
        {
            "x": 20,
            "y": 4,
            "z": 17,

            "elements": [
                "qmd:accelerator_cooler1@9"
            ]
        },
        {
            "x": 5,
            "y": 3,
            "z": 0,

            "elements": [
                "qmd:accelerator_glass@0"
            ]
        },
        {
            "x": 21,
            "y": 4,
            "z": 17,

            "elements": [
                "qmd:accelerator_cavity@0"
            ]
        },
        {
            "x": -10,
            "y": 5,
            "z": 17,

            "elements": [
                "qmd:accelerator_glass@0"
            ]
        },
        {
            "x": 6,
            "y": 3,
            "z": 0,

            "elements": [
                "qmd:accelerator_glass@0"
            ]
        },
        {
            "x": 22,
            "y": 4,
            "z": 17,

            "elements": [
                "qmd:accelerator_cooler1@9"
            ]
        },
        {
            "x": -9,
            "y": 5,
            "z": 17,

            "elements": [
                "qmd:accelerator_glass@0"
            ]
        },
        {
            "x": 7,
            "y": 3,
            "z": 0,

            "elements": [
                "qmd:accelerator_glass@0"
            ]
        },
        {
            "x": 23,
            "y": 4,
            "z": 17,

            "elements": [
                "qmd:accelerator_cooler1@8"
            ]
        },
        {
            "x": -8,
            "y": 5,
            "z": 17,

            "elements": [
                "qmd:accelerator_glass@0"
            ]
        },
        {
            "x": 8,
            "y": 3,
            "z": 0,

            "elements": [
                "qmd:accelerator_glass@0"
            ]
        },
        {
            "x": 24,
            "y": 4,
            "z": 17,

            "elements": [
                "qmd:accelerator_cooler1@1"
            ]
        },
        {
            "x": -7,
            "y": 5,
            "z": 17,

            "elements": [
                "qmd:accelerator_glass@0"
            ]
        },
        {
            "x": 9,
            "y": 3,
            "z": 0,

            "elements": [
                "qmd:accelerator_glass@0"
            ]
        },
        {
            "x": 25,
            "y": 4,
            "z": 17,

            "elements": [
                "qmd:accelerator_cooler2@0"
            ]
        },
        {
            "x": -6,
            "y": 5,
            "z": 17,

            "elements": [
                "qmd:accelerator_glass@0"
            ]
        },
        {
            "x": 10,
            "y": 3,
            "z": 0,

            "elements": [
                "qmd:accelerator_glass@0"
            ]
        },
        {
            "x": 26,
            "y": 4,
            "z": 17,

            "elements": [
                "qmd:accelerator_yoke@0"
            ]
        },
        {
            "x": -5,
            "y": 5,
            "z": 17,

            "elements": [
                "qmd:accelerator_glass@0"
            ]
        },
        {
            "x": 27,
            "y": 4,
            "z": 17,

            "elements": [
                "qmd:accelerator_yoke@0"
            ]
        },
        {
            "x": -4,
            "y": 5,
            "z": 17,

            "elements": [
                "qmd:accelerator_glass@0"
            ]
        },
        {
            "x": 28,
            "y": 4,
            "z": 17,

            "elements": [
                "qmd:accelerator_yoke@0"
            ]
        },
        {
            "x": -3,
            "y": 5,
            "z": 17,

            "elements": [
                "qmd:accelerator_glass@0"
            ]
        },
        {
            "x": 29,
            "y": 4,
            "z": 17,

            "elements": [
                "qmd:accelerator_glass@0"
            ]
        },
        {
            "x": -2,
            "y": 5,
            "z": 17,

            "elements": [
                "qmd:accelerator_glass@0"
            ]
        },
        {
            "x": -1,
            "y": 5,
            "z": 17,

            "elements": [
                "qmd:accelerator_glass@0"
            ]
        },
        {
            "x": 15,
            "y": 3,
            "z": 0,

            "elements": [
                "qmd:particle_chamber_glass@0"
            ]
        },
        {
            "x": 0,
            "y": 5,
            "z": 17,

            "elements": [
                "qmd:accelerator_glass@0"
            ]
        },
        {
            "x": 16,
            "y": 3,
            "z": 0,

            "elements": [
                "qmd:particle_chamber_glass@0"
            ]
        },
        {
            "x": 1,
            "y": 5,
            "z": 17,

            "elements": [
                "qmd:accelerator_glass@0"
            ]
        },
        {
            "x": 17,
            "y": 3,
            "z": 0,

            "elements": [
                "qmd:particle_chamber_glass@0"
            ]
        },
        {
            "x": 2,
            "y": 5,
            "z": 17,

            "elements": [
                "qmd:accelerator_glass@0"
            ]
        },
        {
            "x": 18,
            "y": 3,
            "z": 0,

            "elements": [
                "qmd:particle_chamber_glass@0"
            ]
        },
        {
            "x": 3,
            "y": 5,
            "z": 17,

            "elements": [
                "qmd:accelerator_glass@0"
            ]
        },
        {
            "x": 19,
            "y": 3,
            "z": 0,

            "elements": [
                "qmd:particle_chamber_beam_port@1"
            ]
        },
        {
            "x": 4,
            "y": 5,
            "z": 17,

            "elements": [
                "qmd:accelerator_glass@0"
            ]
        },
        {
            "x": 20,
            "y": 3,
            "z": 0,

            "elements": [
                "qmd:particle_chamber_glass@0"
            ]
        },
        {
            "x": 5,
            "y": 5,
            "z": 17,

            "elements": [
                "qmd:accelerator_glass@0"
            ]
        },
        {
            "x": 21,
            "y": 3,
            "z": 0,

            "elements": [
                "qmd:particle_chamber_glass@0"
            ]
        },
        {
            "x": -10,
            "y": 4,
            "z": 0,

            "elements": [
                "qmd:accelerator_glass@0"
            ]
        },
        {
            "x": 6,
            "y": 5,
            "z": 17,

            "elements": [
                "qmd:accelerator_glass@0"
            ]
        },
        {
            "x": 22,
            "y": 3,
            "z": 0,

            "elements": [
                "qmd:particle_chamber_glass@0"
            ]
        },
        {
            "x": -9,
            "y": 4,
            "z": 0,

            "elements": [
                "qmd:accelerator_glass@0"
            ]
        },
        {
            "x": 7,
            "y": 5,
            "z": 17,

            "elements": [
                "qmd:accelerator_glass@0"
            ]
        },
        {
            "x": 23,
            "y": 3,
            "z": 0,

            "elements": [
                "qmd:particle_chamber_glass@0"
            ]
        },
        {
            "x": -8,
            "y": 4,
            "z": 0,

            "elements": [
                "qmd:accelerator_glass@0"
            ]
        },
        {
            "x": 8,
            "y": 5,
            "z": 17,

            "elements": [
                "qmd:accelerator_glass@0"
            ]
        },
        {
            "x": -7,
            "y": 4,
            "z": 0,

            "elements": [
                "qmd:accelerator_glass@0"
            ]
        },
        {
            "x": 9,
            "y": 5,
            "z": 17,

            "elements": [
                "qmd:accelerator_glass@0"
            ]
        },
        {
            "x": -6,
            "y": 4,
            "z": 0,

            "elements": [
                "qmd:accelerator_glass@0"
            ]
        },
        {
            "x": 10,
            "y": 5,
            "z": 17,

            "elements": [
                "qmd:accelerator_glass@0"
            ]
        },
        {
            "x": -5,
            "y": 4,
            "z": 0,

            "elements": [
                "qmd:accelerator_glass@0"
            ]
        },
        {
            "x": -4,
            "y": 4,
            "z": 0,

            "elements": [
                "qmd:accelerator_glass@0"
            ]
        },
        {
            "x": -3,
            "y": 4,
            "z": 0,

            "elements": [
                "qmd:accelerator_glass@0"
            ]
        },
        {
            "x": 13,
            "y": 5,
            "z": 17,

            "elements": [
                "qmd:accelerator_glass@0"
            ]
        },
        {
            "x": -2,
            "y": 4,
            "z": 0,

            "elements": [
                "qmd:accelerator_glass@0"
            ]
        },
        {
            "x": 14,
            "y": 5,
            "z": 17,

            "elements": [
                "qmd:accelerator_glass@0"
            ]
        },
        {
            "x": -1,
            "y": 4,
            "z": 0,

            "elements": [
                "qmd:accelerator_glass@0"
            ]
        },
        {
            "x": 15,
            "y": 5,
            "z": 17,

            "elements": [
                "qmd:accelerator_glass@0"
            ]
        },
        {
            "x": 0,
            "y": 4,
            "z": 0,

            "elements": [
                "qmd:accelerator_glass@0"
            ]
        },
        {
            "x": 16,
            "y": 5,
            "z": 17,

            "elements": [
                "qmd:accelerator_glass@0"
            ]
        },
        {
            "x": 1,
            "y": 4,
            "z": 0,

            "elements": [
                "qmd:accelerator_glass@0"
            ]
        },
        {
            "x": 17,
            "y": 5,
            "z": 17,

            "elements": [
                "qmd:accelerator_glass@0"
            ]
        },
        {
            "x": 2,
            "y": 4,
            "z": 0,

            "elements": [
                "qmd:accelerator_glass@0"
            ]
        },
        {
            "x": 18,
            "y": 5,
            "z": 17,

            "elements": [
                "qmd:accelerator_glass@0"
            ]
        },
        {
            "x": 3,
            "y": 4,
            "z": 0,

            "elements": [
                "qmd:accelerator_glass@0"
            ]
        },
        {
            "x": 19,
            "y": 5,
            "z": 17,

            "elements": [
                "qmd:accelerator_glass@0"
            ]
        },
        {
            "x": 4,
            "y": 4,
            "z": 0,

            "elements": [
                "qmd:accelerator_glass@0"
            ]
        },
        {
            "x": 20,
            "y": 5,
            "z": 17,

            "elements": [
                "qmd:accelerator_glass@0"
            ]
        },
        {
            "x": 5,
            "y": 4,
            "z": 0,

            "elements": [
                "qmd:accelerator_glass@0"
            ]
        },
        {
            "x": 21,
            "y": 5,
            "z": 17,

            "elements": [
                "qmd:accelerator_glass@0"
            ]
        },
        {
            "x": 6,
            "y": 4,
            "z": 0,

            "elements": [
                "qmd:accelerator_glass@0"
            ]
        },
        {
            "x": 22,
            "y": 5,
            "z": 17,

            "elements": [
                "qmd:accelerator_glass@0"
            ]
        },
        {
            "x": 7,
            "y": 4,
            "z": 0,

            "elements": [
                "qmd:accelerator_glass@0"
            ]
        },
        {
            "x": 23,
            "y": 5,
            "z": 17,

            "elements": [
                "qmd:accelerator_glass@0"
            ]
        },
        {
            "x": 8,
            "y": 4,
            "z": 0,

            "elements": [
                "qmd:accelerator_glass@0"
            ]
        },
        {
            "x": 24,
            "y": 5,
            "z": 17,

            "elements": [
                "qmd:accelerator_glass@0"
            ]
        },
        {
            "x": 9,
            "y": 4,
            "z": 0,

            "elements": [
                "qmd:accelerator_glass@0"
            ]
        },
        {
            "x": 25,
            "y": 5,
            "z": 17,

            "elements": [
                "qmd:accelerator_glass@0"
            ]
        },
        {
            "x": 10,
            "y": 4,
            "z": 0,

            "elements": [
                "qmd:accelerator_glass@0"
            ]
        },
        {
            "x": 26,
            "y": 5,
            "z": 17,

            "elements": [
                "qmd:accelerator_glass@0"
            ]
        },
        {
            "x": 27,
            "y": 5,
            "z": 17,

            "elements": [
                "qmd:accelerator_glass@0"
            ]
        },
        {
            "x": 28,
            "y": 5,
            "z": 17,

            "elements": [
                "qmd:accelerator_glass@0"
            ]
        },
        {
            "x": 29,
            "y": 5,
            "z": 17,

            "elements": [
                "qmd:accelerator_glass@0"
            ]
        },
        {
            "x": 15,
            "y": 4,
            "z": 0,

            "elements": [
                "qmd:particle_chamber_glass@0"
            ]
        },
        {
            "x": 16,
            "y": 4,
            "z": 0,

            "elements": [
                "qmd:particle_chamber_glass@0"
            ]
        },
        {
            "x": 17,
            "y": 4,
            "z": 0,

            "elements": [
                "qmd:particle_chamber_glass@0"
            ]
        },
        {
            "x": 18,
            "y": 4,
            "z": 0,

            "elements": [
                "qmd:particle_chamber_glass@0"
            ]
        },
        {
            "x": 19,
            "y": 4,
            "z": 0,

            "elements": [
                "qmd:particle_chamber_glass@0"
            ]
        },
        {
            "x": 20,
            "y": 4,
            "z": 0,

            "elements": [
                "qmd:particle_chamber_glass@0"
            ]
        },
        {
            "x": 21,
            "y": 4,
            "z": 0,

            "elements": [
                "qmd:particle_chamber_glass@0"
            ]
        },
        {
            "x": -10,
            "y": 5,
            "z": 0,

            "elements": [
                "qmd:accelerator_glass@0"
            ]
        },
        {
            "x": 22,
            "y": 4,
            "z": 0,

            "elements": [
                "qmd:particle_chamber_glass@0"
            ]
        },
        {
            "x": -9,
            "y": 5,
            "z": 0,

            "elements": [
                "qmd:accelerator_glass@0"
            ]
        },
        {
            "x": 23,
            "y": 4,
            "z": 0,

            "elements": [
                "qmd:particle_chamber_glass@0"
            ]
        },
        {
            "x": -8,
            "y": 5,
            "z": 0,

            "elements": [
                "qmd:accelerator_glass@0"
            ]
        },
        {
            "x": -7,
            "y": 5,
            "z": 0,

            "elements": [
                "qmd:accelerator_glass@0"
            ]
        },
        {
            "x": -6,
            "y": 5,
            "z": 0,

            "elements": [
                "qmd:accelerator_glass@0"
            ]
        },
        {
            "x": -5,
            "y": 5,
            "z": 0,

            "elements": [
                "qmd:accelerator_glass@0"
            ]
        },
        {
            "x": -4,
            "y": 5,
            "z": 0,

            "elements": [
                "qmd:accelerator_glass@0"
            ]
        },
        {
            "x": -3,
            "y": 5,
            "z": 0,

            "elements": [
                "qmd:accelerator_glass@0"
            ]
        },
        {
            "x": -2,
            "y": 5,
            "z": 0,

            "elements": [
                "qmd:accelerator_glass@0"
            ]
        },
        {
            "x": -1,
            "y": 5,
            "z": 0,

            "elements": [
                "qmd:accelerator_glass@0"
            ]
        },
        {
            "x": 0,
            "y": 5,
            "z": 0,

            "elements": [
                "qmd:accelerator_glass@0"
            ]
        },
        {
            "x": 1,
            "y": 5,
            "z": 0,

            "elements": [
                "qmd:accelerator_glass@0"
            ]
        },
        {
            "x": 2,
            "y": 5,
            "z": 0,

            "elements": [
                "qmd:accelerator_glass@0"
            ]
        },
        {
            "x": 3,
            "y": 5,
            "z": 0,

            "elements": [
                "qmd:accelerator_glass@0"
            ]
        },
        {
            "x": 4,
            "y": 5,
            "z": 0,

            "elements": [
                "qmd:accelerator_glass@0"
            ]
        },
        {
            "x": 5,
            "y": 5,
            "z": 0,

            "elements": [
                "qmd:accelerator_glass@0"
            ]
        },
        {
            "x": 6,
            "y": 5,
            "z": 0,

            "elements": [
                "qmd:accelerator_glass@0"
            ]
        },
        {
            "x": 7,
            "y": 5,
            "z": 0,

            "elements": [
                "qmd:accelerator_glass@0"
            ]
        },
        {
            "x": 8,
            "y": 5,
            "z": 0,

            "elements": [
                "qmd:accelerator_glass@0"
            ]
        },
        {
            "x": 9,
            "y": 5,
            "z": 0,

            "elements": [
                "qmd:accelerator_glass@0"
            ]
        },
        {
            "x": 10,
            "y": 5,
            "z": 0,

            "elements": [
                "qmd:accelerator_glass@0"
            ]
        },
        {
            "x": 15,
            "y": 5,
            "z": 0,

            "elements": [
                "qmd:particle_chamber_glass@0"
            ]
        },
        {
            "x": 16,
            "y": 5,
            "z": 0,

            "elements": [
                "qmd:particle_chamber_glass@0"
            ]
        },
        {
            "x": 17,
            "y": 5,
            "z": 0,

            "elements": [
                "qmd:particle_chamber_glass@0"
            ]
        },
        {
            "x": 18,
            "y": 5,
            "z": 0,

            "elements": [
                "qmd:particle_chamber_glass@0"
            ]
        },
        {
            "x": 19,
            "y": 5,
            "z": 0,

            "elements": [
                "qmd:particle_chamber_glass@0"
            ]
        },
        {
            "x": 20,
            "y": 5,
            "z": 0,

            "elements": [
                "qmd:particle_chamber_glass@0"
            ]
        },
        {
            "x": 21,
            "y": 5,
            "z": 0,

            "elements": [
                "qmd:particle_chamber_glass@0"
            ]
        },
        {
            "x": 22,
            "y": 5,
            "z": 0,

            "elements": [
                "qmd:particle_chamber_glass@0"
            ]
        },
        {
            "x": 23,
            "y": 5,
            "z": 0,

            "elements": [
                "qmd:particle_chamber_glass@0"
            ]
        },
        {
            "x": 15,
            "y": 6,
            "z": 0,

            "elements": [
                "qmd:particle_chamber_glass@0"
            ]
        },
        {
            "x": 16,
            "y": 6,
            "z": 0,

            "elements": [
                "qmd:particle_chamber_glass@0"
            ]
        },
        {
            "x": 17,
            "y": 6,
            "z": 0,

            "elements": [
                "qmd:particle_chamber_glass@0"
            ]
        },
        {
            "x": 18,
            "y": 6,
            "z": 0,

            "elements": [
                "qmd:particle_chamber_glass@0"
            ]
        },
        {
            "x": 19,
            "y": 6,
            "z": 0,

            "elements": [
                "qmd:particle_chamber_glass@0"
            ]
        },
        {
            "x": 20,
            "y": 6,
            "z": 0,

            "elements": [
                "qmd:particle_chamber_glass@0"
            ]
        },
        {
            "x": 21,
            "y": 6,
            "z": 0,

            "elements": [
                "qmd:particle_chamber_glass@0"
            ]
        },
        {
            "x": 22,
            "y": 6,
            "z": 0,

            "elements": [
                "qmd:particle_chamber_glass@0"
            ]
        },
        {
            "x": 23,
            "y": 6,
            "z": 0,

            "elements": [
                "qmd:particle_chamber_glass@0"
            ]
        },
        {
            "x": 15,
            "y": 7,
            "z": 0,

            "elements": [
                "qmd:particle_chamber_glass@0"
            ]
        },
        {
            "x": 16,
            "y": 7,
            "z": 0,

            "elements": [
                "qmd:particle_chamber_glass@0"
            ]
        },
        {
            "x": 17,
            "y": 7,
            "z": 0,

            "elements": [
                "qmd:particle_chamber_glass@0"
            ]
        },
        {
            "x": 18,
            "y": 7,
            "z": 0,

            "elements": [
                "qmd:particle_chamber_glass@0"
            ]
        },
        {
            "x": 19,
            "y": 7,
            "z": 0,

            "elements": [
                "qmd:particle_chamber_glass@0"
            ]
        },
        {
            "x": 20,
            "y": 7,
            "z": 0,

            "elements": [
                "qmd:particle_chamber_glass@0"
            ]
        },
        {
            "x": 21,
            "y": 7,
            "z": 0,

            "elements": [
                "qmd:particle_chamber_glass@0"
            ]
        },
        {
            "x": 22,
            "y": 7,
            "z": 0,

            "elements": [
                "qmd:particle_chamber_glass@0"
            ]
        },
        {
            "x": 23,
            "y": 7,
            "z": 0,

            "elements": [
                "qmd:particle_chamber_glass@0"
            ]
        },
        {
            "x": -37,
            "y": -1,
            "z": 35,

            "elements": [
                "qmd:particle_chamber_casing@1"
            ]
        },
        {
            "x": -36,
            "y": -1,
            "z": 35,

            "elements": [
                "qmd:particle_chamber_casing@0"
            ]
        },
        {
            "x": -35,
            "y": -1,
            "z": 35,

            "elements": [
                "qmd:particle_chamber_casing@0"
            ]
        },
        {
            "x": -34,
            "y": -1,
            "z": 35,

            "elements": [
                "qmd:particle_chamber_casing@0"
            ]
        },
        {
            "x": -33,
            "y": -1,
            "z": 35,

            "elements": [
                "qmd:particle_chamber_casing@0"
            ]
        },
        {
            "x": -32,
            "y": -1,
            "z": 35,

            "elements": [
                "qmd:particle_chamber_casing@0"
            ]
        },
        {
            "x": -31,
            "y": -1,
            "z": 35,

            "elements": [
                "qmd:particle_chamber_casing@0"
            ]
        },
        {
            "x": -30,
            "y": -1,
            "z": 35,

            "elements": [
                "qmd:particle_chamber_casing@0"
            ]
        },
        {
            "x": -29,
            "y": -1,
            "z": 35,

            "elements": [
                "qmd:particle_chamber_casing@1"
            ]
        },
        {
            "x": -35,
            "y": 1,
            "z": 52,

            "elements": [
                "qmd:accelerator_casing@1"
            ]
        },
        {
            "x": -34,
            "y": 1,
            "z": 52,

            "elements": [
                "qmd:accelerator_casing@0"
            ]
        },
        {
            "x": -33,
            "y": 1,
            "z": 52,

            "elements": [
                "qmd:accelerator_casing@0"
            ]
        },
        {
            "x": -32,
            "y": 1,
            "z": 52,

            "elements": [
                "qmd:accelerator_casing@0"
            ]
        },
        {
            "x": -31,
            "y": 1,
            "z": 52,

            "elements": [
                "qmd:accelerator_casing@1"
            ]
        },
        {
            "x": -37,
            "y": 0,
            "z": 35,

            "elements": [
                "qmd:particle_chamber_glass@0"
            ]
        },
        {
            "x": -34,
            "y": 0,
            "z": 35,

            "elements": [
                "qmd:particle_chamber_detector@4"
            ]
        },
        {
            "x": -33,
            "y": 0,
            "z": 35,

            "elements": [
                "qmd:particle_chamber_detector@3"
            ]
        },
        {
            "x": -32,
            "y": 0,
            "z": 35,

            "elements": [
                "qmd:particle_chamber_detector@4"
            ]
        },
        {
            "x": -29,
            "y": 0,
            "z": 35,

            "elements": [
                "qmd:particle_chamber_glass@0"
            ]
        },
        {
            "x": -35,
            "y": 2,
            "z": 52,

            "elements": [
                "qmd:accelerator_glass@0"
            ]
        },
        {
            "x": -34,
            "y": 2,
            "z": 52,

            "elements": [
                "qmd:accelerator_cooler1@13"
            ]
        },
        {
            "x": -33,
            "y": 2,
            "z": 52,

            "elements": [
                "qmd:accelerator_cooler1@15"
            ]
        },
        {
            "x": -32,
            "y": 2,
            "z": 52,

            "elements": [
                "qmd:accelerator_cooler1@13"
            ]
        },
        {
            "x": -31,
            "y": 2,
            "z": 52,

            "elements": [
                "qmd:accelerator_glass@0"
            ]
        },
        {
            "x": -37,
            "y": 1,
            "z": 35,

            "elements": [
                "qmd:particle_chamber_glass@0"
            ]
        },
        {
            "x": -35,
            "y": 1,
            "z": 35,

            "elements": [
                "qmd:particle_chamber_detector@4"
            ]
        },
        {
            "x": -34,
            "y": 1,
            "z": 35,

            "elements": [
                "qmd:particle_chamber_detector@3"
            ]
        },
        {
            "x": -33,
            "y": 1,
            "z": 35,

            "elements": [
                "qmd:particle_chamber_detector@2"
            ]
        },
        {
            "x": -32,
            "y": 1,
            "z": 35,

            "elements": [
                "qmd:particle_chamber_detector@3"
            ]
        },
        {
            "x": -31,
            "y": 1,
            "z": 35,

            "elements": [
                "qmd:particle_chamber_detector@4"
            ]
        },
        {
            "x": -29,
            "y": 1,
            "z": 35,

            "elements": [
                "qmd:particle_chamber_glass@0"
            ]
        },
        {
            "x": -23,
            "y": 1,
            "z": 35,

            "elements": [
                "qmd:accelerator_casing@1"
            ]
        },
        {
            "x": -22,
            "y": 1,
            "z": 35,

            "elements": [
                "qmd:accelerator_casing@0"
            ]
        },
        {
            "x": -21,
            "y": 1,
            "z": 35,

            "elements": [
                "qmd:accelerator_casing@0"
            ]
        },
        {
            "x": -20,
            "y": 1,
            "z": 35,

            "elements": [
                "qmd:accelerator_casing@0"
            ]
        },
        {
            "x": -35,
            "y": 3,
            "z": 52,

            "elements": [
                "qmd:accelerator_glass@0"
            ]
        },
        {
            "x": -19,
            "y": 1,
            "z": 35,

            "elements": [
                "qmd:accelerator_casing@1"
            ]
        },
        {
            "x": -34,
            "y": 3,
            "z": 52,

            "elements": [
                "qmd:accelerator_cooler1@15"
            ]
        },
        {
            "x": -33,
            "y": 3,
            "z": 52,

            "elements": [
                "qmd:accelerator_beam@0"
            ]
        },
        {
            "x": -32,
            "y": 3,
            "z": 52,

            "elements": [
                "qmd:accelerator_cooler1@15"
            ]
        },
        {
            "x": -31,
            "y": 3,
            "z": 52,

            "elements": [
                "qmd:accelerator_glass@0"
            ]
        },
        {
            "x": -11,
            "y": 1,
            "z": 35,

            "elements": [
                "qmd:accelerator_casing@1"
            ]
        },
        {
            "x": -10,
            "y": 1,
            "z": 35,

            "elements": [
                "qmd:accelerator_casing@0"
            ]
        },
        {
            "x": -9,
            "y": 1,
            "z": 35,

            "elements": [
                "qmd:accelerator_casing@0"
            ]
        },
        {
            "x": -8,
            "y": 1,
            "z": 35,

            "elements": [
                "qmd:accelerator_casing@0"
            ]
        },
        {
            "x": -7,
            "y": 1,
            "z": 35,

            "elements": [
                "qmd:accelerator_casing@1"
            ]
        },
        {
            "x": -37,
            "y": 2,
            "z": 35,

            "elements": [
                "qmd:particle_chamber_glass@0"
            ]
        },
        {
            "x": -36,
            "y": 2,
            "z": 35,

            "elements": [
                "qmd:particle_chamber_detector@4"
            ]
        },
        {
            "x": -35,
            "y": 2,
            "z": 35,

            "elements": [
                "qmd:particle_chamber_detector@3"
            ]
        },
        {
            "x": -34,
            "y": 2,
            "z": 35,

            "elements": [
                "qmd:particle_chamber_detector@2"
            ]
        },
        {
            "x": -33,
            "y": 2,
            "z": 35,

            "elements": [
                "qmd:particle_chamber_detector@1"
            ]
        },
        {
            "x": -32,
            "y": 2,
            "z": 35,

            "elements": [
                "qmd:particle_chamber_detector@2"
            ]
        },
        {
            "x": -31,
            "y": 2,
            "z": 35,

            "elements": [
                "qmd:particle_chamber_detector@3"
            ]
        },
        {
            "x": -30,
            "y": 2,
            "z": 35,

            "elements": [
                "qmd:particle_chamber_detector@4"
            ]
        },
        {
            "x": -29,
            "y": 2,
            "z": 35,

            "elements": [
                "qmd:particle_chamber_glass@0"
            ]
        },
        {
            "x": -23,
            "y": 2,
            "z": 35,

            "elements": [
                "qmd:accelerator_glass@0"
            ]
        },
        {
            "x": -35,
            "y": 4,
            "z": 52,

            "elements": [
                "qmd:accelerator_glass@0"
            ]
        },
        {
            "x": -35,
            "y": 1,
            "z": 18,

            "elements": [
                "qmd:accelerator_casing@1"
            ]
        },
        {
            "x": -19,
            "y": 2,
            "z": 35,

            "elements": [
                "qmd:accelerator_glass@0"
            ]
        },
        {
            "x": -34,
            "y": 4,
            "z": 52,

            "elements": [
                "qmd:accelerator_cooler1@13"
            ]
        },
        {
            "x": -34,
            "y": 1,
            "z": 18,

            "elements": [
                "qmd:accelerator_casing@0"
            ]
        },
        {
            "x": -33,
            "y": 4,
            "z": 52,

            "elements": [
                "qmd:accelerator_cooler1@15"
            ]
        },
        {
            "x": -33,
            "y": 1,
            "z": 18,

            "elements": [
                "qmd:accelerator_casing@0"
            ]
        },
        {
            "x": -32,
            "y": 4,
            "z": 52,

            "elements": [
                "qmd:accelerator_cooler1@13"
            ]
        },
        {
            "x": -32,
            "y": 1,
            "z": 18,

            "elements": [
                "qmd:accelerator_casing@0"
            ]
        },
        {
            "x": -31,
            "y": 4,
            "z": 52,

            "elements": [
                "qmd:accelerator_glass@0"
            ]
        },
        {
            "x": -31,
            "y": 1,
            "z": 18,

            "elements": [
                "qmd:accelerator_casing@1"
            ]
        },
        {
            "x": -11,
            "y": 2,
            "z": 35,

            "elements": [
                "qmd:accelerator_glass@0"
            ]
        },
        {
            "x": -7,
            "y": 2,
            "z": 35,

            "elements": [
                "qmd:accelerator_glass@0"
            ]
        },
        {
            "x": -37,
            "y": 3,
            "z": 35,

            "elements": [
                "qmd:particle_chamber_glass@0"
            ]
        },
        {
            "x": -36,
            "y": 3,
            "z": 35,

            "elements": [
                "qmd:particle_chamber_detector@3"
            ]
        },
        {
            "x": -35,
            "y": 3,
            "z": 35,

            "elements": [
                "qmd:particle_chamber_detector@2"
            ]
        },
        {
            "x": -34,
            "y": 3,
            "z": 35,

            "elements": [
                "qmd:particle_chamber_detector@1"
            ]
        },
        {
            "x": -33,
            "y": 3,
            "z": 35,

            "elements": [
                "qmd:particle_chamber@0"
            ]
        },
        {
            "x": -32,
            "y": 3,
            "z": 35,

            "elements": [
                "qmd:particle_chamber_detector@1"
            ]
        },
        {
            "x": -31,
            "y": 3,
            "z": 35,

            "elements": [
                "qmd:particle_chamber_detector@2"
            ]
        },
        {
            "x": -30,
            "y": 3,
            "z": 35,

            "elements": [
                "qmd:particle_chamber_detector@3"
            ]
        },
        {
            "x": -29,
            "y": 3,
            "z": 35,

            "elements": [
                "qmd:particle_chamber_glass@0"
            ]
        },
        {
            "x": -10,
            "y": 1,
            "z": 18,

            "elements": [
                "qmd:accelerator_casing@1"
            ]
        },
        {
            "x": -9,
            "y": 1,
            "z": 18,

            "elements": [
                "qmd:accelerator_casing@0"
            ]
        },
        {
            "x": -8,
            "y": 1,
            "z": 18,

            "elements": [
                "qmd:accelerator_casing@0"
            ]
        },
        {
            "x": -23,
            "y": 3,
            "z": 35,

            "elements": [
                "qmd:accelerator_glass@0"
            ]
        },
        {
            "x": -7,
            "y": 1,
            "z": 18,

            "elements": [
                "qmd:accelerator_casing@0"
            ]
        },
        {
            "x": -6,
            "y": 1,
            "z": 18,

            "elements": [
                "qmd:accelerator_casing@0"
            ]
        },
        {
            "x": -21,
            "y": 3,
            "z": 35,

            "elements": [
                "qmd:accelerator_beam@0"
            ]
        },
        {
            "x": -5,
            "y": 1,
            "z": 18,

            "elements": [
                "qmd:accelerator_casing@0"
            ]
        },
        {
            "x": -35,
            "y": 5,
            "z": 52,

            "elements": [
                "qmd:accelerator_glass@0"
            ]
        },
        {
            "x": -4,
            "y": 1,
            "z": 18,

            "elements": [
                "qmd:accelerator_casing@0"
            ]
        },
        {
            "x": -35,
            "y": 2,
            "z": 18,

            "elements": [
                "qmd:accelerator_glass@0"
            ]
        },
        {
            "x": -19,
            "y": 3,
            "z": 35,

            "elements": [
                "qmd:accelerator_glass@0"
            ]
        },
        {
            "x": -34,
            "y": 5,
            "z": 52,

            "elements": [
                "qmd:accelerator_glass@0"
            ]
        },
        {
            "x": -3,
            "y": 1,
            "z": 18,

            "elements": [
                "qmd:accelerator_casing@0"
            ]
        },
        {
            "x": -34,
            "y": 2,
            "z": 18,

            "elements": [
                "qmd:accelerator_cavity@1"
            ]
        },
        {
            "x": -33,
            "y": 5,
            "z": 52,

            "elements": [
                "qmd:accelerator_glass@0"
            ]
        },
        {
            "x": -2,
            "y": 1,
            "z": 18,

            "elements": [
                "qmd:accelerator_casing@0"
            ]
        },
        {
            "x": -33,
            "y": 2,
            "z": 18,

            "elements": [
                "qmd:accelerator_cavity@1"
            ]
        },
        {
            "x": -32,
            "y": 5,
            "z": 52,

            "elements": [
                "qmd:accelerator_glass@0"
            ]
        },
        {
            "x": -1,
            "y": 1,
            "z": 18,

            "elements": [
                "qmd:accelerator_casing@0"
            ]
        },
        {
            "x": -32,
            "y": 2,
            "z": 18,

            "elements": [
                "qmd:accelerator_cavity@1"
            ]
        },
        {
            "x": -31,
            "y": 5,
            "z": 52,

            "elements": [
                "qmd:accelerator_glass@0"
            ]
        },
        {
            "x": 0,
            "y": 1,
            "z": 18,

            "elements": [
                "qmd:accelerator_casing@0"
            ]
        },
        {
            "x": -31,
            "y": 2,
            "z": 18,

            "elements": [
                "qmd:accelerator_energy_port@0"
            ]
        },
        {
            "x": 15,
            "y": -1,
            "z": 1,

            "elements": [
                "qmd:particle_chamber_casing@1"
            ]
        },
        {
            "x": 1,
            "y": 1,
            "z": 18,

            "elements": [
                "qmd:accelerator_casing@0"
            ]
        },
        {
            "x": 16,
            "y": -1,
            "z": 1,

            "elements": [
                "qmd:particle_chamber_casing@0"
            ]
        },
        {
            "x": 2,
            "y": 1,
            "z": 18,

            "elements": [
                "qmd:accelerator_casing@0"
            ]
        },
        {
            "x": 17,
            "y": -1,
            "z": 1,

            "elements": [
                "qmd:particle_chamber_casing@0"
            ]
        },
        {
            "x": 3,
            "y": 1,
            "z": 18,

            "elements": [
                "qmd:accelerator_casing@0"
            ]
        },
        {
            "x": 18,
            "y": -1,
            "z": 1,

            "elements": [
                "qmd:particle_chamber_casing@0"
            ]
        },
        {
            "x": 4,
            "y": 1,
            "z": 18,

            "elements": [
                "qmd:accelerator_casing@0"
            ]
        },
        {
            "x": -11,
            "y": 3,
            "z": 35,

            "elements": [
                "qmd:accelerator_glass@0"
            ]
        },
        {
            "x": 19,
            "y": -1,
            "z": 1,

            "elements": [
                "qmd:particle_chamber_casing@0"
            ]
        },
        {
            "x": 5,
            "y": 1,
            "z": 18,

            "elements": [
                "qmd:accelerator_casing@0"
            ]
        },
        {
            "x": 20,
            "y": -1,
            "z": 1,

            "elements": [
                "qmd:particle_chamber_casing@0"
            ]
        },
        {
            "x": 6,
            "y": 1,
            "z": 18,

            "elements": [
                "qmd:accelerator_casing@0"
            ]
        },
        {
            "x": -9,
            "y": 3,
            "z": 35,

            "elements": [
                "qmd:accelerator_beam@0"
            ]
        },
        {
            "x": 21,
            "y": -1,
            "z": 1,

            "elements": [
                "qmd:particle_chamber_casing@0"
            ]
        },
        {
            "x": 7,
            "y": 1,
            "z": 18,

            "elements": [
                "qmd:accelerator_casing@0"
            ]
        },
        {
            "x": 22,
            "y": -1,
            "z": 1,

            "elements": [
                "qmd:particle_chamber_casing@0"
            ]
        },
        {
            "x": 8,
            "y": 1,
            "z": 18,

            "elements": [
                "qmd:accelerator_casing@0"
            ]
        },
        {
            "x": -7,
            "y": 3,
            "z": 35,

            "elements": [
                "qmd:accelerator_glass@0"
            ]
        },
        {
            "x": 23,
            "y": -1,
            "z": 1,

            "elements": [
                "qmd:particle_chamber_casing@1"
            ]
        },
        {
            "x": 9,
            "y": 1,
            "z": 18,

            "elements": [
                "qmd:accelerator_casing@0"
            ]
        },
        {
            "x": -37,
            "y": 4,
            "z": 35,

            "elements": [
                "qmd:particle_chamber_glass@0"
            ]
        },
        {
            "x": 10,
            "y": 1,
            "z": 18,

            "elements": [
                "qmd:accelerator_casing@1"
            ]
        },
        {
            "x": -36,
            "y": 4,
            "z": 35,

            "elements": [
                "qmd:particle_chamber_detector@4"
            ]
        },
        {
            "x": -35,
            "y": 4,
            "z": 35,

            "elements": [
                "qmd:particle_chamber_detector@3"
            ]
        },
        {
            "x": -34,
            "y": 4,
            "z": 35,

            "elements": [
                "qmd:particle_chamber_detector@2"
            ]
        },
        {
            "x": 13,
            "y": 1,
            "z": 18,

            "elements": [
                "qmd:accelerator_casing@1"
            ]
        },
        {
            "x": -33,
            "y": 4,
            "z": 35,

            "elements": [
                "qmd:particle_chamber_detector@1"
            ]
        },
        {
            "x": 14,
            "y": 1,
            "z": 18,

            "elements": [
                "qmd:accelerator_casing@0"
            ]
        },
        {
            "x": -32,
            "y": 4,
            "z": 35,

            "elements": [
                "qmd:particle_chamber_detector@2"
            ]
        },
        {
            "x": 15,
            "y": 1,
            "z": 18,

            "elements": [
                "qmd:accelerator_casing@0"
            ]
        },
        {
            "x": -31,
            "y": 4,
            "z": 35,

            "elements": [
                "qmd:particle_chamber_detector@3"
            ]
        },
        {
            "x": 16,
            "y": 1,
            "z": 18,

            "elements": [
                "qmd:accelerator_casing@0"
            ]
        },
        {
            "x": -30,
            "y": 4,
            "z": 35,

            "elements": [
                "qmd:particle_chamber_detector@4"
            ]
        },
        {
            "x": 17,
            "y": 1,
            "z": 18,

            "elements": [
                "qmd:accelerator_casing@0"
            ]
        },
        {
            "x": -29,
            "y": 4,
            "z": 35,

            "elements": [
                "qmd:particle_chamber_glass@0"
            ]
        },
        {
            "x": 18,
            "y": 1,
            "z": 18,

            "elements": [
                "qmd:accelerator_casing@1"
            ]
        },
        {
            "x": 19,
            "y": 1,
            "z": 18,

            "elements": [
                "qmd:accelerator_casing@1"
            ]
        },
        {
            "x": 20,
            "y": 1,
            "z": 18,

            "elements": [
                "qmd:accelerator_casing@1"
            ]
        },
        {
            "x": 21,
            "y": 1,
            "z": 18,

            "elements": [
                "qmd:accelerator_casing@1"
            ]
        },
        {
            "x": -10,
            "y": 2,
            "z": 18,

            "elements": [
                "qmd:accelerator_glass@0"
            ]
        },
        {
            "x": 22,
            "y": 1,
            "z": 18,

            "elements": [
                "qmd:accelerator_casing@1"
            ]
        },
        {
            "x": -9,
            "y": 2,
            "z": 18,

            "elements": [
                "qmd:accelerator_yoke@0"
            ]
        },
        {
            "x": 23,
            "y": 1,
            "z": 18,

            "elements": [
                "qmd:accelerator_casing@1"
            ]
        },
        {
            "x": -8,
            "y": 2,
            "z": 18,

            "elements": [
                "qmd:accelerator_magnet@3"
            ]
        },
        {
            "x": -23,
            "y": 4,
            "z": 35,

            "elements": [
                "qmd:accelerator_glass@0"
            ]
        },
        {
            "x": 24,
            "y": 1,
            "z": 18,

            "elements": [
                "qmd:accelerator_casing@1"
            ]
        },
        {
            "x": -7,
            "y": 2,
            "z": 18,

            "elements": [
                "qmd:accelerator_yoke@0"
            ]
        },
        {
            "x": 25,
            "y": 1,
            "z": 18,

            "elements": [
                "qmd:accelerator_casing@0"
            ]
        },
        {
            "x": -6,
            "y": 2,
            "z": 18,

            "elements": [
                "qmd:accelerator_magnet@2"
            ]
        },
        {
            "x": 26,
            "y": 1,
            "z": 18,

            "elements": [
                "qmd:accelerator_casing@0"
            ]
        },
        {
            "x": -5,
            "y": 2,
            "z": 18,

            "elements": [
                "qmd:accelerator_cooler1@1"
            ]
        },
        {
            "x": 27,
            "y": 1,
            "z": 18,

            "elements": [
                "qmd:accelerator_casing@0"
            ]
        },
        {
            "x": -4,
            "y": 2,
            "z": 18,

            "elements": [
                "qmd:accelerator_cooler1@15"
            ]
        },
        {
            "x": -35,
            "y": 3,
            "z": 18,

            "elements": [
                "qmd:accelerator_glass@0"
            ]
        },
        {
            "x": -19,
            "y": 4,
            "z": 35,

            "elements": [
                "qmd:accelerator_glass@0"
            ]
        },
        {
            "x": 28,
            "y": 1,
            "z": 18,

            "elements": [
                "qmd:accelerator_casing@0"
            ]
        },
        {
            "x": -3,
            "y": 2,
            "z": 18,

            "elements": [
                "qmd:accelerator_cooler1@0"
            ]
        },
        {
            "x": -34,
            "y": 3,
            "z": 18,

            "elements": [
                "qmd:accelerator_cavity@1"
            ]
        },
        {
            "x": 29,
            "y": 1,
            "z": 18,

            "elements": [
                "qmd:accelerator_casing@1"
            ]
        },
        {
            "x": -2,
            "y": 2,
            "z": 18,

            "elements": [
                "qmd:accelerator_cavity@0"
            ]
        },
        {
            "x": -33,
            "y": 3,
            "z": 18,

            "elements": [
                "qmd:accelerator_beam@0"
            ]
        },
        {
            "x": -1,
            "y": 2,
            "z": 18,

            "elements": [
                "qmd:accelerator_cooler1@0"
            ]
        },
        {
            "x": -32,
            "y": 3,
            "z": 18,

            "elements": [
                "qmd:accelerator_cavity@1"
            ]
        },
        {
            "x": 0,
            "y": 2,
            "z": 18,

            "elements": [
                "qmd:accelerator_cooler1@9"
            ]
        },
        {
            "x": -31,
            "y": 3,
            "z": 18,

            "elements": [
                "qmd:accelerator_glass@0"
            ]
        },
        {
            "x": 15,
            "y": 0,
            "z": 1,

            "elements": [
                "qmd:particle_chamber_glass@0"
            ]
        },
        {
            "x": 1,
            "y": 2,
            "z": 18,

            "elements": [
                "qmd:accelerator_cooler1@0"
            ]
        },
        {
            "x": 2,
            "y": 2,
            "z": 18,

            "elements": [
                "qmd:accelerator_cavity@0"
            ]
        },
        {
            "x": 3,
            "y": 2,
            "z": 18,

            "elements": [
                "qmd:accelerator_cooler1@0"
            ]
        },
        {
            "x": 4,
            "y": 2,
            "z": 18,

            "elements": [
                "qmd:accelerator_cooler1@15"
            ]
        },
        {
            "x": -11,
            "y": 4,
            "z": 35,

            "elements": [
                "qmd:accelerator_glass@0"
            ]
        },
        {
            "x": 5,
            "y": 2,
            "z": 18,

            "elements": [
                "qmd:accelerator_cooler1@1"
            ]
        },
        {
            "x": -10,
            "y": 1,
            "z": 1,

            "elements": [
                "qmd:accelerator_casing@1"
            ]
        },
        {
            "x": 6,
            "y": 2,
            "z": 18,

            "elements": [
                "qmd:accelerator_magnet@0"
            ]
        },
        {
            "x": -9,
            "y": 1,
            "z": 1,

            "elements": [
                "qmd:accelerator_casing@0"
            ]
        },
        {
            "x": 7,
            "y": 2,
            "z": 18,

            "elements": [
                "qmd:accelerator_yoke@0"
            ]
        },
        {
            "x": -8,
            "y": 1,
            "z": 1,

            "elements": [
                "qmd:accelerator_casing@0"
            ]
        },
        {
            "x": 8,
            "y": 2,
            "z": 18,

            "elements": [
                "qmd:accelerator_magnet@4"
            ]
        },
        {
            "x": -7,
            "y": 4,
            "z": 35,

            "elements": [
                "qmd:accelerator_glass@0"
            ]
        },
        {
            "x": 23,
            "y": 0,
            "z": 1,

            "elements": [
                "qmd:particle_chamber_glass@0"
            ]
        },
        {
            "x": -7,
            "y": 1,
            "z": 1,

            "elements": [
                "qmd:accelerator_casing@0"
            ]
        },
        {
            "x": 9,
            "y": 2,
            "z": 18,

            "elements": [
                "qmd:accelerator_yoke@0"
            ]
        },
        {
            "x": -37,
            "y": 5,
            "z": 35,

            "elements": [
                "qmd:particle_chamber_glass@0"
            ]
        },
        {
            "x": -6,
            "y": 1,
            "z": 1,

            "elements": [
                "qmd:accelerator_casing@0"
            ]
        },
        {
            "x": 10,
            "y": 2,
            "z": 18,

            "elements": [
                "qmd:accelerator_glass@0"
            ]
        },
        {
            "x": -5,
            "y": 1,
            "z": 1,

            "elements": [
                "qmd:accelerator_casing@0"
            ]
        },
        {
