{
    "registryname":"gongmingjitan",
    "localizedname":"众神凝视之坛",
    "color":"ffffff",
    "parts": [
        {
            "x": -1,
            "y": 0,
            "z": 0,
            "elements": [
                "astralsorcery:blockmarble@6"
            ]
        },
        {
            "x": 0,
            "y": 0,
            "z": 0,
            "elements": [
                "modularmachinery:blockcontroller@2"
            ]
        },
        {
            "x": -5,
            "y": -6,
            "z": -3,
            "elements": [
                "botania:managlass@0"
            ]
        },
        {
            "x": -2,
            "y": 0,
            "z": 0,
            "elements": [
                "astralsorcery:blockmarble@6"
            ]
        },
        {
            "x": 1,
            "y": 0,
            "z": 0,
            "elements": [
                "astralsorcery:blockmarble@6"
            ]
        },
        {
            "x": -6,
            "y": -6,
            "z": -3,
            "elements": [
                "enderio:block_fluid_liquid_sunshine@0"
            ]
        },
        {
            "x": -4,
            "y": -2,
            "z": -1,
            "elements": [
                "astralsorcery:blockinfusedwood@2"
            ]
        },
        {
            "x": 2,
            "y": 0,
            "z": 0,
            "elements": [
                "astralsorcery:blockmarble@6"
            ]
        },
        {
            "x": -7,
            "y": -6,
            "z": -3,
            "elements": [
                "botania:managlass@0"
            ]
        },
        {
            "x": -6,
            "y": -4,
            "z": -2,
            "elements": [
                "botania:managlass@0"
            ]
        },
        {
            "x": 7,
            "y": -7,
            "z": -3,
            "elements": [
                "astralsorcery:blockmarble@3"
            ]
        },
        {
            "x": 6,
            "y": -7,
            "z": -3,
            "elements": [
                "astralsorcery:blockmarble@0"
            ]
        },
        {
            "x": 5,
            "y": -7,
            "z": -3,
            "elements": [
                "astralsorcery:blockmarble@0"
            ]
        },
        {
            "x": 6,
            "y": -5,
            "z": -2,
            "elements": [
                "botania:managlass@0"
            ]
        },
        {
            "x": 4,
            "y": -7,
            "z": -3,
            "elements": [
                "astralsorcery:blockmarble@0"
            ]
        },
        {
            "x": 3,
            "y": -7,
            "z": -3,
            "elements": [
                "astralsorcery:blockmarble@0"
            ]
        },
        {
            "x": 6,
            "y": -1,
            "z": 0,
            "elements": [
                "astralsorcery:blockmarble@4"
            ]
        },
        {
            "x": 2,
            "y": -7,
            "z": -3,
            "elements": [
                "astralsorcery:blockmarble@3"
            ]
        },
        {
            "x": 4,
            "y": -3,
            "z": -1,
            "elements": [
                "astralsorcery:blockinfusedwood@2"
            ]
        },
        {
            "x": 5,
            "y": -1,
            "z": 0,
            "elements": [
                "botania:managlass@0"
            ]
        },
        {
            "x": 1,
            "y": -7,
            "z": -3,
            "elements": [
                "astralsorcery:blockmarble@3"
            ]
        },
        {
            "x": 4,
            "y": -1,
            "z": 0,
            "elements": [
                "botania:managlass@0"
            ]
        },
        {
            "x": 0,
            "y": -7,
            "z": -3,
            "elements": [
                "modularmachinery:blockoutputbus"
            ]
        },
        {
            "x": 3,
            "y": -1,
            "z": 0,
            "elements": [
                "botania:managlass@0"
            ]
        },
        {
            "x": -1,
            "y": -7,
            "z": -3,
            "elements": [
                "astralsorcery:blockmarble@3"
            ]
        },
        {
            "x": -2,
            "y": -7,
            "z": -3,
            "elements": [
                "astralsorcery:blockmarble@3"
            ]
        },
        {
            "x": -3,
            "y": -7,
            "z": -3,
            "elements": [
                "astralsorcery:blockmarble@0"
            ]
        },
        {
            "x": -4,
            "y": -7,
            "z": -3,
            "elements": [
                "astralsorcery:blockmarble@0"
            ]
        },
        {
            "x": -5,
            "y": -7,
            "z": -3,
            "elements": [
                "astralsorcery:blockmarble@0"
            ]
        },
        {
            "x": -6,
            "y": -7,
            "z": -3,
            "elements": [
                "astralsorcery:blockmarble@0"
            ]
        },
        {
            "x": -4,
            "y": -3,
            "z": -1,
            "elements": [
                "astralsorcery:blockinfusedwood@2"
            ]
        },
        {
            "x": -3,
            "y": -1,
            "z": 0,
            "elements": [
                "botania:managlass@0"
            ]
        },
        {
            "x": -7,
            "y": -7,
            "z": -3,
            "elements": [
                "astralsorcery:blockmarble@3"
            ]
        },
        {
            "x": -6,
            "y": -5,
            "z": -2,
            "elements": [
                "botania:managlass@0"
            ]
        },
        {
            "x": -4,
            "y": -1,
            "z": 0,
            "elements": [
                "botania:managlass@0"
            ]
        },
        {
            "x": -5,
            "y": -1,
            "z": 0,
            "elements": [
                "botania:managlass@0"
            ]
        },
        {
            "x": -6,
            "y": -1,
            "z": 0,
            "elements": [
                "astralsorcery:blockmarble@4"
            ]
        },
        {
            "x": 6,
            "y": -6,
            "z": -2,
            "elements": [
                "botania:managlass@0"
            ]
        },
        {
            "x": 4,
            "y": -4,
            "z": -1,
            "elements": [
                "astralsorcery:blockinfusedwood@2"
            ]
        },
        {
            "x": -4,
            "y": -4,
            "z": -1,
            "elements": [
                "astralsorcery:blockinfusedwood@2"
            ]
        },
        {
            "x": -6,
            "y": -6,
            "z": -2,
            "elements": [
                "botania:managlass@0"
            ]
        },
        {
            "x": 7,
            "y": -7,
            "z": -2,
            "elements": [
                "astralsorcery:blockmarble@3"
            ]
        },
        {
            "x": 6,
            "y": -7,
            "z": -2,
            "elements": [
                "astralsorcery:blockmarble@0"
            ]
        },
        {
            "x": 5,
            "y": -7,
            "z": -2,
            "elements": [
                "astralsorcery:blockblackmarble@0"
            ]
        },
        {
            "x": 4,
            "y": -7,
            "z": -2,
            "elements": [
                "astralsorcery:blockblackmarble@0"
            ]
        },
        {
            "x": 3,
            "y": -7,
            "z": -2,
            "elements": [
                "astralsorcery:blockblackmarble@0"
            ]
        },
        {
            "x": 4,
            "y": -5,
            "z": -1,
            "elements": [
                "astralsorcery:blockinfusedwood@2"
            ]
        },
        {
            "x": 2,
            "y": -7,
            "z": -2,
            "elements": [
                "astralsorcery:blockmarble@0"
            ]
        },
        {
            "x": 1,
            "y": -7,
            "z": -2,
            "elements": [
                "astralsorcery:blockmarble@0"
            ]
        },
        {
            "x": 0,
            "y": -7,
            "z": -2,
            "elements": [
                "astralsorcery:blockmarble@0"
            ]
        },
        {
            "x": -1,
            "y": -7,
            "z": -2,
            "elements": [
                "astralsorcery:blockmarble@0"
            ]
        },
        {
            "x": -2,
            "y": -7,
            "z": -2,
            "elements": [
                "astralsorcery:blockmarble@0"
            ]
        },
        {
            "x": -3,
            "y": -7,
            "z": -2,
            "elements": [
                "astralsorcery:blockblackmarble@0"
            ]
        },
        {
            "x": -4,
            "y": -7,
            "z": -2,
            "elements": [
                "astralsorcery:blockblackmarble@0"
            ]
        },
        {
            "x": -5,
            "y": -7,
            "z": -2,
            "elements": [
                "astralsorcery:blockblackmarble@0"
            ]
        },
        {
            "x": -4,
            "y": -5,
            "z": -1,
            "elements": [
                "astralsorcery:blockinfusedwood@2"
            ]
        },
        {
            "x": -6,
            "y": -7,
            "z": -2,
            "elements": [
                "astralsorcery:blockmarble@0"
            ]
        },
        {
            "x": -7,
            "y": -7,
            "z": -2,
            "elements": [
                "astralsorcery:blockmarble@3"
            ]
        },
        {
            "x": 4,
            "y": -6,
            "z": -1,
            "elements": [
                "astralsorcery:blockinfusedwood@2"
            ]
        },
        {
            "x": -4,
            "y": -6,
            "z": -1,
            "elements": [
                "astralsorcery:blockinfusedwood@2"
            ]
        },
        {
            "x": 7,
            "y": -7,
            "z": -1,
            "elements": [
                "astralsorcery:blockmarble@3"
            ]
        },
        {
            "x": 6,
            "y": -7,
            "z": -1,
            "elements": [
                "astralsorcery:blockmarble@0"
            ]
        },
        {
            "x": 5,
            "y": -7,
            "z": -1,
            "elements": [
                "astralsorcery:blockblackmarble@0"
            ]
        },
        {
            "x": 4,
            "y": -7,
            "z": -1,
            "elements": [
                "astralsorcery:blockblackmarble@0"
            ]
        },
        {
            "x": 3,
            "y": -7,
            "z": -1,
            "elements": [
                "astralsorcery:blockblackmarble@0"
            ]
        },
        {
            "x": 2,
            "y": -7,
            "z": -1,
            "elements": [
                "astralsorcery:blockblackmarble@0"
            ]
        },
        {
            "x": 1,
            "y": -7,
            "z": -1,
            "elements": [
                "astralsorcery:blockblackmarble@0"
            ]
        },
        {
            "x": 0,
            "y": -7,
            "z": -1,
            "elements": [
                "astralsorcery:blockblackmarble@0"
            ]
        },
        {
            "x": -1,
            "y": -7,
            "z": -1,
            "elements": [
                "astralsorcery:blockblackmarble@0"
            ]
        },
        {
            "x": -2,
            "y": -7,
            "z": -1,
            "elements": [
                "astralsorcery:blockblackmarble@0"
            ]
        },
        {
            "x": -3,
            "y": -7,
            "z": -1,
            "elements": [
                "astralsorcery:blockblackmarble@0"
            ]
        },
        {
            "x": -4,
            "y": -7,
            "z": -1,
            "elements": [
                "astralsorcery:blockblackmarble@0"
            ]
        },
        {
            "x": -5,
            "y": -7,
            "z": -1,
            "elements": [
                "astralsorcery:blockblackmarble@0"
            ]
        },
        {
            "x": -6,
            "y": -7,
            "z": -1,
            "elements": [
                "astralsorcery:blockmarble@0"
            ]
        },
        {
            "x": -7,
            "y": -7,
            "z": -1,
            "elements": [
                "astralsorcery:blockmarble@3"
            ]
        },
        {
            "x": -7,
            "y": -7,
            "z": 10,
            "elements": [
                "astralsorcery:blockmarble@3"
            ]
        },
        {
            "x": -6,
            "y": -7,
            "z": 10,
            "elements": [
                "astralsorcery:blockmarble@3"
            ]
        },
        {
            "x": -5,
            "y": -7,
            "z": 10,
            "elements": [
                "astralsorcery:blockmarble@3"
            ]
        },
        {
            "x": -4,
            "y": -7,
            "z": 10,
            "elements": [
                "astralsorcery:blockmarble@3"
            ]
        },
        {
            "x": -3,
            "y": -7,
            "z": 10,
            "elements": [
                "astralsorcery:blockmarble@3"
            ]
        },
        {
            "x": 3,
            "y": -7,
            "z": 10,
            "elements": [
                "astralsorcery:blockmarble@3"
            ]
        },
        {
            "x": 4,
            "y": -7,
            "z": 10,
            "elements": [
                "astralsorcery:blockmarble@3"
            ]
        },
        {
            "x": 5,
            "y": -7,
            "z": 10,
            "elements": [
                "astralsorcery:blockmarble@3"
            ]
        },
        {
            "x": 6,
            "y": -7,
            "z": 10,
            "elements": [
                "astralsorcery:blockmarble@3"
            ]
        },
        {
            "x": 7,
            "y": -7,
            "z": 10,
            "elements": [
                "astralsorcery:blockmarble@3"
            ]
        },
        {
            "x": -7,
            "y": -6,
            "z": 10,
            "elements": [
                "astralsorcery:blockmarble@6"
            ]
        },
        {
            "x": -6,
            "y": -6,
            "z": 10,
            "elements": [
                "botania:managlass@0"
            ]
        },
        {
            "x": 7,
            "y": -7,
            "z": 0,
            "elements": [
                "astralsorcery:blockmarble@3"
            ]
        },
        {
            "x": 6,
            "y": -7,
            "z": 0,
            "elements": [
                "astralsorcery:blockmarble@0"
            ]
        },
        {
            "x": 5,
            "y": -7,
            "z": 0,
            "elements": [
                "astralsorcery:blockblackmarble@0"
            ]
        },
        {
            "x": 4,
            "y": -7,
            "z": 0,
            "elements": [
                "astralsorcery:blockblackmarble@0"
            ]
        },
        {
            "x": 3,
            "y": -7,
            "z": 0,
            "elements": [
                "astralsorcery:blockblackmarble@0"
            ]
        },
        {
            "x": 2,
            "y": -7,
            "z": 0,
            "elements": [
                "astralsorcery:blockblackmarble@0"
            ]
        },
        {
            "x": 6,
            "y": -6,
            "z": 10,
            "elements": [
                "botania:managlass@0"
            ]
        },
        {
            "x": 1,
            "y": -7,
            "z": 0,
            "elements": [
                "astralsorcery:blockblackmarble@0"
            ]
        },
        {
            "x": 7,
            "y": -6,
            "z": 10,
            "elements": [
                "astralsorcery:blockmarble@6"
            ]
        },
        {
            "x": 0,
            "y": -7,
            "z": 0,
            "elements": [
                "astralsorcery:blockblackmarble@0"
            ]
        },
        {
            "x": -1,
            "y": -7,
            "z": 0,
            "elements": [
                "astralsorcery:blockblackmarble@0"
            ]
        },
        {
            "x": -2,
            "y": -7,
            "z": 0,
            "elements": [
                "astralsorcery:blockblackmarble@0"
            ]
        },
        {
            "x": -3,
            "y": -7,
            "z": 0,
            "elements": [
                "astralsorcery:blockblackmarble@0"
            ]
        },
        {
            "x": -4,
            "y": -7,
            "z": 0,
            "elements": [
                "astralsorcery:blockblackmarble@0"
            ]
        },
        {
            "x": -5,
            "y": -7,
            "z": 0,
            "elements": [
                "astralsorcery:blockblackmarble@0"
            ]
        },
        {
            "x": -6,
            "y": -7,
            "z": 0,
            "elements": [
                "astralsorcery:blockmarble@0"
            ]
        },
        {
            "x": -7,
            "y": -7,
            "z": 0,
            "elements": [
                "astralsorcery:blockmarble@3"
            ]
        },
        {
            "x": -7,
            "y": -5,
            "z": 10,
            "elements": [
                "astralsorcery:blockmarble@2"
            ]
        },
        {
            "x": -7,
            "y": -7,
            "z": 9,
            "elements": [
                "astralsorcery:blockmarble@3"
            ]
        },
        {
            "x": -6,
            "y": -5,
            "z": 10,
            "elements": [
                "botania:managlass@0"
            ]
        },
        {
            "x": -6,
            "y": -7,
            "z": 9,
            "elements": [
                "astralsorcery:blockmarble@0"
            ]
        },
        {
            "x": -5,
            "y": -7,
            "z": 9,
            "elements": [
                "astralsorcery:blockmarble@0"
            ]
        },
        {
            "x": -4,
            "y": -7,
            "z": 9,
            "elements": [
                "astralsorcery:blockmarble@0"
            ]
        },
        {
            "x": -3,
            "y": -7,
            "z": 9,
            "elements": [
                "astralsorcery:blockmarble@0"
            ]
        },
        {
            "x": -2,
            "y": -7,
            "z": 9,
            "elements": [
                "astralsorcery:blockmarble@3"
            ]
        },
        {
            "x": -1,
            "y": -7,
            "z": 9,
            "elements": [
                "astralsorcery:blockmarble@3"
            ]
        },
        {
            "x": 0,
            "y": -7,
            "z": 9,
            "elements": [
                "astralsorcery:blockmarble@3"
            ]
        },
        {
            "x": 1,
            "y": -7,
            "z": 9,
            "elements": [
                "astralsorcery:blockmarble@3"
            ]
        },
        {
            "x": 2,
            "y": -7,
            "z": 9,
            "elements": [
                "astralsorcery:blockmarble@3"
            ]
        },
        {
            "x": 3,
            "y": -7,
            "z": 9,
            "elements": [
                "astralsorcery:blockmarble@0"
            ]
        },
        {
            "x": 4,
            "y": -7,
            "z": 9,
            "elements": [
                "astralsorcery:blockmarble@0"
            ]
        },
        {
            "x": 5,
            "y": -7,
            "z": 9,
            "elements": [
                "astralsorcery:blockmarble@0"
            ]
        },
        {
            "x": 6,
            "y": -5,
            "z": 10,
            "elements": [
                "botania:managlass@0"
            ]
        },
        {
            "x": 6,
            "y": -7,
            "z": 9,
            "elements": [
                "astralsorcery:blockmarble@0"
            ]
        },
        {
            "x": 7,
            "y": -5,
            "z": 10,
            "elements": [
                "astralsorcery:blockmarble@2"
            ]
        },
        {
            "x": 7,
            "y": -7,
            "z": 9,
            "elements": [
                "astralsorcery:blockmarble@3"
            ]
        },
        {
            "x": -7,
            "y": -4,
            "z": 10,
            "elements": [
                "astralsorcery:blockmarble@2"
            ]
        },
        {
            "x": -7,
            "y": -6,
            "z": 9,
            "elements": [
                "botania:managlass@0"
            ]
        },
        {
            "x": -6,
            "y": -4,
            "z": 10,
            "elements": [
                "botania:managlass@0"
            ]
        },
        {
            "x": -6,
            "y": -6,
            "z": 9,
            "elements": [
                "enderio:block_fluid_cloud_seed_concentrated@0"
            ]
        },
        {
            "x": -5,
            "y": -6,
            "z": 9,
            "elements": [
                "botania:managlass@0"
            ]
        },
        {
            "x": 5,
            "y": -6,
            "z": 9,
            "elements": [
                "botania:managlass@0"
            ]
        },
        {
            "x": 6,
            "y": -4,
            "z": 10,
            "elements": [
                "botania:managlass@0"
            ]
        },
        {
            "x": 6,
            "y": -6,
            "z": 9,
            "elements": [
                "contenttweaker:molten_compact_machine_wall@0"
            ]
        },
        {
            "x": 7,
            "y": -4,
            "z": 10,
            "elements": [
                "astralsorcery:blockmarble@2"
            ]
        },
        {
            "x": 7,
            "y": -6,
            "z": 9,
            "elements": [
                "botania:managlass@0"
            ]
        },
        {
            "x": -7,
            "y": -3,
            "z": 10,
            "elements": [
                "astralsorcery:blockmarble@2"
            ]
        },
        {
            "x": -7,
            "y": -5,
            "z": 9,
            "elements": [
                "botania:managlass@0"
            ]
        },
        {
            "x": -6,
            "y": -3,
            "z": 10,
            "elements": [
                "botania:managlass@0"
            ]
        },
        {
            "x": -7,
            "y": -7,
            "z": 8,
            "elements": [
                "astralsorcery:blockmarble@3"
            ]
        },
        {
            "x": -6,
            "y": -5,
            "z": 9,
            "elements": [
                "enderio:block_fluid_cloud_seed_concentrated@0"
            ]
        },
        {
            "x": -6,
            "y": -7,
            "z": 8,
            "elements": [
                "astralsorcery:blockmarble@0"
            ]
        },
        {
            "x": -5,
            "y": -5,
            "z": 9,
            "elements": [
                "botania:managlass@0"
            ]
        },
        {
            "x": -5,
            "y": -7,
            "z": 8,
            "elements": [
                "astralsorcery:blockblackmarble@0"
            ]
        },
        {
            "x": -4,
            "y": -7,
            "z": 8,
            "elements": [
                "astralsorcery:blockblackmarble@0"
            ]
        },
        {
            "x": -3,
            "y": -7,
            "z": 8,
            "elements": [
                "astralsorcery:blockblackmarble@0"
            ]
        },
        {
            "x": -2,
            "y": -7,
            "z": 8,
            "elements": [
                "astralsorcery:blockmarble@0"
            ]
        },
        {
            "x": -1,
            "y": -7,
            "z": 8,
            "elements": [
                "astralsorcery:blockmarble@0"
            ]
        },
        {
            "x": 0,
            "y": -7,
            "z": 8,
            "elements": [
                "astralsorcery:blockmarble@0"
            ]
        },
        {
            "x": 1,
            "y": -7,
            "z": 8,
            "elements": [
                "astralsorcery:blockmarble@0"
            ]
        },
        {
            "x": 2,
            "y": -7,
            "z": 8,
            "elements": [
                "astralsorcery:blockmarble@0"
            ]
        },
        {
            "x": 3,
            "y": -7,
            "z": 8,
            "elements": [
                "astralsorcery:blockblackmarble@0"
            ]
        },
        {
            "x": 4,
            "y": -7,
            "z": 8,
            "elements": [
                "astralsorcery:blockblackmarble@0"
            ]
        },
        {
            "x": 5,
            "y": -5,
            "z": 9,
            "elements": [
                "botania:managlass@0"
            ]
        },
        {
            "x": 6,
            "y": -3,
            "z": 10,
            "elements": [
                "botania:managlass@0"
            ]
        },
        {
            "x": 5,
            "y": -7,
            "z": 8,
            "elements": [
                "astralsorcery:blockblackmarble@0"
            ]
        },
        {
            "x": 6,
            "y": -5,
            "z": 9,
            "elements": [
                "contenttweaker:molten_compact_machine_wall@0"
            ]
        },
        {
            "x": 7,
            "y": -3,
            "z": 10,
            "elements": [
                "astralsorcery:blockmarble@2"
            ]
        },
        {
            "x": 6,
            "y": -7,
            "z": 8,
            "elements": [
                "astralsorcery:blockmarble@0"
            ]
        },
        {
            "x": 7,
            "y": -5,
            "z": 9,
            "elements": [
                "botania:managlass@0"
            ]
        },
        {
            "x": 7,
            "y": -7,
            "z": 8,
            "elements": [
                "astralsorcery:blockmarble@3"
            ]
        },
        {
            "x": -7,
            "y": -2,
            "z": 10,
            "elements": [
                "astralsorcery:blockmarble@4"
            ]
        },
        {
            "x": -7,
            "y": -4,
            "z": 9,
            "elements": [
                "botania:managlass@0"
            ]
        },
        {
            "x": -6,
            "y": -2,
            "z": 10,
            "elements": [
                "astralsorcery:blockmarble@4"
            ]
        },
        {
            "x": -6,
            "y": -4,
            "z": 9,
            "elements": [
                "enderio:block_fluid_cloud_seed_concentrated@0"
            ]
        },
        {
            "x": -5,
            "y": -2,
            "z": 10,
            "elements": [
                "astralsorcery:blockmarble@4"
            ]
        },
        {
            "x": -6,
            "y": -6,
            "z": 8,
            "elements": [
                "botania:managlass@0"
            ]
        },
        {
            "x": -5,
            "y": -4,
            "z": 9,
            "elements": [
                "botania:managlass@0"
            ]
        },
        {
            "x": 5,
            "y": -2,
            "z": 10,
            "elements": [
                "astralsorcery:blockmarble@4"
            ]
        },
        {
            "x": 5,
            "y": -4,
            "z": 9,
            "elements": [
                "botania:managlass@0"
            ]
        },
        {
            "x": 6,
            "y": -2,
            "z": 10,
            "elements": [
                "astralsorcery:blockmarble@4"
            ]
        },
        {
            "x": 6,
            "y": -4,
            "z": 9,
            "elements": [
                "contenttweaker:molten_compact_machine_wall@0"
            ]
        },
        {
            "x": 7,
            "y": -2,
            "z": 10,
            "elements": [
                "astralsorcery:blockmarble@4"
            ]
        },
        {
            "x": 6,
            "y": -6,
            "z": 8,
            "elements": [
                "botania:managlass@0"
            ]
        },
        {
            "x": 7,
            "y": -4,
            "z": 9,
            "elements": [
                "botania:managlass@0"
            ]
        },
        {
            "x": -7,
            "y": -3,
            "z": 9,
            "elements": [
                "botania:managlass@0"
            ]
        },
        {
            "x": -6,
            "y": -3,
            "z": 9,
            "elements": [
                "enderio:block_fluid_cloud_seed_concentrated@0"
            ]
        },
        {
            "x": -7,
            "y": -7,
            "z": 7,
            "elements": [
                "astralsorcery:blockmarble@3"
            ]
        },
        {
            "x": -6,
            "y": -5,
            "z": 8,
            "elements": [
                "botania:managlass@0"
            ]
        },
        {
            "x": -5,
            "y": -3,
            "z": 9,
            "elements": [
                "botania:managlass@0"
            ]
        },
        {
            "x": -6,
            "y": -7,
            "z": 7,
            "elements": [
                "astralsorcery:blockmarble@0"
            ]
        },
        {
            "x": -5,
            "y": -7,
            "z": 7,
            "elements": [
                "astralsorcery:blockblackmarble@0"
            ]
        },
        {
            "x": -4,
            "y": -7,
            "z": 7,
            "elements": [
                "astralsorcery:blockblackmarble@0"
            ]
        },
        {
            "x": -3,
            "y": -7,
            "z": 7,
            "elements": [
                "astralsorcery:blockblackmarble@0"
            ]
        },
        {
            "x": -2,
            "y": -7,
            "z": 7,
            "elements": [
                "astralsorcery:blockblackmarble@0"
            ]
        },
        {
            "x": -1,
            "y": -7,
            "z": 7,
            "elements": [
                "astralsorcery:blockblackmarble@0"
            ]
        },
        {
            "x": 0,
            "y": -7,
            "z": 7,
            "elements": [
                "astralsorcery:blockblackmarble@0"
            ]
        },
        {
            "x": 1,
            "y": -7,
            "z": 7,
            "elements": [
                "astralsorcery:blockblackmarble@0"
            ]
        },
        {
            "x": 2,
            "y": -7,
            "z": 7,
            "elements": [
                "astralsorcery:blockblackmarble@0"
            ]
        },
        {
            "x": 3,
            "y": -7,
            "z": 7,
            "elements": [
                "astralsorcery:blockblackmarble@0"
            ]
        },
        {
            "x": 5,
            "y": -3,
            "z": 9,
            "elements": [
                "botania:managlass@0"
            ]
        },
        {
            "x": 4,
            "y": -7,
            "z": 7,
            "elements": [
                "astralsorcery:blockblackmarble@0"
            ]
        },
        {
            "x": 6,
            "y": -3,
            "z": 9,
            "elements": [
                "contenttweaker:molten_compact_machine_wall@0"
            ]
        },
        {
            "x": 5,
            "y": -7,
            "z": 7,
            "elements": [
                "astralsorcery:blockblackmarble@0"
            ]
        },
        {
            "x": 6,
            "y": -5,
            "z": 8,
            "elements": [
                "botania:managlass@0"
            ]
        },
        {
            "x": 7,
            "y": -3,
            "z": 9,
            "elements": [
                "botania:managlass@0"
            ]
        },
        {
            "x": 6,
            "y": -7,
            "z": 7,
            "elements": [
                "astralsorcery:blockmarble@0"
            ]
        },
        {
            "x": 7,
            "y": -7,
            "z": 7,
            "elements": [
                "astralsorcery:blockmarble@3"
            ]
        },
        {
            "x": -7,
            "y": -2,
            "z": 9,
            "elements": [
                "astralsorcery:blockmarble@4"
            ]
        },
        {
            "x": -6,
            "y": -2,
            "z": 9,
            "elements": [
                "botania:managlass@0"
            ]
        },
        {
            "x": -6,
            "y": -4,
            "z": 8,
            "elements": [
                "botania:managlass@0"
            ]
        },
        {
            "x": -4,
            "y": -6,
            "z": 7,
            "elements": [
                "astralsorcery:blockinfusedwood@2"
            ]
        },
        {
            "x": 4,
            "y": -6,
            "z": 7,
            "elements": [
                "astralsorcery:blockinfusedwood@2"
            ]
        },
        {
            "x": 6,
            "y": -2,
            "z": 9,
            "elements": [
                "botania:managlass@0"
            ]
        },
        {
            "x": 6,
            "y": -4,
            "z": 8,
            "elements": [
                "botania:managlass@0"
            ]
        },
        {
            "x": 7,
            "y": -2,
            "z": 9,
            "elements": [
                "astralsorcery:blockmarble@4"
            ]
        },
        {
            "x": -6,
            "y": -1,
            "z": 9,
            "elements": [
                "astralsorcery:blockmarble@4"
            ]
        },
        {
            "x": -6,
            "y": -3,
            "z": 8,
            "elements": [
                "botania:managlass@0"
            ]
        },
        {
            "x": -5,
            "y": -1,
            "z": 9,
            "elements": [
                "astralsorcery:blockmarble@4"
            ]
        },
        {
            "x": -7,
            "y": -7,
            "z": 6,
            "elements": [
                "astralsorcery:blockmarble@3"
            ]
        },
        {
            "x": -4,
            "y": -1,
            "z": 9,
            "elements": [
                "astralsorcery:blockmarble@4"
            ]
        },
        {
            "x": -6,
            "y": -7,
            "z": 6,
            "elements": [
                "astralsorcery:blockmarble@0"
            ]
        },
        {
            "x": -3,
            "y": -1,
            "z": 9,
            "elements": [
                "astralsorcery:blockmarble@4"
            ]
        },
        {
            "x": -5,
            "y": -7,
            "z": 6,
            "elements": [
                "astralsorcery:blockblackmarble@0"
            ]
        },
        {
            "x": -4,
            "y": -5,
            "z": 7,
            "elements": [
                "astralsorcery:blockinfusedwood@2"
            ]
        },
        {
            "x": -4,
            "y": -7,
            "z": 6,
            "elements": [
                "astralsorcery:blockblackmarble@0"
            ]
        },
        {
            "x": -3,
            "y": -7,
            "z": 6,
            "elements": [
                "astralsorcery:blockblackmarble@0"
            ]
        },
        {
            "x": -2,
            "y": -7,
            "z": 6,
            "elements": [
                "astralsorcery:blockblackmarble@0"
            ]
        },
        {
            "x": -1,
            "y": -7,
            "z": 6,
            "elements": [
                "astralsorcery:blockblackmarble@0"
            ]
        },
        {
            "x": 0,
            "y": -7,
            "z": 6,
            "elements": [
                "astralsorcery:blockblackmarble@0"
            ]
        },
        {
            "x": 3,
            "y": -1,
            "z": 9,
            "elements": [
                "astralsorcery:blockmarble@4"
            ]
        },
        {
            "x": 1,
            "y": -7,
            "z": 6,
            "elements": [
                "astralsorcery:blockblackmarble@0"
            ]
        },
        {
            "x": 4,
            "y": -1,
            "z": 9,
            "elements": [
                "astralsorcery:blockmarble@4"
            ]
        },
        {
            "x": 2,
            "y": -7,
            "z": 6,
            "elements": [
                "astralsorcery:blockblackmarble@0"
            ]
        },
        {
            "x": 5,
            "y": -1,
            "z": 9,
            "elements": [
                "astralsorcery:blockmarble@4"
            ]
        },
        {
            "x": 3,
            "y": -7,
            "z": 6,
            "elements": [
                "astralsorcery:blockblackmarble@0"
            ]
        },
        {
            "x": 4,
            "y": -5,
            "z": 7,
            "elements": [
                "astralsorcery:blockinfusedwood@2"
            ]
        },
        {
            "x": 6,
            "y": -1,
            "z": 9,
            "elements": [
                "astralsorcery:blockmarble@4"
            ]
        },
        {
            "x": 4,
            "y": -7,
            "z": 6,
            "elements": [
                "astralsorcery:blockblackmarble@0"
            ]
        },
        {
            "x": 6,
            "y": -3,
            "z": 8,
            "elements": [
                "botania:managlass@0"
            ]
        },
        {
            "x": 5,
            "y": -7,
            "z": 6,
            "elements": [
                "astralsorcery:blockblackmarble@0"
            ]
        },
        {
            "x": 6,
            "y": -7,
            "z": 6,
            "elements": [
                "astralsorcery:blockmarble@0"
            ]
        },
        {
            "x": 7,
            "y": -7,
            "z": 6,
            "elements": [
                "astralsorcery:blockmarble@3"
            ]
        },
        {
            "x": -7,
            "y": -2,
            "z": 8,
            "elements": [
                "astralsorcery:blockmarble@4"
            ]
        },
        {
            "x": -4,
            "y": -4,
            "z": 7,
            "elements": [
                "astralsorcery:blockinfusedwood@2"
            ]
        },
        {
            "x": 4,
            "y": -4,
            "z": 7,
            "elements": [
                "astralsorcery:blockinfusedwood@2"
            ]
        },
        {
            "x": 7,
            "y": -2,
            "z": 8,
            "elements": [
                "astralsorcery:blockmarble@4"
            ]
        },
        {
            "x": -6,
            "y": -1,
            "z": 8,
            "elements": [
                "astralsorcery:blockmarble@4"
            ]
        },
        {
            "x": -5,
            "y": -1,
            "z": 8,
            "elements": [
                "botania:managlass@0"
            ]
        },
        {
            "x": -4,
            "y": -1,
            "z": 8,
            "elements": [
                "botania:managlass@0"
            ]
        },
        {
            "x": -6,
            "y": -7,
            "z": 5,
            "elements": [
                "astralsorcery:blockmarble@3"
            ]
        },
        {
            "x": -4,
            "y": -3,
            "z": 7,
            "elements": [
                "astralsorcery:blockinfusedwood@2"
            ]
        },
        {
            "x": -3,
            "y": -1,
            "z": 8,
            "elements": [
                "botania:managlass@0"
            ]
        },
        {
            "x": -5,
            "y": -7,
            "z": 5,
            "elements": [
                "astralsorcery:blockmarble@0"
            ]
        },
        {
            "x": -4,
            "y": -7,
            "z": 5,
            "elements": [
                "astralsorcery:blockblackmarble@0"
            ]
        },
        {
            "x": -3,
            "y": -7,
            "z": 5,
            "elements": [
                "astralsorcery:blockblackmarble@0"
            ]
        },
        {
            "x": -2,
            "y": -7,
            "z": 5,
            "elements": [
                "astralsorcery:blockblackmarble@0"
            ]
        },
        {
            "x": -1,
            "y": -7,
            "z": 5,
            "elements": [
                "astralsorcery:blockblackmarble@0"
            ]
        },
        {
            "x": 0,
            "y": -7,
            "z": 5,
            "elements": [
                "astralsorcery:blockblackmarble@0"
            ]
        },
        {
            "x": 3,
            "y": -1,
            "z": 8,
            "elements": [
                "botania:managlass@0"
            ]
        },
        {
            "x": 1,
            "y": -7,
            "z": 5,
            "elements": [
                "astralsorcery:blockblackmarble@0"
            ]
        },
        {
            "x": 4,
            "y": -1,
            "z": 8,
            "elements": [
                "botania:managlass@0"
            ]
        },
        {
            "x": 2,
            "y": -7,
            "z": 5,
            "elements": [
                "astralsorcery:blockblackmarble@0"
            ]
        },
        {
            "x": 4,
            "y": -3,
            "z": 7,
            "elements": [
                "astralsorcery:blockinfusedwood@2"
            ]
        },
        {
            "x": 5,
            "y": -1,
            "z": 8,
            "elements": [
                "botania:managlass@0"
            ]
        },
        {
            "x": 3,
            "y": -7,
            "z": 5,
            "elements": [
                "astralsorcery:blockblackmarble@0"
            ]
        },
        {
            "x": 6,
            "y": -1,
            "z": 8,
            "elements": [
                "astralsorcery:blockmarble@4"
            ]
        },
        {
            "x": 4,
            "y": -7,
            "z": 5,
            "elements": [
                "astralsorcery:blockblackmarble@0"
            ]
        },
        {
            "x": 5,
            "y": -7,
            "z": 5,
            "elements": [
                "astralsorcery:blockmarble@0"
            ]
        },
        {
            "x": 6,
            "y": -7,
            "z": 5,
            "elements": [
                "astralsorcery:blockmarble@3"
            ]
        },
        {
            "x": -4,
            "y": -2,
            "z": 7,
            "elements": [
                "astralsorcery:blockinfusedwood@2"
            ]
        },
        {
            "x": 4,
            "y": -2,
            "z": 7,
            "elements": [
                "astralsorcery:blockinfusedwood@2"
            ]
        },
        {
            "x": -6,
            "y": -1,
            "z": 7,
            "elements": [
                "astralsorcery:blockmarble@4"
            ]
        },
        {
            "x": -5,
            "y": -1,
            "z": 7,
            "elements": [
                "botania:managlass@0"
            ]
        },
        {
            "x": -4,
            "y": -1,
            "z": 7,
            "elements": [
                "botania:managlass@0"
            ]
        },
        {
            "x": -6,
            "y": -7,
            "z": 4,
            "elements": [
                "astralsorcery:blockmarble@3"
            ]
        },
        {
            "x": -3,
            "y": -1,
            "z": 7,
            "elements": [
                "botania:managlass@0"
            ]
        },
        {
            "x": -5,
            "y": -7,
            "z": 4,
            "elements": [
                "astralsorcery:blockmarble@0"
            ]
        },
        {
            "x": -4,
            "y": -7,
            "z": 4,
            "elements": [
                "astralsorcery:blockblackmarble@0"
            ]
        },
        {
            "x": -3,
            "y": -7,
            "z": 4,
            "elements": [
                "astralsorcery:blockblackmarble@0"
            ]
        },
        {
            "x": -2,
            "y": -7,
            "z": 4,
            "elements": [
                "astralsorcery:blockblackmarble@0"
            ]
        },
        {
            "x": -1,
            "y": -7,
            "z": 4,
            "elements": [
                "astralsorcery:blockblackmarble@0"
            ]
        },
        {
            "x": 0,
            "y": -7,
            "z": 4,
            "elements": [
                "astralsorcery:blockblackmarble@0"
            ]
        },
        {
            "x": 3,
            "y": -1,
            "z": 7,
            "elements": [
                "botania:managlass@0"
            ]
        },
        {
            "x": 1,
            "y": -7,
            "z": 4,
            "elements": [
                "astralsorcery:blockblackmarble@0"
            ]
        },
        {
            "x": 4,
            "y": -1,
            "z": 7,
            "elements": [
                "botania:managlass@0"
            ]
        },
        {
            "x": 2,
            "y": -7,
            "z": 4,
            "elements": [
                "astralsorcery:blockblackmarble@0"
            ]
        },
        {
            "x": 5,
            "y": -1,
            "z": 7,
            "elements": [
                "botania:managlass@0"
            ]
        },
        {
            "x": 3,
            "y": -7,
            "z": 4,
            "elements": [
                "astralsorcery:blockblackmarble@0"
            ]
        },
        {
            "x": 6,
            "y": -1,
            "z": 7,
            "elements": [
                "astralsorcery:blockmarble@4"
            ]
        },
        {
            "x": 4,
            "y": -7,
            "z": 4,
            "elements": [
                "astralsorcery:blockblackmarble@0"
            ]
        },
        {
            "x": 5,
            "y": -7,
            "z": 4,
            "elements": [
                "astralsorcery:blockmarble@0"
            ]
        },
        {
            "x": 6,
            "y": -7,
            "z": 4,
            "elements": [
                "astralsorcery:blockmarble@3"
            ]
        },
        {
            "x": -6,
            "y": -1,
            "z": 6,
            "elements": [
                "astralsorcery:blockmarble@4"
            ]
        },
        {
            "x": -5,
            "y": -1,
            "z": 6,
            "elements": [
                "botania:managlass@0"
            ]
        },
        {
            "x": -4,
            "y": -1,
            "z": 6,
            "elements": [
                "botania:managlass@0"
            ]
        },
        {
            "x": -6,
            "y": -7,
            "z": 3,
            "elements": [
                "astralsorcery:blockmarble@3"
            ]
        },
        {
            "x": -3,
            "y": -1,
            "z": 6,
            "elements": [
                "botania:managlass@0"
            ]
        },
        {
            "x": -5,
            "y": -7,
            "z": 3,
            "elements": [
                "astralsorcery:blockmarble@0"
            ]
        },
        {
            "x": -4,
            "y": -7,
            "z": 3,
            "elements": [
                "astralsorcery:blockblackmarble@0"
            ]
        },
        {
            "x": -3,
            "y": -7,
            "z": 3,
            "elements": [
                "astralsorcery:blockblackmarble@0"
            ]
        },
        {
            "x": -2,
            "y": -7,
            "z": 3,
            "elements": [
                "astralsorcery:blockblackmarble@0"
            ]
        },
        {
            "x": -1,
            "y": -7,
            "z": 3,
            "elements": [
                "astralsorcery:blockblackmarble@0"
            ]
        },
        {
            "x": 0,
            "y": -7,
            "z": 3,
            "elements": [
                "astralsorcery:blockblackmarble@0"
            ]
        },
        {
            "x": 3,
            "y": -1,
            "z": 6,
            "elements": [
                "botania:managlass@0"
            ]
        },
        {
            "x": 1,
            "y": -7,
            "z": 3,
            "elements": [
                "astralsorcery:blockblackmarble@0"
            ]
        },
        {
            "x": 4,
            "y": -1,
            "z": 6,
            "elements": [
                "botania:managlass@0"
            ]
        },
        {
            "x": 2,
            "y": -7,
            "z": 3,
            "elements": [
                "astralsorcery:blockblackmarble@0"
            ]
        },
        {
            "x": 5,
            "y": -1,
            "z": 6,
            "elements": [
                "botania:managlass@0"
            ]
        },
        {
            "x": 3,
            "y": -7,
            "z": 3,
            "elements": [
                "astralsorcery:blockblackmarble@0"
            ]
        },
        {
            "x": 6,
            "y": -1,
            "z": 6,
            "elements": [
                "astralsorcery:blockmarble@4"
            ]
        },
        {
            "x": 4,
            "y": -7,
            "z": 3,
            "elements": [
                "astralsorcery:blockblackmarble@0"
            ]
        },
        {
            "x": 5,
            "y": -7,
            "z": 3,
            "elements": [
                "astralsorcery:blockmarble@0"
            ]
        },
        {
            "x": 6,
            "y": -7,
            "z": 3,
            "elements": [
                "astralsorcery:blockmarble@3"
            ]
        },
        {
            "x": -2,
            "y": 0,
            "z": 6,
            "elements": [
                "astralsorcery:blockmarble@6"
            ]
        },
        {
            "x": -1,
            "y": 0,
            "z": 6,
            "elements": [
                "astralsorcery:blockmarble@6"
            ]
        },
        {
            "x": 0,
            "y": 0,
            "z": 6,
            "elements": [
                "modularmachinery:blockinputbus"
            ]
        },
        {
            "x": 1,
            "y": 0,
            "z": 6,
            "elements": [
                "astralsorcery:blockmarble@6"
            ]
        },
        {
            "x": 2,
            "y": 0,
            "z": 6,
            "elements": [
                "astralsorcery:blockmarble@6"
            ]
        },
        {
            "x": 0,
            "y": -6,
            "z": 3,
            "elements": [
                "astralsorcery:blockaltar@3"
            ]
        },
        {
            "x": -6,
            "y": -7,
            "z": 2,
            "elements": [
                "astralsorcery:blockmarble@3"
            ]
        },
        {
            "x": -5,
            "y": -7,
            "z": 2,
            "elements": [
                "astralsorcery:blockmarble@0"
            ]
        },
        {
            "x": -4,
            "y": -7,
            "z": 2,
            "elements": [
                "astralsorcery:blockblackmarble@0"
            ]
        },
        {
            "x": -3,
            "y": -7,
            "z": 2,
            "elements": [
                "astralsorcery:blockblackmarble@0"
            ]
        },
        {
            "x": -2,
            "y": -7,
            "z": 2,
            "elements": [
                "astralsorcery:blockblackmarble@0"
            ]
        },
        {
            "x": -1,
            "y": -7,
            "z": 2,
            "elements": [
                "astralsorcery:blockblackmarble@0"
            ]
        },
        {
            "x": 0,
            "y": -7,
            "z": 2,
            "elements": [
                "astralsorcery:blockblackmarble@0"
            ]
        },
        {
            "x": 1,
            "y": -7,
            "z": 2,
            "elements": [
                "astralsorcery:blockblackmarble@0"
            ]
        },
        {
            "x": 2,
            "y": -7,
            "z": 2,
            "elements": [
                "astralsorcery:blockblackmarble@0"
            ]
        },
        {
            "x": 3,
            "y": -7,
            "z": 2,
            "elements": [
                "astralsorcery:blockblackmarble@0"
            ]
        },
        {
            "x": 4,
            "y": -7,
            "z": 2,
            "elements": [
                "astralsorcery:blockblackmarble@0"
            ]
        },
        {
            "x": 5,
            "y": -7,
            "z": 2,
            "elements": [
                "astralsorcery:blockmarble@0"
            ]
        },
        {
            "x": 6,
            "y": -7,
            "z": 2,
            "elements": [
                "astralsorcery:blockmarble@3"
            ]
        },
        {
            "x": -3,
            "y": 0,
            "z": 5,
            "elements": [
                "astralsorcery:blockmarble@6"
            ]
        },
        {
            "x": 3,
            "y": 0,
            "z": 5,
            "elements": [
                "astralsorcery:blockmarble@6"
            ]
        },
        {
            "x": -6,
            "y": -7,
            "z": 1,
            "elements": [
                "astralsorcery:blockmarble@3"
            ]
        },
        {
            "x": -2,
            "y": 1,
            "z": 5,
            "elements": [
                "astralsorcery:blockmarble@6"
            ]
        },
        {
            "x": -5,
            "y": -7,
            "z": 1,
            "elements": [
                "astralsorcery:blockmarble@0"
            ]
        },
        {
            "x": -1,
            "y": 1,
            "z": 5,
            "elements": [
                "astralsorcery:blockmarble@6"
            ]
        },
        {
            "x": -4,
            "y": -7,
            "z": 1,
            "elements": [
                "astralsorcery:blockblackmarble@0"
            ]
        },
        {
            "x": 0,
            "y": 1,
            "z": 5,
            "elements": [
                "astralsorcery:blockmarble@6"
            ]
        },
        {
            "x": -3,
            "y": -7,
            "z": 1,
            "elements": [
                "astralsorcery:blockblackmarble@0"
            ]
        },
        {
            "x": 1,
            "y": 1,
            "z": 5,
            "elements": [
                "astralsorcery:blockmarble@6"
            ]
        },
        {
            "x": -2,
            "y": -7,
            "z": 1,
            "elements": [
                "astralsorcery:blockblackmarble@0"
            ]
        },
        {
            "x": 2,
            "y": 1,
            "z": 5,
            "elements": [
                "astralsorcery:blockmarble@6"
            ]
        },
        {
            "x": -1,
            "y": -7,
            "z": 1,
            "elements": [
                "astralsorcery:blockblackmarble@0"
            ]
        },
        {
            "x": 0,
            "y": -7,
            "z": 1,
            "elements": [
                "astralsorcery:blockblackmarble@0"
            ]
        },
        {
            "x": 1,
            "y": -7,
            "z": 1,
            "elements": [
                "astralsorcery:blockblackmarble@0"
            ]
        },
        {
            "x": 2,
            "y": -7,
            "z": 1,
            "elements": [
                "astralsorcery:blockblackmarble@0"
            ]
        },
        {
            "x": 3,
            "y": -7,
            "z": 1,
            "elements": [
                "astralsorcery:blockblackmarble@0"
            ]
        },
        {
            "x": 4,
            "y": -7,
            "z": 1,
            "elements": [
                "astralsorcery:blockblackmarble@0"
            ]
        },
        {
            "x": 5,
            "y": -7,
            "z": 1,
            "elements": [
                "astralsorcery:blockmarble@0"
            ]
        },
        {
            "x": 6,
            "y": -7,
            "z": 1,
            "elements": [
                "astralsorcery:blockmarble@3"
            ]
        },
        {
            "x": -3,
            "y": 0,
            "z": 4,
            "elements": [
                "astralsorcery:blockmarble@6"
            ]
        },
        {
            "x": 3,
            "y": 0,
            "z": 4,
            "elements": [
                "astralsorcery:blockmarble@6"
            ]
        },
        {
            "x": -2,
            "y": 1,
            "z": 4,
            "elements": [
                "astralsorcery:blockmarble@6"
            ]
        },
        {
            "x": -1,
            "y": 1,
            "z": 4,
            "elements": [
                "botania:elfglass@0"
            ]
        },
        {
            "x": 0,
            "y": 1,
            "z": 4,
            "elements": [
                "botania:elfglass@0"
            ]
        },
        {
            "x": 1,
            "y": 1,
            "z": 4,
            "elements": [
                "botania:elfglass@0"
            ]
        },
        {
            "x": 2,
            "y": 1,
            "z": 4,
            "elements": [
                "astralsorcery:blockmarble@6"
            ]
        },
        {
            "x": 7,
            "y": -2,
            "z": -4,
            "elements": [
                "astralsorcery:blockmarble@4"
            ]
        },
        {
            "x": 6,
            "y": -2,
            "z": -4,
            "elements": [
                "astralsorcery:blockmarble@4"
            ]
        },
        {
            "x": 5,
            "y": -2,
            "z": -4,
            "elements": [
                "astralsorcery:blockmarble@4"
            ]
        },
        {
            "x": -3,
            "y": 0,
            "z": 3,
            "elements": [
                "gugu-utils:environmenthatch@0"
            ]
        },
        {
            "x": 0,
            "y": 2,
            "z": 4,
            "elements": [
                "astralsorcery:blockrituallink@0"
            ]
        },
        {
            "x": -5,
            "y": -2,
            "z": -4,
            "elements": [
                "astralsorcery:blockmarble@4"
            ]
        },
        {
            "x": 3,
            "y": 0,
            "z": 3,
            "elements": [
                "gugu-utils:starlightinputhatch"
            ]
        },
        {
            "x": -6,
            "y": -2,
            "z": -4,
            "elements": [
                "astralsorcery:blockmarble@4"
            ]
        },
        {
            "x": -7,
            "y": -2,
            "z": -4,
            "elements": [
                "astralsorcery:blockmarble@4"
            ]
        },
        {
            "x": 7,
            "y": -3,
            "z": -4,
            "elements": [
                "astralsorcery:blockmarble@2"
            ]
        },
        {
            "x": 6,
            "y": -3,
            "z": -4,
            "elements": [
                "botania:managlass@0"
            ]
        },
        {
            "x": 6,
            "y": -1,
            "z": -3,
            "elements": [
                "astralsorcery:blockmarble@4"
            ]
        },
        {
            "x": 5,
            "y": -1,
            "z": -3,
            "elements": [
                "astralsorcery:blockmarble@4"
            ]
        },
        {
            "x": 4,
            "y": -1,
            "z": -3,
            "elements": [
                "astralsorcery:blockmarble@4"
            ]
        },
        {
            "x": 3,
            "y": -1,
            "z": -3,
            "elements": [
                "astralsorcery:blockmarble@4"
            ]
        },
        {
            "x": -2,
            "y": 1,
            "z": 3,
            "elements": [
                "astralsorcery:blockmarble@6"
            ]
        },
        {
            "x": -1,
            "y": 1,
            "z": 3,
            "elements": [
                "botania:elfglass@0"
            ]
        },
        {
            "x": 0,
            "y": 1,
            "z": 3,
            "elements": [
                "botania:elfglass@0"
            ]
        },
        {
            "x": 1,
            "y": 1,
            "z": 3,
            "elements": [
                "botania:elfglass@0"
            ]
        },
        {
            "x": -3,
            "y": -1,
            "z": -3,
            "elements": [
                "astralsorcery:blockmarble@4"
            ]
        },
        {
            "x": 2,
            "y": 1,
            "z": 3,
            "elements": [
                "astralsorcery:blockmarble@6"
            ]
        },
        {
            "x": -4,
            "y": -1,
            "z": -3,
            "elements": [
                "astralsorcery:blockmarble@4"
            ]
        },
        {
            "x": -6,
            "y": -3,
            "z": -4,
            "elements": [
                "botania:managlass@0"
            ]
        },
        {
            "x": -5,
            "y": -1,
            "z": -3,
            "elements": [
                "astralsorcery:blockmarble@4"
            ]
        },
        {
            "x": -7,
            "y": -3,
            "z": -4,
            "elements": [
                "astralsorcery:blockmarble@2"
            ]
        },
        {
            "x": -6,
            "y": -1,
            "z": -3,
            "elements": [
                "astralsorcery:blockmarble@4"
            ]
        },
        {
            "x": 7,
            "y": -4,
            "z": -4,
            "elements": [
                "astralsorcery:blockmarble@2"
            ]
        },
        {
            "x": 6,
            "y": -4,
            "z": -4,
            "elements": [
                "botania:managlass@0"
            ]
        },
        {
            "x": 7,
            "y": -2,
            "z": -3,
            "elements": [
                "astralsorcery:blockmarble@4"
            ]
        },
        {
            "x": 6,
            "y": -2,
            "z": -3,
            "elements": [
                "botania:managlass@0"
            ]
        },
        {
            "x": -3,
            "y": 0,
            "z": 2,
            "elements": [
                "astralsorcery:blockmarble@6"
            ]
        },
        {
            "x": -1,
            "y": 2,
            "z": 3,
            "elements": [
                "astralsorcery:blockrituallink@0"
            ]
        },
        {
            "x": 1,
            "y": 2,
            "z": 3,
            "elements": [
                "astralsorcery:blockrituallink@0"
            ]
        },
        {
            "x": -6,
            "y": -4,
            "z": -4,
            "elements": [
                "botania:managlass@0"
            ]
        },
        {
            "x": 3,
            "y": 0,
            "z": 2,
            "elements": [
                "astralsorcery:blockmarble@6"
            ]
        },
        {
            "x": -7,
            "y": -4,
            "z": -4,
            "elements": [
                "astralsorcery:blockmarble@2"
            ]
        },
        {
            "x": -6,
            "y": -2,
            "z": -3,
            "elements": [
                "botania:managlass@0"
            ]
        },
        {
            "x": -7,
            "y": -2,
            "z": -3,
            "elements": [
                "astralsorcery:blockmarble@4"
            ]
        },
        {
            "x": 7,
            "y": -5,
            "z": -4,
            "elements": [
                "astralsorcery:blockmarble@2"
            ]
        },
        {
            "x": 6,
            "y": -5,
            "z": -4,
            "elements": [
                "botania:managlass@0"
            ]
        },
        {
            "x": 7,
            "y": -3,
            "z": -3,
            "elements": [
                "botania:managlass@0"
            ]
        },
        {
            "x": 6,
            "y": -3,
            "z": -3,
            "elements": [
                "contenttweaker:fluid_runhuayou@0"
            ]
        },
        {
            "x": 5,
            "y": -3,
            "z": -3,
            "elements": [
                "botania:managlass@0"
            ]
        },
        {
            "x": 6,
            "y": -1,
            "z": -2,
            "elements": [
                "astralsorcery:blockmarble@4"
            ]
        },
        {
            "x": 5,
            "y": -1,
            "z": -2,
            "elements": [
                "botania:managlass@0"
            ]
        },
        {
            "x": 4,
            "y": -1,
            "z": -2,
            "elements": [
                "botania:managlass@0"
            ]
        },
        {
            "x": 3,
            "y": -1,
            "z": -2,
            "elements": [
                "botania:managlass@0"
            ]
        },
        {
            "x": -2,
            "y": 1,
            "z": 2,
            "elements": [
                "astralsorcery:blockmarble@6"
            ]
        },
        {
            "x": -1,
            "y": 1,
            "z": 2,
            "elements": [
                "botania:elfglass@0"
            ]
        },
        {
            "x": 0,
            "y": 1,
            "z": 2,
            "elements": [
                "botania:elfglass@0"
            ]
        },
        {
            "x": 1,
            "y": 1,
            "z": 2,
            "elements": [
                "botania:elfglass@0"
            ]
        },
        {
            "x": -3,
            "y": -1,
            "z": -2,
            "elements": [
                "botania:managlass@0"
            ]
        },
        {
            "x": 2,
            "y": 1,
            "z": 2,
            "elements": [
                "astralsorcery:blockmarble@6"
            ]
        },
        {
            "x": -6,
            "y": -5,
            "z": -4,
            "elements": [
                "botania:managlass@0"
            ]
        },
        {
            "x": -5,
            "y": -3,
            "z": -3,
            "elements": [
                "botania:managlass@0"
            ]
        },
        {
            "x": -4,
            "y": -1,
            "z": -2,
            "elements": [
                "botania:managlass@0"
            ]
        },
        {
            "x": -7,
            "y": -5,
            "z": -4,
            "elements": [
                "astralsorcery:blockmarble@2"
            ]
        },
        {
            "x": -6,
            "y": -3,
            "z": -3,
            "elements": [
                "enderio:block_fluid_liquid_sunshine@0"
            ]
        },
        {
            "x": -5,
            "y": -1,
            "z": -2,
            "elements": [
                "botania:managlass@0"
            ]
        },
        {
            "x": -7,
            "y": -3,
            "z": -3,
            "elements": [
                "botania:managlass@0"
            ]
        },
        {
            "x": -6,
            "y": -1,
            "z": -2,
            "elements": [
                "astralsorcery:blockmarble@4"
            ]
        },
        {
            "x": 7,
            "y": -6,
            "z": -4,
            "elements": [
                "astralsorcery:blockmarble@6"
            ]
        },
        {
            "x": 6,
            "y": -6,
            "z": -4,
            "elements": [
                "botania:managlass@0"
            ]
        },
        {
            "x": 7,
            "y": -4,
            "z": -3,
            "elements": [
                "botania:managlass@0"
            ]
        },
        {
            "x": 6,
            "y": -4,
            "z": -3,
            "elements": [
                "contenttweaker:fluid_runhuayou@0"
            ]
        },
        {
            "x": 7,
            "y": -2,
            "z": -2,
            "elements": [
                "astralsorcery:blockmarble@4"
            ]
        },
        {
            "x": 5,
            "y": -4,
            "z": -3,
            "elements": [
                "botania:managlass@0"
            ]
        },
        {
            "x": -3,
            "y": 0,
            "z": 1,
            "elements": [
                "astralsorcery:blockmarble@6"
            ]
        },
        {
            "x": 0,
            "y": 2,
            "z": 2,
            "elements": [
                "astralsorcery:blockrituallink@0"
            ]
        },
        {
            "x": -6,
            "y": -6,
            "z": -4,
            "elements": [
                "botania:managlass@0"
            ]
        },
        {
            "x": -5,
            "y": -4,
            "z": -3,
            "elements": [
                "botania:managlass@0"
            ]
        },
        {
            "x": -7,
            "y": -6,
            "z": -4,
            "elements": [
                "astralsorcery:blockmarble@6"
            ]
        },
        {
            "x": -6,
            "y": -4,
            "z": -3,
            "elements": [
                "enderio:block_fluid_liquid_sunshine@0"
            ]
        },
        {
            "x": 3,
            "y": 0,
            "z": 1,
            "elements": [
                "astralsorcery:blockmarble@6"
            ]
        },
        {
            "x": -7,
            "y": -4,
            "z": -3,
            "elements": [
                "botania:managlass@0"
            ]
        },
        {
            "x": -7,
            "y": -2,
            "z": -2,
            "elements": [
                "astralsorcery:blockmarble@4"
            ]
        },
        {
            "x": 7,
            "y": -7,
            "z": -4,
            "elements": [
                "astralsorcery:blockmarble@3"
            ]
        },
        {
            "x": 6,
            "y": -7,
            "z": -4,
            "elements": [
                "astralsorcery:blockmarble@3"
            ]
        },
        {
            "x": 7,
            "y": -5,
            "z": -3,
            "elements": [
                "botania:managlass@0"
            ]
        },
        {
            "x": 5,
            "y": -7,
            "z": -4,
            "elements": [
                "astralsorcery:blockmarble@3"
            ]
        },
        {
            "x": 6,
            "y": -5,
            "z": -3,
            "elements": [
                "contenttweaker:fluid_runhuayou@0"
            ]
        },
        {
            "x": 4,
            "y": -7,
            "z": -4,
            "elements": [
                "astralsorcery:blockmarble@3"
            ]
        },
        {
            "x": 5,
            "y": -5,
            "z": -3,
            "elements": [
                "botania:managlass@0"
            ]
        },
        {
            "x": 6,
            "y": -3,
            "z": -2,
            "elements": [
                "botania:managlass@0"
            ]
        },
        {
            "x": 3,
            "y": -7,
            "z": -4,
            "elements": [
                "astralsorcery:blockmarble@3"
            ]
        },
        {
            "x": 6,
            "y": -1,
            "z": -1,
            "elements": [
                "astralsorcery:blockmarble@4"
            ]
        },
        {
            "x": 5,
            "y": -1,
            "z": -1,
            "elements": [
                "botania:managlass@0"
            ]
        },
        {
            "x": 4,
            "y": -1,
            "z": -1,
            "elements": [
                "botania:managlass@0"
            ]
        },
        {
            "x": 3,
            "y": -1,
            "z": -1,
            "elements": [
                "botania:managlass@0"
            ]
        },
        {
            "x": -2,
            "y": 1,
            "z": 1,
            "elements": [
                "astralsorcery:blockmarble@6"
            ]
        },
        {
            "x": -3,
            "y": -7,
            "z": -4,
            "elements": [
                "astralsorcery:blockmarble@3"
            ]
        },
        {
            "x": -1,
            "y": 1,
            "z": 1,
            "elements": [
                "astralsorcery:blockmarble@6"
            ]
        },
        {
            "x": -4,
            "y": -7,
            "z": -4,
            "elements": [
                "astralsorcery:blockmarble@3"
            ]
        },
        {
            "x": 0,
            "y": 1,
            "z": 1,
            "elements": [
                "astralsorcery:blockmarble@6"
            ]
        },
        {
            "x": -5,
            "y": -7,
            "z": -4,
            "elements": [
                "astralsorcery:blockmarble@3"
            ]
        },
        {
            "x": 1,
            "y": 1,
            "z": 1,
            "elements": [
                "astralsorcery:blockmarble@6"
            ]
        },
        {
            "x": -6,
            "y": -7,
            "z": -4,
            "elements": [
                "astralsorcery:blockmarble@3"
            ]
        },
        {
            "x": -5,
            "y": -5,
            "z": -3,
            "elements": [
                "botania:managlass@0"
            ]
        },
        {
            "x": -3,
            "y": -1,
            "z": -1,
            "elements": [
                "botania:managlass@0"
            ]
        },
        {
            "x": 2,
            "y": 1,
            "z": 1,
            "elements": [
                "astralsorcery:blockmarble@6"
            ]
        },
        {
            "x": -7,
            "y": -7,
            "z": -4,
            "elements": [
                "astralsorcery:blockmarble@3"
            ]
        },
        {
            "x": -6,
            "y": -5,
            "z": -3,
            "elements": [
                "enderio:block_fluid_liquid_sunshine@0"
            ]
        },
        {
            "x": -4,
            "y": -1,
            "z": -1,
            "elements": [
                "botania:managlass@0"
            ]
        },
        {
            "x": -7,
            "y": -5,
            "z": -3,
            "elements": [
                "botania:managlass@0"
            ]
        },
        {
            "x": -6,
            "y": -3,
            "z": -2,
            "elements": [
                "botania:managlass@0"
            ]
        },
        {
            "x": -5,
            "y": -1,
            "z": -1,
            "elements": [
                "botania:managlass@0"
            ]
        },
        {
            "x": -6,
            "y": -1,
            "z": -1,
            "elements": [
                "astralsorcery:blockmarble@4"
            ]
        },
        {
            "x": 7,
            "y": -6,
            "z": -3,
            "elements": [
                "botania:managlass@0"
            ]
        },
        {
            "x": 6,
            "y": -6,
            "z": -3,
            "elements": [
                "contenttweaker:fluid_runhuayou@0"
            ]
        },
        {
            "x": 5,
            "y": -6,
            "z": -3,
            "elements": [
                "botania:managlass@0"
            ]
        },
        {
            "x": 6,
            "y": -4,
            "z": -2,
            "elements": [
                "botania:managlass@0"
            ]
        },
        {
            "x": 4,
            "y": -2,
            "z": -1,
            "elements": [
                "astralsorcery:blockinfusedwood@2"
            ]
        }
    ]}