{
    "registryname":"huaxuefanyingfu",
    "localizedname":"化学反应釜",
    "color":"483a2c",
    "parts": [
        {
            "x": 0,
            "y": 0,
            "z": 0,
            "elements": [
                "modularmachinery:blockcontroller@2"
            ]
        },
        {
            "x": -1,
            "y": 0,
            "z": 0,
            "elements": [
                "modularmachinery:blockoutputbus"
            ]
        },
        {
            "x": 1,
            "y": 2,
            "z": 1,
            "elements": [
                "mekanismgenerators:reactor@1"
            ]
        },
        {
            "x": -2,
            "y": 0,
            "z": 0,
             
            "elements": [
                "mekanismgenerators:reactor@1"
            ]
        },
        {
            "x": 2,
            "y": 2,
            "z": 1,
             
            "elements": [
                "mekanismgenerators:reactor@1"
            ]
        },
        {
            "x": 1,
            "y": 0,
            "z": 0,
              
            "elements": [
                "modularmachinery:blockinputbus"
            ]
        },
        {
            "x": 2,
            "y": 0,
            "z": 0,
             
            "elements": [
                "mekanismgenerators:reactor@1"
            ]
        },
        {
            "x": -2,
            "y": 0,
            "z": 4,
             
            "elements": [
                "mekanismgenerators:reactor@1"
            ]
        },
        {
            "x": -2,
            "y": -2,
            "z": 3,
             
            "elements": [
                "mekanismgenerators:reactor@1"
            ]
        },
        {
            "x": -1,
            "y": 0,
            "z": 4,
            "elements": [
                "modularmachinery:blockfluidoutputhatch"
            ]
        },
        {
            "x": -1,
            "y": -2,
            "z": 3,
             
            "elements": [
                "mekanismgenerators:reactor@1"
            ]
        },
        {
            "x": 0,
            "y": 0,
            "z": 4,
            "elements": [
                "modularmachinery:blockenergyinputhatch"
            ]
        },
        {
            "x": 0,
            "y": -2,
            "z": 3,
             
            "elements": [
                "mekanismgenerators:reactor@1"
            ]
        },
        {
            "x": 1,
            "y": 0,
            "z": 4,
            "elements": [
                "modularmachinery:blockfluidoutputhatch"
            ]
        },
        {
            "x": 2,
            "y": 0,
            "z": 4,
             
            "elements": [
                "mekanismgenerators:reactor@1"
            ]
        },
        {
            "x": 1,
            "y": -2,
            "z": 3,
             
            "elements": [
                "mekanismgenerators:reactor@1"
            ]
        },
        {
            "x": 2,
            "y": -2,
            "z": 3,
             
            "elements": [
                "mekanismgenerators:reactor@1"
            ]
        },
        {
            "x": 2,
            "y": -1,
            "z": 0,
             
            "elements": [
                "mekanismgenerators:reactor@1"
            ]
        },
        {
            "x": -2,
            "y": 1,
            "z": 0,
             
            "elements": [
                "mekanismgenerators:reactor@1"
            ]
        },
        {
            "x": 1,
            "y": -1,
            "z": 0,
            "elements": [
                "mekanismgenerators:reactorglass@0"
            ]
        },
        {
            "x": 0,
            "y": -1,
            "z": 0,
             
            "elements": [
                "mekanismgenerators:reactorglass@0"
            ]
        },
        {
            "x": -1,
            "y": 1,
            "z": 0,
             
            "elements": [
                "mekanismgenerators:reactorglass@0"
            ]
        },
        {
            "x": 0,
            "y": 1,
            "z": 0,
             
            "elements": [
                "mekanismgenerators:reactorglass@0"
            ]
        },
        {
            "x": -1,
            "y": -1,
            "z": 0,
             
            "elements": [
                "mekanismgenerators:reactorglass@0"
            ]
        },
        {
            "x": -2,
            "y": -1,
            "z": 0,
             
            "elements": [
                "mekanismgenerators:reactor@1"
            ]
        },
        {
            "x": 1,
            "y": 1,
            "z": 0,
             
            "elements": [
                "mekanismgenerators:reactorglass@0"
            ]
        },
        {
            "x": -2,
            "y": 1,
            "z": 4,
             
            "elements": [
                "mekanismgenerators:reactor@1"
            ]
        },
        {
            "x": 2,
            "y": 1,
            "z": 0,
             
            "elements": [
                "mekanismgenerators:reactor@1"
            ]
        },
        {
            "x": -2,
            "y": -1,
            "z": 3,
             
            "elements": [
                "mekanismgenerators:reactorglass@0"
            ]
        },
        {
            "x": -1,
            "y": 1,
            "z": 4,
             
            "elements": [
                "mekanismgenerators:reactorglass@0"
            ]
        },
        {
            "x": 0,
            "y": 1,
            "z": 4,
             
            "elements": [
                "mekanismgenerators:reactorglass@0"
            ]
        },
        {
            "x": -1,
            "y": -1,
            "z": 3,
            "elements": [
                "actuallyadditions:block_crystal@3"
            ]
        },
        {
            "x": 1,
            "y": 1,
            "z": 4,
             
            "elements": [
                "mekanismgenerators:reactorglass@0"
            ]
        },
        {
            "x": 2,
            "y": 1,
            "z": 4,
             
            "elements": [
                "mekanismgenerators:reactor@1"
            ]
        },
        {
            "x": 1,
            "y": -1,
            "z": 3,
            "elements": [
                "actuallyadditions:block_crystal@3"
            ]
        },
        {
            "x": 2,
            "y": -1,
            "z": 3,
             
            "elements": [
                "mekanismgenerators:reactorglass@0"
            ]
        },
        {
            "x": 2,
            "y": -2,
            "z": 0,
             
            "elements": [
                "mekanismgenerators:reactor@1"
            ]
        },
        {
            "x": -2,
            "y": 2,
            "z": 0,
             
            "elements": [
                "mekanismgenerators:reactor@1"
            ]
        },
        {
            "x": 1,
            "y": -2,
            "z": 0,
             
            "elements": [
                "mekanismgenerators:reactor@1"
            ]
        },
        {
            "x": 0,
            "y": -2,
            "z": 0,
             
            "elements": [
                "mekanismgenerators:reactor@1"
            ]
        },
        {
            "x": -1,
            "y": 2,
            "z": 0,
             
            "elements": [
                "mekanismgenerators:reactor@1"
            ]
        },
        {
            "x": 0,
            "y": 2,
            "z": 0,
             
            "elements": [
                "mekanismgenerators:reactor@1"
            ]
        },
        {
            "x": -1,
            "y": -2,
            "z": 0,
             
            "elements": [
                "mekanismgenerators:reactor@1"
            ]
        },
        {
            "x": -2,
            "y": -2,
            "z": 0,
             
            "elements": [
                "mekanismgenerators:reactor@1"
            ]
        },
        {
            "x": 1,
            "y": 2,
            "z": 0,
             
            "elements": [
                "mekanismgenerators:reactor@1"
            ]
        },
        {
            "x": -2,
            "y": 2,
            "z": 4,
             
            "elements": [
                "mekanismgenerators:reactor@1"
            ]
        },
        {
            "x": 2,
            "y": 2,
            "z": 0,
             
            "elements": [
                "mekanismgenerators:reactor@1"
            ]
        },
        {
            "x": -2,
            "y": 0,
            "z": 3,
            "elements": [
                "modularmachinery:blockfluidinputhatch"
            ]
        },
        {
            "x": -1,
            "y": 2,
            "z": 4,
             
            "elements": [
                "mekanismgenerators:reactor@1"
            ]
        },
        {
            "x": 0,
            "y": 2,
            "z": 4,
             
            "elements": [
                "mekanismgenerators:reactor@1"
            ]
        },
        {
            "x": -2,
            "y": -2,
            "z": 2,
             
            "elements": [
                "mekanismgenerators:reactor@1"
            ]
        },
        {
            "x": -1,
            "y": -2,
            "z": 2,
             
            "elements": [
                "mekanismgenerators:reactor@1"
            ]
        },
        {
            "x": 1,
            "y": 2,
            "z": 4,
             
            "elements": [
                "mekanismgenerators:reactor@1"
            ]
        },
        {
            "x": 0,
            "y": -2,
            "z": 2,
             
            "elements": [
                "mekanismgenerators:reactor@1"
            ]
        },
        {
            "x": 2,
            "y": 2,
            "z": 4,
             
            "elements": [
                "mekanismgenerators:reactor@1"
            ]
        },
        {
            "x": 2,
            "y": 0,
            "z": 3,
            "elements": [
                "modularmachinery:blockfluidinputhatch"
            ]
        },
        {
            "x": 1,
            "y": -2,
            "z": 2,
             
            "elements": [
                "mekanismgenerators:reactor@1"
            ]
        },
        {
            "x": 2,
            "y": -2,
            "z": 2,
             
            "elements": [
                "mekanismgenerators:reactor@1"
            ]
        },
        {
            "x": -2,
            "y": 1,
            "z": 3,
             
            "elements": [
                "mekanismgenerators:reactorglass@0"
            ]
        },
        {
            "x": -2,
            "y": -1,
            "z": 2,
             
            "elements": [
                "mekanismgenerators:reactorglass@0"
            ]
        },
        {
            "x": -1,
            "y": 1,
            "z": 3,
            "elements": [
                "actuallyadditions:block_crystal@3"
            ]
        },
        {
            "x": 0,
            "y": -1,
            "z": 2,
            "elements": [
                "mekanismgenerators:generator"
            ]
        },
        {
            "x": 1,
            "y": 1,
            "z": 3,
            "elements": [
                "actuallyadditions:block_crystal@3"
            ]
        },
        {
            "x": 2,
            "y": 1,
            "z": 3,
             
            "elements": [
                "mekanismgenerators:reactorglass@0"
            ]
        },
        {
            "x": 2,
            "y": -1,
            "z": 2,
             
            "elements": [
                "mekanismgenerators:reactorglass@0"
            ]
        },
        {
            "x": -2,
            "y": 2,
            "z": 3,
             
            "elements": [
                "mekanismgenerators:reactor@1"
            ]
        },
        {
            "x": -2,
            "y": 0,
            "z": 2,
            "elements": [
                "modularmachinery:blockfluidinputhatch"
            ]
        },
        {
            "x": -1,
            "y": 2,
            "z": 3,
             
            "elements": [
                "mekanismgenerators:reactor@1"
            ]
        },
        {
            "x": 0,
            "y": 2,
            "z": 3,
             
            "elements": [
                "mekanismgenerators:reactor@1"
            ]
        },
        {
            "x": -2,
            "y": -2,
            "z": 1,
             
            "elements": [
                "mekanismgenerators:reactor@1"
            ]
        },
        {
            "x": 0,
            "y": 0,
            "z": 2,
            "elements": [
                "actuallyadditions:block_shock_suppressor@0"
            ]
        },
        {
            "x": 1,
            "y": 2,
            "z": 3,
             
            "elements": [
                "mekanismgenerators:reactor@1"
            ]
        },
        {
            "x": -1,
            "y": -2,
            "z": 1,
             
            "elements": [
                "mekanismgenerators:reactor@1"
            ]
        },
        {
            "x": 0,
            "y": -2,
            "z": 1,
             
            "elements": [
                "mekanismgenerators:reactor@1"
            ]
        },
        {
            "x": 2,
            "y": 2,
            "z": 3,
             
            "elements": [
                "mekanismgenerators:reactor@1"
            ]
        },
        {
            "x": 2,
            "y": 0,
            "z": 2,
            "elements": [
                "modularmachinery:blockfluidinputhatch"
            ]
        },
        {
            "x": 1,
            "y": -2,
            "z": 1,
             
            "elements": [
                "mekanismgenerators:reactor@1"
            ]
        },
        {
            "x": 2,
            "y": -2,
            "z": 1,
             
            "elements": [
                "mekanismgenerators:reactor@1"
            ]
        },
        {
            "x": -2,
            "y": 1,
            "z": 2,
             
            "elements": [
                "mekanismgenerators:reactorglass@0"
            ]
        },
        {
            "x": -2,
            "y": -1,
            "z": 1,
             
            "elements": [
                "mekanismgenerators:reactorglass@0"
            ]
        },
        {
            "x": 0,
            "y": 1,
            "z": 2,
            "elements": [
                "mekanismgenerators:generator@7"
            ]
        },
        {
            "x": -1,
            "y": -1,
            "z": 1,
            "elements": [
                "actuallyadditions:block_crystal@3"
            ]
        },
        {
            "x": 2,
            "y": 1,
            "z": 2,
             
            "elements": [
                "mekanismgenerators:reactorglass@0"
            ]
        },
        {
            "x": 1,
            "y": -1,
            "z": 1,
            "elements": [
                "actuallyadditions:block_crystal@3"
            ]
        },
        {
            "x": 2,
            "y": -1,
            "z": 1,
             
            "elements": [
                "mekanismgenerators:reactorglass@0"
            ]
        },
        {
            "x": -2,
            "y": 2,
            "z": 2,
             
            "elements": [
                "mekanismgenerators:reactor@1"
            ]
        },
        {
            "x": -2,
            "y": 0,
            "z": 1,
            "elements": [
                "modularmachinery:blockfluidinputhatch"
            ]
        },
        {
            "x": -1,
            "y": 2,
            "z": 2,
             
            "elements": [
                "mekanismgenerators:reactor@1"
            ]
        },
        {
            "x": 0,
            "y": 2,
            "z": 2,
             
            "elements": [
                "mekanismgenerators:reactor@1"
            ]
        },
        {
            "x": 1,
            "y": 2,
            "z": 2,
             
            "elements": [
                "mekanismgenerators:reactor@1"
            ]
        },
        {
            "x": 2,
            "y": 2,
            "z": 2,
             
            "elements": [
                "mekanismgenerators:reactor@1"
            ]
        },
        {
            "x": 2,
            "y": 0,
            "z": 1,
            "elements": [
                "modularmachinery:blockfluidinputhatch"
            ]
        },
        {
            "x": -2,
            "y": -2,
            "z": 4,
             
            "elements": [
                "mekanismgenerators:reactor@1"
            ]
        },
        {
            "x": -1,
            "y": -2,
            "z": 4,
             
            "elements": [
                "mekanismgenerators:reactor@1"
            ]
        },
        {
            "x": 0,
            "y": -2,
            "z": 4,
             
            "elements": [
                "mekanismgenerators:reactor@1"
            ]
        },
        {
            "x": 1,
            "y": -2,
            "z": 4,
             
            "elements": [
                "mekanismgenerators:reactor@1"
            ]
        },
        {
            "x": 2,
            "y": -2,
            "z": 4,
             
            "elements": [
                "mekanismgenerators:reactor@1"
            ]
        },
        {
            "x": -2,
            "y": 1,
            "z": 1,
             
            "elements": [
                "mekanismgenerators:reactorglass@0"
            ]
        },
        {
            "x": -1,
            "y": 1,
            "z": 1,
            "elements": [
                "actuallyadditions:block_crystal@3"
            ]
        },
        {
            "x": 1,
            "y": 1,
            "z": 1,
            "elements": [
                "actuallyadditions:block_crystal@3"
            ]
        },
        {
            "x": 2,
            "y": 1,
            "z": 1,
             
            "elements": [
                "mekanismgenerators:reactorglass@0"
            ]
        },
        {
            "x": -2,
            "y": -1,
            "z": 4,
             
            "elements": [
                "mekanismgenerators:reactor@1"
            ]
        },
        {
            "x": -1,
            "y": -1,
            "z": 4,
             
            "elements": [
                "mekanismgenerators:reactorglass@0"
            ]
        },
        {
            "x": 0,
            "y": -1,
            "z": 4,
             
            "elements": [
                "mekanismgenerators:reactorglass@0"
            ]
        },
        {
            "x": 1,
            "y": -1,
            "z": 4,
             
            "elements": [
                "mekanismgenerators:reactorglass@0"
            ]
        },
        {
            "x": 2,
            "y": -1,
            "z": 4,
             
            "elements": [
                "mekanismgenerators:reactor@1"
            ]
        },
        {
            "x": -2,
            "y": 2,
            "z": 1,
             
            "elements": [
                "mekanismgenerators:reactor@1"
            ]
        },
        {
            "x": -1,
            "y": 2,
            "z": 1,
             
            "elements": [
                "mekanismgenerators:reactor@1"
            ]
        },
        {
            "x": 0,
            "y": 2,
            "z": 1,
             
            "elements": [
                "mekanismgenerators:reactor@1"
            ]
        }
    ]}