{
    "registryname":"tanshihua",
    "localizedname":"贪食花",
    "color":"f0f0f0",
    "parts": [
        {
            "x": 0,
            "y": 0,
            "z": 0,
            "elements": [
                "modularmachinery:blockcontroller@2"
            ]
        },
        {
            "x": -1,
            "y": 0,
            "z": 0,
            "elements": [
                "botania:petalblock@0"
            ]
        },
        {
            "x": -2,
            "y": 0,
            "z": 0,
            "elements": [
                "botania:petalblock@0"
            ]
        },
        {
            "x": 1,
            "y": 0,
            "z": 0,
            "elements": [
                "modularmachinery:blockinputbus"
            ]
        },
        {
            "x": -3,
            "y": 0,
            "z": 0,
            "elements": [
                "botania:petalblock@0"
            ]
        },
        {
            "x": 2,
            "y": 0,
            "z": 0,
            "elements": [
                "botania:petalblock@0"
            ]
        },
        {
            "x": -4,
            "y": 0,
            "z": 0,
            "elements": [
                "botania:petalblock@0"
            ]
        },
        {
            "x": 3,
            "y": 0,
            "z": 0,
            "elements": [
                "botania:petalblock@0"
            ]
        },
        {
            "x": -5,
            "y": 0,
            "z": 0,
            "elements": [
                "botania:petalblock@0"
            ]
        },
        {
            "x": 4,
            "y": 0,
            "z": 0,
            "elements": [
                "botania:petalblock@0"
            ]
        },
        {
            "x": -6,
            "y": 0,
            "z": 0,
            "elements": [
                "botania:petalblock@0"
            ]
        },
        {
            "x": 5,
            "y": 0,
            "z": 0,
            "elements": [
                "botania:petalblock@0"
            ]
        },
        {
            "x": 6,
            "y": 0,
            "z": 0,
            "elements": [
                "botania:petalblock@0"
            ]
        },
        {
            "x": 7,
            "y": 0,
            "z": 0,
            "elements": [
                "botania:petalblock@0"
            ]
        },
        {
            "x": -6,
            "y": -6,
            "z": 13,
            "elements": [
                "botania:petalblock@12"
            ]
        },
        {
            "x": -5,
            "y": -6,
            "z": 13,
            "elements": [
                "minecraft:hardened_clay@0"
            ]
        },
        {
            "x": -4,
            "y": -6,
            "z": 13,
            "elements": [
                "minecraft:hardened_clay@0"
            ]
        },
        {
            "x": -3,
            "y": -6,
            "z": 13,
            "elements": [
                "minecraft:hardened_clay@0"
            ]
        },
        {
            "x": -2,
            "y": -6,
            "z": 13,
            "elements": [
                "minecraft:hardened_clay@0"
            ]
        },
        {
            "x": -1,
            "y": -6,
            "z": 13,
            "elements": [
                "minecraft:hardened_clay@0"
            ]
        },
        {
            "x": 0,
            "y": -6,
            "z": 13,
            "elements": [
                "minecraft:hardened_clay@0"
            ]
        },
        {
            "x": 1,
            "y": -6,
            "z": 13,
            "elements": [
                "minecraft:hardened_clay@0"
            ]
        },
        {
            "x": 2,
            "y": -6,
            "z": 13,
            "elements": [
                "minecraft:hardened_clay@0"
            ]
        },
        {
            "x": 3,
            "y": -6,
            "z": 13,
            "elements": [
                "minecraft:hardened_clay@0"
            ]
        },
        {
            "x": 7,
            "y": -1,
            "z": 0,
            "elements": [
                "botania:petalblock@8"
            ]
        },
        {
            "x": 4,
            "y": -6,
            "z": 13,
            "elements": [
                "minecraft:hardened_clay@0"
            ]
        },
        {
            "x": 5,
            "y": -6,
            "z": 13,
            "elements": [
                "minecraft:hardened_clay@0"
            ]
        },
        {
            "x": 6,
            "y": -1,
            "z": 0,
            "elements": [
                "botania:petalblock@0"
            ]
        },
        {
            "x": 6,
            "y": -6,
            "z": 13,
            "elements": [
                "minecraft:hardened_clay@0"
            ]
        },
        {
            "x": 5,
            "y": -1,
            "z": 0,
            "elements": [
                "botania:petalblock@0"
            ]
        },
        {
            "x": 7,
            "y": -6,
            "z": 13,
            "elements": [
                "botania:petalblock@12"
            ]
        },
        {
            "x": 4,
            "y": -1,
            "z": 0,
            "elements": [
                "botania:petalblock@0"
            ]
        },
        {
            "x": 3,
            "y": -1,
            "z": 0,
            "elements": [
                "botania:petalblock@0"
            ]
        },
        {
            "x": 2,
            "y": -1,
            "z": 0,
            "elements": [
                "botania:petalblock@0"
            ]
        },
        {
            "x": 1,
            "y": -1,
            "z": 0,
            "elements": [
                "botania:petalblock@0"
            ]
        },
        {
            "x": 0,
            "y": -1,
            "z": 0,
            "elements": [
                "botania:petalblock@0"
            ]
        },
        {
            "x": -1,
            "y": -1,
            "z": 0,
            "elements": [
                "botania:petalblock@0"
            ]
        },
        {
            "x": -2,
            "y": -1,
            "z": 0,
            "elements": [
                "botania:petalblock@0"
            ]
        },
        {
            "x": -3,
            "y": -1,
            "z": 0,
            "elements": [
                "botania:petalblock@0"
            ]
        },
        {
            "x": -4,
            "y": -1,
            "z": 0,
            "elements": [
                "botania:petalblock@0"
            ]
        },
        {
            "x": -5,
            "y": -1,
            "z": 0,
            "elements": [
                "botania:petalblock@0"
            ]
        },
        {
            "x": -6,
            "y": -1,
            "z": 0,
            "elements": [
                "botania:petalblock@8"
            ]
        },
        {
            "x": -6,
            "y": -5,
            "z": 13,
            "elements": [
                "botania:petalblock@12"
            ]
        },
        {
            "x": -6,
            "y": -7,
            "z": 12,
            "elements": [
                "botania:petalblock@12"
            ]
        },
        {
            "x": -5,
            "y": -5,
            "z": 13,
            "elements": [
                "minecraft:hardened_clay@0"
            ]
        },
        {
            "x": -4,
            "y": -5,
            "z": 13,
            "elements": [
                "minecraft:hardened_clay@0"
            ]
        },
        {
            "x": -3,
            "y": -5,
            "z": 13,
            "elements": [
                "minecraft:hardened_clay@0"
            ]
        },
        {
            "x": -2,
            "y": -5,
            "z": 13,
            "elements": [
                "minecraft:hardened_clay@0"
            ]
        },
        {
            "x": -1,
            "y": -5,
            "z": 13,
            "elements": [
                "minecraft:hardened_clay@0"
            ]
        },
        {
            "x": 0,
            "y": -5,
            "z": 13,
            "elements": [
                "minecraft:hardened_clay@0"
            ]
        },
        {
            "x": 1,
            "y": -5,
            "z": 13,
            "elements": [
                "minecraft:hardened_clay@0"
            ]
        },
        {
            "x": 2,
            "y": -5,
            "z": 13,
            "elements": [
                "minecraft:hardened_clay@0"
            ]
        },
        {
            "x": 3,
            "y": -5,
            "z": 13,
            "elements": [
                "minecraft:hardened_clay@0"
            ]
        },
        {
            "x": 7,
            "y": -2,
            "z": 0,
            "elements": [
                "botania:petalblock@8"
            ]
        },
        {
            "x": 4,
            "y": -5,
            "z": 13,
            "elements": [
                "minecraft:hardened_clay@0"
            ]
        },
        {
            "x": 5,
            "y": -5,
            "z": 13,
            "elements": [
                "minecraft:hardened_clay@0"
            ]
        },
        {
            "x": 6,
            "y": -2,
            "z": 0,
            "elements": [
                "botania:petalblock@0"
            ]
        },
        {
            "x": 6,
            "y": -5,
            "z": 13,
            "elements": [
                "minecraft:hardened_clay@0"
            ]
        },
        {
            "x": 5,
            "y": -2,
            "z": 0,
            "elements": [
                "botania:petalblock@8"
            ]
        },
        {
            "x": 7,
            "y": -5,
            "z": 13,
            "elements": [
                "botania:petalblock@12"
            ]
        },
        {
            "x": 4,
            "y": -2,
            "z": 0,
            "elements": [
                "botania:petalblock@8"
            ]
        },
        {
            "x": 7,
            "y": -7,
            "z": 12,
            "elements": [
                "botania:petalblock@12"
            ]
        },
        {
            "x": 3,
            "y": -2,
            "z": 0,
            "elements": [
                "botania:petalblock@0"
            ]
        },
        {
            "x": 2,
            "y": -2,
            "z": 0,
            "elements": [
                "botania:petalblock@0"
            ]
        },
        {
            "x": 1,
            "y": -2,
            "z": 0,
            "elements": [
                "botania:petalblock@8"
            ]
        },
        {
            "x": 0,
            "y": -2,
            "z": 0,
            "elements": [
                "botania:petalblock@8"
            ]
        },
        {
            "x": -1,
            "y": -2,
            "z": 0,
            "elements": [
                "botania:petalblock@0"
            ]
        },
        {
            "x": -2,
            "y": -2,
            "z": 0,
            "elements": [
                "botania:petalblock@0"
            ]
        },
        {
            "x": -3,
            "y": -2,
            "z": 0,
            "elements": [
                "botania:petalblock@8"
            ]
        },
        {
            "x": -4,
            "y": -2,
            "z": 0,
            "elements": [
                "botania:petalblock@8"
            ]
        },
        {
            "x": -5,
            "y": -2,
            "z": 0,
            "elements": [
                "botania:petalblock@0"
            ]
        },
        {
            "x": -6,
            "y": -2,
            "z": 0,
            "elements": [
                "botania:petalblock@8"
            ]
        },
        {
            "x": -6,
            "y": -4,
            "z": 13,
            "elements": [
                "botania:petalblock@12"
            ]
        },
        {
            "x": -6,
            "y": -6,
            "z": 12,
            "elements": [
                "minecraft:hardened_clay@0"
            ]
        },
        {
            "x": -5,
            "y": -4,
            "z": 13,
            "elements": [
                "minecraft:hardened_clay@0"
            ]
        },
        {
            "x": -4,
            "y": -4,
            "z": 13,
            "elements": [
                "minecraft:hardened_clay@0"
            ]
        },
        {
            "x": -3,
            "y": -4,
            "z": 13,
            "elements": [
                "minecraft:hardened_clay@0"
            ]
        },
        {
            "x": -2,
            "y": -4,
            "z": 13,
            "elements": [
                "minecraft:hardened_clay@0"
            ]
        },
        {
            "x": -1,
            "y": -4,
            "z": 13,
            "elements": [
                "minecraft:hardened_clay@0"
            ]
        },
        {
            "x": 0,
            "y": -4,
            "z": 13,
            "elements": [
                "minecraft:hardened_clay@0"
            ]
        },
        {
            "x": 1,
            "y": -4,
            "z": 13,
            "elements": [
                "minecraft:hardened_clay@0"
            ]
        },
        {
            "x": 2,
            "y": -4,
            "z": 13,
            "elements": [
                "minecraft:hardened_clay@0"
            ]
        },
        {
            "x": 3,
            "y": -4,
            "z": 13,
            "elements": [
                "minecraft:hardened_clay@0"
            ]
        },
        {
            "x": 7,
            "y": -3,
            "z": 0,
            "elements": [
                "botania:petalblock@8"
            ]
        },
        {
            "x": 4,
            "y": -4,
            "z": 13,
            "elements": [
                "minecraft:hardened_clay@0"
            ]
        },
        {
            "x": 6,
            "y": -3,
            "z": 0,
            "elements": [
                "botania:petalblock@8"
            ]
        },
        {
            "x": 5,
            "y": -4,
            "z": 13,
            "elements": [
                "minecraft:hardened_clay@0"
            ]
        },
        {
            "x": 6,
            "y": -4,
            "z": 13,
            "elements": [
                "minecraft:hardened_clay@0"
            ]
        },
        {
            "x": 5,
            "y": -3,
            "z": 0,
            "elements": [
                "minecraft:hardened_clay@0"
            ]
        },
        {
            "x": 7,
            "y": -4,
            "z": 13,
            "elements": [
                "botania:petalblock@12"
            ]
        },
        {
            "x": 4,
            "y": -3,
            "z": 0,
            "elements": [
                "minecraft:hardened_clay@0"
            ]
        },
        {
            "x": 7,
            "y": -6,
            "z": 12,
            "elements": [
                "minecraft:hardened_clay@0"
            ]
        },
        {
            "x": 3,
            "y": -3,
            "z": 0,
            "elements": [
                "botania:petalblock@8"
            ]
        },
        {
            "x": 2,
            "y": -3,
            "z": 0,
            "elements": [
                "botania:petalblock@8"
            ]
        },
        {
            "x": 1,
            "y": -3,
            "z": 0,
            "elements": [
                "minecraft:hardened_clay@0"
            ]
        },
        {
            "x": 0,
            "y": -3,
            "z": 0,
            "elements": [
                "minecraft:hardened_clay@0"
            ]
        },
        {
            "x": -1,
            "y": -3,
            "z": 0,
            "elements": [
                "botania:petalblock@8"
            ]
        },
        {
            "x": -2,
            "y": -3,
            "z": 0,
            "elements": [
                "botania:petalblock@8"
            ]
        },
        {
            "x": -3,
            "y": -3,
            "z": 0,
            "elements": [
                "minecraft:hardened_clay@0"
            ]
        },
        {
            "x": -4,
            "y": -3,
            "z": 0,
            "elements": [
                "minecraft:hardened_clay@0"
            ]
        },
        {
            "x": -5,
            "y": -3,
            "z": 0,
            "elements": [
                "botania:petalblock@8"
            ]
        },
        {
            "x": -6,
            "y": -3,
            "z": 0,
            "elements": [
                "botania:petalblock@8"
            ]
        },
        {
            "x": -6,
            "y": -3,
            "z": 13,
            "elements": [
                "botania:petalblock@8"
            ]
        },
        {
            "x": -6,
            "y": -5,
            "z": 12,
            "elements": [
                "minecraft:hardened_clay@0"
            ]
        },
        {
            "x": -5,
            "y": -3,
            "z": 13,
            "elements": [
                "botania:petalblock@8"
            ]
        },
        {
            "x": -6,
            "y": -7,
            "z": 11,
            "elements": [
                "botania:petalblock@12"
            ]
        },
        {
            "x": -4,
            "y": -3,
            "z": 13,
            "elements": [
                "minecraft:hardened_clay@0"
            ]
        },
        {
            "x": -3,
            "y": -3,
            "z": 13,
            "elements": [
                "minecraft:hardened_clay@0"
            ]
        },
        {
            "x": -2,
            "y": -3,
            "z": 13,
            "elements": [
                "botania:petalblock@8"
            ]
        },
        {
            "x": -1,
            "y": -3,
            "z": 13,
            "elements": [
                "botania:petalblock@8"
            ]
        },
        {
            "x": 0,
            "y": -3,
            "z": 13,
            "elements": [
                "minecraft:hardened_clay@0"
            ]
        },
        {
            "x": 1,
            "y": -3,
            "z": 13,
            "elements": [
                "minecraft:hardened_clay@0"
            ]
        },
        {
            "x": 2,
            "y": -3,
            "z": 13,
            "elements": [
                "botania:petalblock@8"
            ]
        },
        {
            "x": 3,
            "y": -3,
            "z": 13,
            "elements": [
                "botania:petalblock@8"
            ]
        },
        {
            "x": 7,
            "y": -4,
            "z": 0,
            "elements": [
                "botania:petalblock@12"
            ]
        },
        {
            "x": 4,
            "y": -3,
            "z": 13,
            "elements": [
                "minecraft:hardened_clay@0"
            ]
        },
        {
            "x": 6,
            "y": -4,
            "z": 0,
            "elements": [
                "minecraft:hardened_clay@0"
            ]
        },
        {
            "x": 5,
            "y": -3,
            "z": 13,
            "elements": [
                "minecraft:hardened_clay@0"
            ]
        },
        {
            "x": 6,
            "y": -3,
            "z": 13,
            "elements": [
                "botania:petalblock@8"
            ]
        },
        {
            "x": 5,
            "y": -4,
            "z": 0,
            "elements": [
                "minecraft:hardened_clay@0"
            ]
        },
        {
            "x": 7,
            "y": -3,
            "z": 13,
            "elements": [
                "botania:petalblock@8"
            ]
        },
        {
            "x": 4,
            "y": -4,
            "z": 0,
            "elements": [
                "minecraft:hardened_clay@0"
            ]
        },
        {
            "x": 7,
            "y": -5,
            "z": 12,
            "elements": [
                "minecraft:hardened_clay@0"
            ]
        },
        {
            "x": 3,
            "y": -4,
            "z": 0,
            "elements": [
                "minecraft:hardened_clay@0"
            ]
        },
        {
            "x": 7,
            "y": -7,
            "z": 11,
            "elements": [
                "botania:petalblock@12"
            ]
        },
        {
            "x": 2,
            "y": -4,
            "z": 0,
            "elements": [
                "minecraft:hardened_clay@0"
            ]
        },
        {
            "x": 1,
            "y": -4,
            "z": 0,
            "elements": [
                "minecraft:hardened_clay@0"
            ]
        },
        {
            "x": 0,
            "y": -4,
            "z": 0,
            "elements": [
                "minecraft:hardened_clay@0"
            ]
        },
        {
            "x": -1,
            "y": -4,
            "z": 0,
            "elements": [
                "minecraft:hardened_clay@0"
            ]
        },
        {
            "x": -2,
            "y": -4,
            "z": 0,
            "elements": [
                "minecraft:hardened_clay@0"
            ]
        },
        {
            "x": -3,
            "y": -4,
            "z": 0,
            "elements": [
                "minecraft:hardened_clay@0"
            ]
        },
        {
            "x": -4,
            "y": -4,
            "z": 0,
            "elements": [
                "minecraft:hardened_clay@0"
            ]
        },
        {
            "x": -5,
            "y": -4,
            "z": 0,
            "elements": [
                "minecraft:hardened_clay@0"
            ]
        },
        {
            "x": -6,
            "y": -4,
            "z": 0,
            "elements": [
                "botania:petalblock@12"
            ]
        },
        {
            "x": -6,
            "y": -2,
            "z": 13,
            "elements": [
                "botania:petalblock@8"
            ]
        },
        {
            "x": -6,
            "y": -4,
            "z": 12,
            "elements": [
                "minecraft:hardened_clay@0"
            ]
        },
        {
            "x": -5,
            "y": -2,
            "z": 13,
            "elements": [
                "botania:petalblock@0"
            ]
        },
        {
            "x": -6,
            "y": -6,
            "z": 11,
            "elements": [
                "minecraft:hardened_clay@0"
            ]
        },
        {
            "x": -4,
            "y": -2,
            "z": 13,
            "elements": [
                "botania:petalblock@8"
            ]
        },
        {
            "x": -3,
            "y": -2,
            "z": 13,
            "elements": [
                "botania:petalblock@8"
            ]
        },
        {
            "x": -2,
            "y": -2,
            "z": 13,
            "elements": [
                "botania:petalblock@0"
            ]
        },
        {
            "x": -1,
            "y": -2,
            "z": 13,
            "elements": [
                "botania:petalblock@0"
            ]
        },
        {
            "x": 0,
            "y": -2,
            "z": 13,
            "elements": [
                "botania:petalblock@8"
            ]
        },
        {
            "x": 1,
            "y": -2,
            "z": 13,
            "elements": [
                "botania:petalblock@8"
            ]
        },
        {
            "x": 2,
            "y": -2,
            "z": 13,
            "elements": [
                "botania:petalblock@0"
            ]
        },
        {
            "x": 3,
            "y": -2,
            "z": 13,
            "elements": [
                "botania:petalblock@0"
            ]
        },
        {
            "x": 7,
            "y": -5,
            "z": 0,
            "elements": [
                "botania:petalblock@12"
            ]
        },
        {
            "x": 4,
            "y": -2,
            "z": 13,
            "elements": [
                "botania:petalblock@8"
            ]
        },
        {
            "x": 6,
            "y": -5,
            "z": 0,
            "elements": [
                "minecraft:hardened_clay@0"
            ]
        },
        {
            "x": 5,
            "y": -2,
            "z": 13,
            "elements": [
                "botania:petalblock@8"
            ]
        },
        {
            "x": 5,
            "y": -5,
            "z": 0,
            "elements": [
                "minecraft:hardened_clay@0"
            ]
        },
        {
            "x": 6,
            "y": -2,
            "z": 13,
            "elements": [
                "botania:petalblock@0"
            ]
        },
        {
            "x": 7,
            "y": -2,
            "z": 13,
            "elements": [
                "botania:petalblock@8"
            ]
        },
        {
            "x": 4,
            "y": -5,
            "z": 0,
            "elements": [
                "minecraft:hardened_clay@0"
            ]
        },
        {
            "x": 7,
            "y": -4,
            "z": 12,
            "elements": [
                "minecraft:hardened_clay@0"
            ]
        },
        {
            "x": 3,
            "y": -5,
            "z": 0,
            "elements": [
                "minecraft:hardened_clay@0"
            ]
        },
        {
            "x": 7,
            "y": -6,
            "z": 11,
            "elements": [
                "minecraft:hardened_clay@0"
            ]
        },
        {
            "x": 2,
            "y": -5,
            "z": 0,
            "elements": [
                "minecraft:hardened_clay@0"
            ]
        },
        {
            "x": 1,
            "y": -5,
            "z": 0,
            "elements": [
                "minecraft:hardened_clay@0"
            ]
        },
        {
            "x": 0,
            "y": -5,
            "z": 0,
            "elements": [
                "minecraft:hardened_clay@0"
            ]
        },
        {
            "x": -1,
            "y": -5,
            "z": 0,
            "elements": [
                "minecraft:hardened_clay@0"
            ]
        },
        {
            "x": -2,
            "y": -5,
            "z": 0,
            "elements": [
                "minecraft:hardened_clay@0"
            ]
        },
        {
            "x": -3,
            "y": -5,
            "z": 0,
            "elements": [
                "minecraft:hardened_clay@0"
            ]
        },
        {
            "x": -4,
            "y": -5,
            "z": 0,
            "elements": [
                "minecraft:hardened_clay@0"
            ]
        },
        {
            "x": -5,
            "y": -5,
            "z": 0,
            "elements": [
                "minecraft:hardened_clay@0"
            ]
        },
        {
            "x": -6,
            "y": -5,
            "z": 0,
            "elements": [
                "botania:petalblock@12"
            ]
        },
        {
            "x": -6,
            "y": -1,
            "z": 13,
            "elements": [
                "botania:petalblock@8"
            ]
        },
        {
            "x": -6,
            "y": -3,
            "z": 12,
            "elements": [
                "botania:petalblock@8"
            ]
        },
        {
            "x": -5,
            "y": -1,
            "z": 13,
            "elements": [
                "botania:petalblock@0"
            ]
        },
        {
            "x": -6,
            "y": -5,
            "z": 11,
            "elements": [
                "minecraft:hardened_clay@0"
            ]
        },
        {
            "x": -4,
            "y": -1,
            "z": 13,
            "elements": [
                "botania:petalblock@0"
            ]
        },
        {
            "x": -6,
            "y": -7,
            "z": 10,
            "elements": [
                "botania:petalblock@12"
            ]
        },
        {
            "x": -3,
            "y": -1,
            "z": 13,
            "elements": [
                "botania:petalblock@0"
            ]
        },
        {
            "x": -2,
            "y": -1,
            "z": 13,
            "elements": [
                "botania:petalblock@0"
            ]
        },
        {
            "x": -1,
            "y": -1,
            "z": 13,
            "elements": [
                "botania:petalblock@0"
            ]
        },
        {
            "x": 0,
            "y": -1,
            "z": 13,
            "elements": [
                "botania:petalblock@0"
            ]
        },
        {
            "x": 1,
            "y": -1,
            "z": 13,
            "elements": [
                "botania:petalblock@0"
            ]
        },
        {
            "x": 2,
            "y": -1,
            "z": 13,
            "elements": [
                "botania:petalblock@0"
            ]
        },
        {
            "x": 3,
            "y": -1,
            "z": 13,
            "elements": [
                "botania:petalblock@0"
            ]
        },
        {
            "x": 7,
            "y": -6,
            "z": 0,
            "elements": [
                "botania:petalblock@12"
            ]
        },
        {
            "x": 4,
            "y": -1,
            "z": 13,
            "elements": [
                "botania:petalblock@0"
            ]
        },
        {
            "x": 6,
            "y": -6,
            "z": 0,
            "elements": [
                "minecraft:hardened_clay@0"
            ]
        },
        {
            "x": 5,
            "y": -1,
            "z": 13,
            "elements": [
                "botania:petalblock@0"
            ]
        },
        {
            "x": 5,
            "y": -6,
            "z": 0,
            "elements": [
                "minecraft:hardened_clay@0"
            ]
        },
        {
            "x": 6,
            "y": -1,
            "z": 13,
            "elements": [
                "botania:petalblock@0"
            ]
        },
        {
            "x": 7,
            "y": -1,
            "z": 13,
            "elements": [
                "botania:petalblock@8"
            ]
        },
        {
            "x": 4,
            "y": -6,
            "z": 0,
            "elements": [
                "minecraft:hardened_clay@0"
            ]
        },
        {
            "x": 7,
            "y": -3,
            "z": 12,
            "elements": [
                "botania:petalblock@8"
            ]
        },
        {
            "x": 3,
            "y": -6,
            "z": 0,
            "elements": [
                "minecraft:hardened_clay@0"
            ]
        },
        {
            "x": 7,
            "y": -5,
            "z": 11,
            "elements": [
                "minecraft:hardened_clay@0"
            ]
        },
        {
            "x": 2,
            "y": -6,
            "z": 0,
            "elements": [
                "minecraft:hardened_clay@0"
            ]
        },
        {
            "x": 7,
            "y": -7,
            "z": 10,
            "elements": [
                "botania:petalblock@12"
            ]
        },
        {
            "x": 1,
            "y": -6,
            "z": 0,
            "elements": [
                "minecraft:hardened_clay@0"
            ]
        },
        {
            "x": 0,
            "y": -6,
            "z": 0,
            "elements": [
                "minecraft:hardened_clay@0"
            ]
        },
        {
            "x": -1,
            "y": -6,
            "z": 0,
            "elements": [
                "minecraft:hardened_clay@0"
            ]
        },
        {
            "x": -2,
            "y": -6,
            "z": 0,
            "elements": [
                "minecraft:hardened_clay@0"
            ]
        },
        {
            "x": -3,
            "y": -6,
            "z": 0,
            "elements": [
                "minecraft:hardened_clay@0"
            ]
        },
        {
            "x": -4,
            "y": -6,
            "z": 0,
            "elements": [
                "minecraft:hardened_clay@0"
            ]
        },
        {
            "x": -5,
            "y": -6,
            "z": 0,
            "elements": [
                "minecraft:hardened_clay@0"
            ]
        },
        {
            "x": -6,
            "y": -6,
            "z": 0,
            "elements": [
                "botania:petalblock@12"
            ]
        },
        {
            "x": -6,
            "y": 0,
            "z": 13,
            "elements": [
                "botania:petalblock@0"
            ]
        },
        {
            "x": -6,
            "y": -2,
            "z": 12,
            "elements": [
                "botania:petalblock@0"
            ]
        },
        {
            "x": -5,
            "y": 0,
            "z": 13,
            "elements": [
                "botania:petalblock@0"
            ]
        },
        {
            "x": -6,
            "y": -4,
            "z": 11,
            "elements": [
                "minecraft:hardened_clay@0"
            ]
        },
        {
            "x": -4,
            "y": 0,
            "z": 13,
            "elements": [
                "botania:petalblock@0"
            ]
        },
        {
            "x": -6,
            "y": -6,
            "z": 10,
            "elements": [
                "minecraft:hardened_clay@0"
            ]
        },
        {
            "x": -3,
            "y": 0,
            "z": 13,
            "elements": [
                "botania:petalblock@0"
            ]
        },
        {
            "x": -2,
            "y": 0,
            "z": 13,
            "elements": [
                "botania:petalblock@0"
            ]
        },
        {
            "x": -1,
            "y": 0,
            "z": 13,
            "elements": [
                "botania:petalblock@0"
            ]
        },
        {
            "x": 0,
            "y": 0,
            "z": 13,
            "elements": [
                "gugu-utils:sparkmanahatch@1"
            ]
        },
        {
            "x": 1,
            "y": 0,
            "z": 13,
            "elements": [
                "gugu-utils:sparkmanahatch@1"
            ]
        },
        {
            "x": 2,
            "y": 0,
            "z": 13,
            "elements": [
                "botania:petalblock@0"
            ]
        },
        {
            "x": 3,
            "y": 0,
            "z": 13,
            "elements": [
                "botania:petalblock@0"
            ]
        },
        {
            "x": 7,
            "y": -7,
            "z": 0,
            "elements": [
                "botania:petalblock@12"
            ]
        },
        {
            "x": 4,
            "y": 0,
            "z": 13,
            "elements": [
                "botania:petalblock@0"
            ]
        },
        {
            "x": 6,
            "y": -7,
            "z": 0,
            "elements": [
                "botania:petalblock@12"
            ]
        },
        {
            "x": 5,
            "y": 0,
            "z": 13,
            "elements": [
                "botania:petalblock@0"
            ]
        },
        {
            "x": 5,
            "y": -7,
            "z": 0,
            "elements": [
                "botania:petalblock@12"
            ]
        },
        {
            "x": 6,
            "y": 0,
            "z": 13,
            "elements": [
                "botania:petalblock@0"
            ]
        },
        {
            "x": 4,
            "y": -7,
            "z": 0,
            "elements": [
                "botania:petalblock@12"
            ]
        },
        {
            "x": 7,
            "y": 0,
            "z": 13,
            "elements": [
                "botania:petalblock@0"
            ]
        },
        {
            "x": 7,
            "y": -2,
            "z": 12,
            "elements": [
                "botania:petalblock@0"
            ]
        },
        {
            "x": 3,
            "y": -7,
            "z": 0,
            "elements": [
                "botania:petalblock@12"
            ]
        },
        {
            "x": 7,
            "y": -4,
            "z": 11,
            "elements": [
                "minecraft:hardened_clay@0"
            ]
        },
        {
            "x": 2,
            "y": -7,
            "z": 0,
            "elements": [
                "botania:petalblock@12"
            ]
        },
        {
            "x": 7,
            "y": -6,
            "z": 10,
            "elements": [
                "minecraft:hardened_clay@0"
            ]
        },
        {
            "x": 1,
            "y": -7,
            "z": 0,
            "elements": [
                "botania:petalblock@12"
            ]
        },
        {
            "x": 0,
            "y": -7,
            "z": 0,
            "elements": [
                "botania:petalblock@12"
            ]
        },
        {
            "x": -1,
            "y": -7,
            "z": 0,
            "elements": [
                "botania:petalblock@12"
            ]
        },
        {
            "x": -2,
            "y": -7,
            "z": 0,
            "elements": [
                "botania:petalblock@12"
            ]
        },
        {
            "x": -3,
            "y": -7,
            "z": 0,
            "elements": [
                "botania:petalblock@12"
            ]
        },
        {
            "x": -4,
            "y": -7,
            "z": 0,
            "elements": [
                "botania:petalblock@12"
            ]
        },
        {
            "x": -5,
            "y": -7,
            "z": 0,
            "elements": [
                "botania:petalblock@12"
            ]
        },
        {
            "x": -6,
            "y": -7,
            "z": 0,
            "elements": [
                "botania:petalblock@12"
            ]
        },
        {
            "x": -6,
            "y": -1,
            "z": 12,
            "elements": [
                "botania:petalblock@0"
            ]
        },
        {
            "x": -6,
            "y": -3,
            "z": 11,
            "elements": [
                "minecraft:hardened_clay@0"
            ]
        },
        {
            "x": -6,
            "y": -5,
            "z": 10,
            "elements": [
                "minecraft:hardened_clay@0"
            ]
        },
        {
            "x": -6,
            "y": -7,
            "z": 9,
            "elements": [
                "botania:petalblock@12"
            ]
        },
        {
            "x": 7,
            "y": -1,
            "z": 12,
            "elements": [
                "botania:petalblock@0"
            ]
        },
        {
            "x": 7,
            "y": -3,
            "z": 11,
            "elements": [
                "minecraft:hardened_clay@0"
            ]
        },
        {
            "x": 7,
            "y": -5,
            "z": 10,
            "elements": [
                "minecraft:hardened_clay@0"
            ]
        },
        {
            "x": 7,
            "y": -7,
            "z": 9,
            "elements": [
                "botania:petalblock@12"
            ]
        },
        {
            "x": -6,
            "y": 0,
            "z": 12,
            "elements": [
                "botania:petalblock@0"
            ]
        },
        {
            "x": -6,
            "y": -2,
            "z": 11,
            "elements": [
                "botania:petalblock@8"
            ]
        },
        {
            "x": -5,
            "y": 0,
            "z": 12,
            "elements": [
                "botania:petalblock@0"
            ]
        },
        {
            "x": -6,
            "y": -4,
            "z": 10,
            "elements": [
                "minecraft:hardened_clay@0"
            ]
        },
        {
            "x": -4,
            "y": 0,
            "z": 12,
            "elements": [
                "botania:petalblock@14"
            ]
        },
        {
            "x": -6,
            "y": -6,
            "z": 9,
            "elements": [
                "minecraft:hardened_clay@0"
            ]
        },
        {
            "x": -3,
            "y": 0,
            "z": 12,
            "elements": [
                "botania:petalblock@0"
            ]
        },
        {
            "x": -2,
            "y": 0,
            "z": 12,
            "elements": [
                "botania:petalblock@0"
            ]
        },
        {
            "x": -1,
            "y": 0,
            "z": 12,
            "elements": [
                "botania:petalblock@0"
            ]
        },
        {
            "x": 0,
            "y": 0,
            "z": 12,
            "elements": [
                "botania:petalblock@0"
            ]
        },
        {
            "x": 1,
            "y": 0,
            "z": 12,
            "elements": [
                "botania:petalblock@0"
            ]
        },
        {
            "x": 2,
            "y": 0,
            "z": 12,
            "elements": [
                "botania:petalblock@0"
            ]
        },
        {
            "x": 3,
            "y": 0,
            "z": 12,
            "elements": [
                "botania:petalblock@0"
            ]
        },
        {
            "x": 4,
            "y": 0,
            "z": 12,
            "elements": [
                "botania:petalblock@0"
            ]
        },
        {
            "x": 5,
            "y": 0,
            "z": 12,
            "elements": [
                "botania:petalblock@0"
            ]
        },
        {
            "x": 6,
            "y": 0,
            "z": 12,
            "elements": [
                "botania:petalblock@0"
            ]
        },
        {
            "x": 7,
            "y": 0,
            "z": 12,
            "elements": [
                "botania:petalblock@0"
            ]
        },
        {
            "x": 7,
            "y": -2,
            "z": 11,
            "elements": [
                "botania:petalblock@8"
            ]
        },
        {
            "x": 7,
            "y": -4,
            "z": 10,
            "elements": [
                "minecraft:hardened_clay@0"
            ]
        },
        {
            "x": 7,
            "y": -6,
            "z": 9,
            "elements": [
                "minecraft:hardened_clay@0"
            ]
        },
        {
            "x": -6,
            "y": -1,
            "z": 11,
            "elements": [
                "botania:petalblock@0"
            ]
        },
        {
            "x": -6,
            "y": -3,
            "z": 10,
            "elements": [
                "minecraft:hardened_clay@0"
            ]
        },
        {
            "x": -6,
            "y": -5,
            "z": 9,
            "elements": [
                "minecraft:hardened_clay@0"
            ]
        },
        {
            "x": -6,
            "y": -7,
            "z": 8,
            "elements": [
                "botania:petalblock@12"
            ]
        },
        {
            "x": 7,
            "y": -1,
            "z": 11,
            "elements": [
                "botania:petalblock@0"
            ]
        },
        {
            "x": 7,
            "y": -3,
            "z": 10,
            "elements": [
                "minecraft:hardened_clay@0"
            ]
        },
        {
            "x": 7,
            "y": -5,
            "z": 9,
            "elements": [
                "minecraft:hardened_clay@0"
            ]
        },
        {
            "x": 7,
            "y": -7,
            "z": 8,
            "elements": [
                "botania:petalblock@12"
            ]
        },
        {
            "x": -6,
            "y": 0,
            "z": 11,
            "elements": [
                "botania:petalblock@0"
            ]
        },
        {
            "x": -6,
            "y": -2,
            "z": 10,
            "elements": [
                "botania:petalblock@8"
            ]
        },
        {
            "x": -5,
            "y": 0,
            "z": 11,
            "elements": [
                "botania:petalblock@0"
            ]
        },
        {
            "x": -6,
            "y": -4,
            "z": 9,
            "elements": [
                "minecraft:hardened_clay@0"
            ]
        },
        {
            "x": -4,
            "y": 0,
            "z": 11,
            "elements": [
                "botania:petalblock@0"
            ]
        },
        {
            "x": -6,
            "y": -6,
            "z": 8,
            "elements": [
                "minecraft:hardened_clay@0"
            ]
        },
        {
            "x": -3,
            "y": 0,
            "z": 11,
            "elements": [
                "botania:petalblock@0"
            ]
        },
        {
            "x": -2,
            "y": 0,
            "z": 11,
            "elements": [
                "botania:petalblock@0"
            ]
        },
        {
            "x": -1,
            "y": 0,
            "z": 11,
            "elements": [
                "botania:petalblock@0"
            ]
        },
        {
            "x": 0,
            "y": 0,
            "z": 11,
            "elements": [
                "botania:petalblock@0"
            ]
        },
        {
            "x": 1,
            "y": 0,
            "z": 11,
            "elements": [
                "botania:petalblock@0"
            ]
        },
        {
            "x": 2,
            "y": 0,
            "z": 11,
            "elements": [
                "botania:petalblock@0"
            ]
        },
        {
            "x": 3,
            "y": 0,
            "z": 11,
            "elements": [
                "botania:petalblock@0"
            ]
        },
        {
            "x": 4,
            "y": 0,
            "z": 11,
            "elements": [
                "botania:petalblock@0"
            ]
        },
        {
            "x": 5,
            "y": 0,
            "z": 11,
            "elements": [
                "botania:petalblock@0"
            ]
        },
        {
            "x": 6,
            "y": 0,
            "z": 11,
            "elements": [
                "botania:petalblock@0"
            ]
        },
        {
            "x": 7,
            "y": 0,
            "z": 11,
            "elements": [
                "botania:petalblock@0"
            ]
        },
        {
            "x": 7,
            "y": -2,
            "z": 10,
            "elements": [
                "botania:petalblock@8"
            ]
        },
        {
            "x": 7,
            "y": -4,
            "z": 9,
            "elements": [
                "minecraft:hardened_clay@0"
            ]
        },
        {
            "x": 7,
            "y": -6,
            "z": 8,
            "elements": [
                "minecraft:hardened_clay@0"
            ]
        },
        {
            "x": -6,
            "y": -1,
            "z": 10,
            "elements": [
                "botania:petalblock@0"
            ]
        },
        {
            "x": -6,
            "y": -3,
            "z": 9,
            "elements": [
                "botania:petalblock@8"
            ]
        },
        {
            "x": -6,
            "y": -5,
            "z": 8,
            "elements": [
                "minecraft:hardened_clay@0"
            ]
        },
        {
            "x": -6,
            "y": -7,
            "z": 7,
            "elements": [
                "botania:petalblock@12"
            ]
        },
        {
            "x": 7,
            "y": -1,
            "z": 10,
            "elements": [
                "botania:petalblock@0"
            ]
        },
        {
            "x": 7,
            "y": -3,
            "z": 9,
            "elements": [
                "botania:petalblock@8"
            ]
        },
        {
            "x": 7,
            "y": -5,
            "z": 8,
            "elements": [
                "minecraft:hardened_clay@0"
            ]
        },
        {
            "x": 7,
            "y": -7,
            "z": 7,
            "elements": [
                "botania:petalblock@12"
            ]
        },
        {
            "x": -6,
            "y": 0,
            "z": 10,
            "elements": [
                "botania:petalblock@0"
            ]
        },
        {
            "x": -6,
            "y": -2,
            "z": 9,
            "elements": [
                "botania:petalblock@0"
            ]
        },
        {
            "x": -5,
            "y": 0,
            "z": 10,
            "elements": [
                "botania:petalblock@0"
            ]
        },
        {
            "x": -6,
            "y": -4,
            "z": 8,
            "elements": [
                "minecraft:hardened_clay@0"
            ]
        },
        {
            "x": -4,
            "y": 0,
            "z": 10,
            "elements": [
                "botania:petalblock@0"
            ]
        },
        {
            "x": -6,
            "y": -6,
            "z": 7,
            "elements": [
                "minecraft:hardened_clay@0"
            ]
        },
        {
            "x": -3,
            "y": 0,
            "z": 10,
            "elements": [
                "botania:petalblock@0"
            ]
        },
        {
            "x": -2,
            "y": 0,
            "z": 10,
            "elements": [
                "botania:petalblock@0"
            ]
        },
        {
            "x": -1,
            "y": 0,
            "z": 10,
            "elements": [
                "botania:petalblock@14"
            ]
        },
        {
            "x": 0,
            "y": 0,
            "z": 10,
            "elements": [
                "botania:petalblock@0"
            ]
        },
        {
            "x": 1,
            "y": 0,
            "z": 10,
            "elements": [
                "botania:petalblock@0"
            ]
        },
        {
            "x": 2,
            "y": 0,
            "z": 10,
            "elements": [
                "botania:petalblock@0"
            ]
        },
        {
            "x": 3,
            "y": 0,
            "z": 10,
            "elements": [
                "botania:petalblock@0"
            ]
        },
        {
            "x": 4,
            "y": 0,
            "z": 10,
            "elements": [
                "botania:petalblock@14"
            ]
        },
        {
            "x": 5,
            "y": 0,
            "z": 10,
            "elements": [
                "botania:petalblock@14"
            ]
        },
        {
            "x": 6,
            "y": 0,
            "z": 10,
            "elements": [
                "botania:petalblock@0"
            ]
        },
        {
            "x": 7,
            "y": 0,
            "z": 10,
            "elements": [
                "botania:petalblock@0"
            ]
        },
        {
            "x": 7,
            "y": -2,
            "z": 9,
            "elements": [
                "botania:petalblock@0"
            ]
        },
        {
            "x": 7,
            "y": -4,
            "z": 8,
            "elements": [
                "minecraft:hardened_clay@0"
            ]
        },
        {
            "x": 7,
            "y": -6,
            "z": 7,
            "elements": [
                "minecraft:hardened_clay@0"
            ]
        },
        {
            "x": -6,
            "y": -1,
            "z": 9,
            "elements": [
                "botania:petalblock@0"
            ]
        },
        {
            "x": -6,
            "y": -3,
            "z": 8,
            "elements": [
                "botania:petalblock@8"
            ]
        },
        {
            "x": -6,
            "y": -5,
            "z": 7,
            "elements": [
                "minecraft:hardened_clay@0"
            ]
        },
        {
            "x": -6,
            "y": -7,
            "z": 6,
            "elements": [
                "botania:petalblock@12"
            ]
        },
        {
            "x": 7,
            "y": -1,
            "z": 9,
            "elements": [
                "botania:petalblock@0"
            ]
        },
        {
            "x": 7,
            "y": -3,
            "z": 8,
            "elements": [
                "botania:petalblock@8"
            ]
        },
        {
            "x": 7,
            "y": -5,
            "z": 7,
            "elements": [
                "minecraft:hardened_clay@0"
            ]
        },
        {
            "x": 7,
            "y": -7,
            "z": 6,
            "elements": [
                "botania:petalblock@12"
            ]
        },
        {
            "x": -6,
            "y": 0,
            "z": 9,
            "elements": [
                "botania:petalblock@0"
            ]
        },
        {
            "x": -6,
            "y": -2,
            "z": 8,
            "elements": [
                "botania:petalblock@0"
            ]
        },
        {
            "x": -5,
            "y": 0,
            "z": 9,
            "elements": [
                "botania:petalblock@0"
            ]
        },
        {
            "x": -6,
            "y": -4,
            "z": 7,
            "elements": [
                "minecraft:hardened_clay@0"
            ]
        },
        {
            "x": -4,
            "y": 0,
            "z": 9,
            "elements": [
                "botania:petalblock@0"
            ]
        },
        {
            "x": -6,
            "y": -6,
            "z": 6,
            "elements": [
                "minecraft:hardened_clay@0"
            ]
        },
        {
            "x": -3,
            "y": 0,
            "z": 9,
            "elements": [
                "botania:petalblock@0"
            ]
        },
        {
            "x": -2,
            "y": 0,
            "z": 9,
            "elements": [
                "botania:petalblock@0"
            ]
        },
        {
            "x": -1,
            "y": 0,
            "z": 9,
            "elements": [
                "botania:petalblock@0"
            ]
        },
        {
            "x": 0,
            "y": 0,
            "z": 9,
            "elements": [
                "botania:petalblock@0"
            ]
        },
        {
            "x": 1,
            "y": 0,
            "z": 9,
            "elements": [
                "botania:petalblock@0"
            ]
        },
        {
            "x": 2,
            "y": 0,
            "z": 9,
            "elements": [
                "botania:petalblock@0"
            ]
        },
        {
            "x": 3,
            "y": 0,
            "z": 9,
            "elements": [
                "botania:petalblock@0"
            ]
        },
        {
            "x": 4,
            "y": 0,
            "z": 9,
            "elements": [
                "botania:petalblock@14"
            ]
        },
        {
            "x": 5,
            "y": 0,
            "z": 9,
            "elements": [
                "botania:petalblock@14"
            ]
        },
        {
            "x": 6,
            "y": 0,
            "z": 9,
            "elements": [
                "botania:petalblock@0"
            ]
        },
        {
            "x": 7,
            "y": 0,
            "z": 9,
            "elements": [
                "botania:petalblock@0"
            ]
        },
        {
            "x": 7,
            "y": -2,
            "z": 8,
            "elements": [
                "botania:petalblock@0"
            ]
        },
        {
            "x": 7,
            "y": -4,
            "z": 7,
            "elements": [
                "minecraft:hardened_clay@0"
            ]
        },
        {
            "x": 7,
            "y": -6,
            "z": 6,
            "elements": [
                "minecraft:hardened_clay@0"
            ]
        },
        {
            "x": -6,
            "y": -1,
            "z": 8,
            "elements": [
                "botania:petalblock@0"
            ]
        },
        {
            "x": -6,
            "y": -3,
            "z": 7,
            "elements": [
                "minecraft:hardened_clay@0"
            ]
        },
        {
            "x": -6,
            "y": -5,
            "z": 6,
            "elements": [
                "minecraft:hardened_clay@0"
            ]
        },
        {
            "x": -6,
            "y": -7,
            "z": 5,
            "elements": [
                "botania:petalblock@12"
            ]
        },
        {
            "x": 7,
            "y": -1,
            "z": 8,
            "elements": [
                "botania:petalblock@0"
            ]
        },
        {
            "x": 7,
            "y": -3,
            "z": 7,
            "elements": [
                "minecraft:hardened_clay@0"
            ]
        },
        {
            "x": 7,
            "y": -5,
            "z": 6,
            "elements": [
                "minecraft:hardened_clay@0"
            ]
        },
        {
            "x": 7,
            "y": -7,
            "z": 5,
            "elements": [
                "botania:petalblock@12"
            ]
        },
        {
            "x": -6,
            "y": 0,
            "z": 8,
            "elements": [
                "botania:petalblock@0"
            ]
        },
        {
            "x": -6,
            "y": -2,
            "z": 7,
            "elements": [
                "botania:petalblock@8"
            ]
        },
        {
            "x": -5,
            "y": 0,
            "z": 8,
            "elements": [
                "botania:petalblock@0"
            ]
        },
        {
            "x": -6,
            "y": -4,
            "z": 6,
            "elements": [
                "minecraft:hardened_clay@0"
            ]
        },
        {
            "x": -4,
            "y": 0,
            "z": 8,
            "elements": [
                "botania:petalblock@0"
            ]
        },
        {
            "x": -6,
            "y": -6,
            "z": 5,
            "elements": [
                "minecraft:hardened_clay@0"
            ]
        },
        {
            "x": -3,
            "y": 0,
            "z": 8,
            "elements": [
                "botania:petalblock@0"
            ]
        },
        {
            "x": -2,
            "y": 0,
            "z": 8,
            "elements": [
                "botania:petalblock@14"
            ]
        },
        {
            "x": -1,
            "y": 0,
            "z": 8,
            "elements": [
                "botania:petalblock@0"
            ]
        },
        {
            "x": 0,
            "y": 0,
            "z": 8,
            "elements": [
                "botania:petalblock@0"
            ]
        },
        {
            "x": 1,
            "y": 0,
            "z": 8,
            "elements": [
                "botania:petalblock@0"
            ]
        },
        {
            "x": 2,
            "y": 0,
            "z": 8,
            "elements": [
                "botania:petalblock@0"
            ]
        },
        {
            "x": 3,
            "y": 0,
            "z": 8,
            "elements": [
                "botania:petalblock@0"
            ]
        },
        {
            "x": 4,
            "y": 0,
            "z": 8,
            "elements": [
                "botania:petalblock@0"
            ]
        },
        {
            "x": 5,
            "y": 0,
            "z": 8,
            "elements": [
                "botania:petalblock@0"
            ]
        },
        {
            "x": 6,
            "y": 0,
            "z": 8,
            "elements": [
                "botania:petalblock@0"
            ]
        },
        {
            "x": 7,
            "y": 0,
            "z": 8,
            "elements": [
                "botania:petalblock@0"
            ]
        },
        {
            "x": 7,
            "y": -2,
            "z": 7,
            "elements": [
                "botania:petalblock@8"
            ]
        },
        {
            "x": 7,
            "y": -4,
            "z": 6,
            "elements": [
                "minecraft:hardened_clay@0"
            ]
        },
        {
            "x": 7,
            "y": -6,
            "z": 5,
            "elements": [
                "minecraft:hardened_clay@0"
            ]
        },
        {
            "x": -6,
            "y": -1,
            "z": 7,
            "elements": [
                "botania:petalblock@0"
            ]
        },
        {
            "x": -6,
            "y": -3,
            "z": 6,
            "elements": [
                "minecraft:hardened_clay@0"
            ]
        },
        {
            "x": -6,
            "y": -5,
            "z": 5,
            "elements": [
                "minecraft:hardened_clay@0"
            ]
        },
        {
            "x": -6,
            "y": -7,
            "z": 4,
            "elements": [
                "botania:petalblock@12"
            ]
        },
        {
            "x": 7,
            "y": -1,
            "z": 7,
            "elements": [
                "botania:petalblock@0"
            ]
        },
        {
            "x": 7,
            "y": -3,
            "z": 6,
            "elements": [
                "minecraft:hardened_clay@0"
            ]
        },
        {
            "x": 7,
            "y": -5,
            "z": 5,
            "elements": [
                "minecraft:hardened_clay@0"
            ]
        },
        {
            "x": 7,
            "y": -7,
            "z": 4,
            "elements": [
                "botania:petalblock@12"
            ]
        },
        {
            "x": -6,
            "y": 0,
            "z": 7,
            "elements": [
                "botania:petalblock@0"
            ]
        },
        {
            "x": -6,
            "y": -2,
            "z": 6,
            "elements": [
                "botania:petalblock@8"
            ]
        },
        {
            "x": -5,
            "y": 0,
            "z": 7,
            "elements": [
                "botania:petalblock@0"
            ]
        },
        {
            "x": -6,
            "y": -4,
            "z": 5,
            "elements": [
                "minecraft:hardened_clay@0"
            ]
        },
        {
            "x": -4,
            "y": 0,
            "z": 7,
            "elements": [
                "botania:petalblock@0"
            ]
        },
        {
            "x": -6,
            "y": -6,
            "z": 4,
            "elements": [
                "minecraft:hardened_clay@0"
            ]
        },
        {
            "x": -3,
            "y": 0,
            "z": 7,
            "elements": [
                "botania:petalblock@0"
            ]
        },
        {
            "x": -2,
            "y": 0,
            "z": 7,
            "elements": [
                "botania:petalblock@0"
            ]
        },
        {
            "x": -1,
            "y": 0,
            "z": 7,
            "elements": [
                "botania:petalblock@0"
            ]
        },
        {
            "x": 0,
            "y": 0,
            "z": 7,
            "elements": [
                "botania:petalblock@14"
            ]
        },
        {
            "x": 1,
            "y": 0,
            "z": 7,
            "elements": [
                "botania:petalblock@14"
            ]
        },
        {
            "x": 2,
            "y": 0,
            "z": 7,
            "elements": [
                "botania:petalblock@0"
            ]
        },
        {
            "x": 3,
            "y": 0,
            "z": 7,
            "elements": [
                "botania:petalblock@0"
            ]
        },
        {
            "x": 4,
            "y": 0,
            "z": 7,
            "elements": [
                "botania:petalblock@0"
            ]
        },
        {
            "x": 5,
            "y": 0,
            "z": 7,
            "elements": [
                "botania:petalblock@0"
            ]
        },
        {
            "x": 6,
            "y": 0,
            "z": 7,
            "elements": [
                "botania:petalblock@14"
            ]
        },
        {
            "x": 7,
            "y": 0,
            "z": 7,
            "elements": [
                "botania:petalblock@0"
            ]
        },
        {
            "x": 7,
            "y": -2,
            "z": 6,
            "elements": [
                "botania:petalblock@8"
            ]
        },
        {
            "x": 7,
            "y": -4,
            "z": 5,
            "elements": [
                "minecraft:hardened_clay@0"
            ]
        },
        {
            "x": 7,
            "y": -6,
            "z": 4,
            "elements": [
                "minecraft:hardened_clay@0"
            ]
        },
        {
            "x": -6,
            "y": -1,
            "z": 6,
            "elements": [
                "botania:petalblock@0"
            ]
        },
        {
            "x": -6,
            "y": -3,
            "z": 5,
            "elements": [
                "botania:petalblock@8"
            ]
        },
        {
            "x": -6,
            "y": -5,
            "z": 4,
            "elements": [
                "minecraft:hardened_clay@0"
            ]
        },
        {
            "x": -6,
            "y": -7,
            "z": 3,
            "elements": [
                "botania:petalblock@12"
            ]
        },
        {
            "x": 7,
            "y": -1,
            "z": 6,
            "elements": [
                "botania:petalblock@0"
            ]
        },
        {
            "x": 7,
            "y": -3,
            "z": 5,
            "elements": [
                "botania:petalblock@8"
            ]
        },
        {
            "x": 7,
            "y": -5,
            "z": 4,
            "elements": [
                "minecraft:hardened_clay@0"
            ]
        },
        {
            "x": 7,
            "y": -7,
            "z": 3,
            "elements": [
                "botania:petalblock@12"
            ]
        },
        {
            "x": -6,
            "y": 0,
            "z": 6,
            "elements": [
                "botania:petalblock@0"
            ]
        },
        {
            "x": -6,
            "y": -2,
            "z": 5,
            "elements": [
                "botania:petalblock@0"
            ]
        },
        {
            "x": -5,
            "y": 0,
            "z": 6,
            "elements": [
                "botania:petalblock@0"
            ]
        },
        {
            "x": -6,
            "y": -4,
            "z": 4,
            "elements": [
                "minecraft:hardened_clay@0"
            ]
        },
        {
            "x": -4,
            "y": 0,
            "z": 6,
            "elements": [
                "botania:petalblock@14"
            ]
        },
        {
            "x": -6,
            "y": -6,
            "z": 3,
            "elements": [
                "minecraft:hardened_clay@0"
            ]
        },
        {
            "x": -3,
            "y": 0,
            "z": 6,
            "elements": [
                "botania:petalblock@14"
            ]
        },
        {
            "x": -2,
            "y": 0,
            "z": 6,
            "elements": [
                "botania:petalblock@0"
            ]
        },
        {
            "x": -1,
            "y": 0,
            "z": 6,
            "elements": [
                "botania:petalblock@0"
            ]
        },
        {
            "x": 0,
            "y": 0,
            "z": 6,
            "elements": [
                "botania:petalblock@14"
            ]
        },
        {
            "x": 1,
            "y": 0,
            "z": 6,
            "elements": [
                "botania:petalblock@14"
            ]
        },
        {
            "x": 2,
            "y": 0,
            "z": 6,
            "elements": [
                "botania:petalblock@0"
            ]
        },
        {
            "x": 3,
            "y": 0,
            "z": 6,
            "elements": [
                "botania:petalblock@0"
            ]
        },
        {
            "x": 4,
            "y": 0,
            "z": 6,
            "elements": [
                "botania:petalblock@0"
            ]
        },
        {
            "x": 5,
            "y": 0,
            "z": 6,
            "elements": [
                "botania:petalblock@0"
            ]
        },
        {
            "x": 6,
            "y": 0,
            "z": 6,
            "elements": [
                "botania:petalblock@0"
            ]
        },
        {
            "x": 7,
            "y": 0,
            "z": 6,
            "elements": [
                "botania:petalblock@0"
            ]
        },
        {
            "x": 7,
            "y": -2,
            "z": 5,
            "elements": [
                "botania:petalblock@0"
            ]
        },
        {
            "x": 7,
            "y": -4,
            "z": 4,
            "elements": [
                "minecraft:hardened_clay@0"
            ]
        },
        {
            "x": 7,
            "y": -6,
            "z": 3,
            "elements": [
                "minecraft:hardened_clay@0"
            ]
        },
        {
            "x": -6,
            "y": -1,
            "z": 5,
            "elements": [
                "botania:petalblock@0"
            ]
        },
        {
            "x": -6,
            "y": -3,
            "z": 4,
            "elements": [
                "botania:petalblock@8"
            ]
        },
        {
            "x": -6,
            "y": -5,
            "z": 3,
            "elements": [
                "minecraft:hardened_clay@0"
            ]
        },
        {
            "x": -6,
            "y": -7,
            "z": 2,
            "elements": [
                "botania:petalblock@12"
            ]
        },
        {
            "x": 7,
            "y": -1,
            "z": 5,
            "elements": [
                "botania:petalblock@0"
            ]
        },
        {
            "x": 7,
            "y": -3,
            "z": 4,
            "elements": [
                "botania:petalblock@8"
            ]
        },
        {
            "x": 7,
            "y": -5,
            "z": 3,
            "elements": [
                "minecraft:hardened_clay@0"
            ]
        },
        {
            "x": 7,
            "y": -7,
            "z": 2,
            "elements": [
                "botania:petalblock@12"
            ]
        },
        {
            "x": -6,
            "y": 0,
            "z": 5,
            "elements": [
                "botania:petalblock@0"
            ]
        },
        {
            "x": -6,
            "y": -2,
            "z": 4,
            "elements": [
                "botania:petalblock@0"
            ]
        },
        {
            "x": -5,
            "y": 0,
            "z": 5,
            "elements": [
                "botania:petalblock@0"
            ]
        },
        {
            "x": -6,
            "y": -4,
            "z": 3,
            "elements": [
                "minecraft:hardened_clay@0"
            ]
        },
        {
            "x": -4,
            "y": 0,
            "z": 5,
            "elements": [
                "botania:petalblock@14"
            ]
        },
        {
            "x": -6,
            "y": -6,
            "z": 2,
            "elements": [
                "minecraft:hardened_clay@0"
            ]
        },
        {
            "x": -3,
            "y": 0,
            "z": 5,
            "elements": [
                "botania:petalblock@14"
            ]
        },
        {
            "x": -2,
            "y": 0,
            "z": 5,
            "elements": [
                "botania:petalblock@0"
            ]
        },
        {
            "x": -1,
            "y": 0,
            "z": 5,
            "elements": [
                "botania:petalblock@0"
            ]
        },
        {
            "x": 0,
            "y": 0,
            "z": 5,
            "elements": [
                "botania:petalblock@0"
            ]
        },
        {
            "x": 1,
            "y": 0,
            "z": 5,
            "elements": [
                "botania:petalblock@0"
            ]
        },
        {
            "x": 2,
            "y": 0,
            "z": 5,
            "elements": [
                "botania:petalblock@0"
            ]
        },
        {
            "x": 3,
            "y": 0,
            "z": 5,
            "elements": [
                "botania:petalblock@0"
            ]
        },
        {
            "x": 4,
            "y": 0,
            "z": 5,
            "elements": [
                "botania:petalblock@14"
            ]
        },
        {
            "x": 5,
            "y": 0,
            "z": 5,
            "elements": [
                "botania:petalblock@0"
            ]
        },
        {
            "x": 6,
            "y": 0,
            "z": 5,
            "elements": [
                "botania:petalblock@0"
            ]
        },
        {
            "x": 7,
            "y": 0,
            "z": 5,
            "elements": [
                "botania:petalblock@0"
            ]
        },
        {
            "x": 7,
            "y": -2,
            "z": 4,
            "elements": [
                "botania:petalblock@0"
            ]
        },
        {
            "x": 7,
            "y": -4,
            "z": 3,
            "elements": [
                "minecraft:hardened_clay@0"
            ]
        },
        {
            "x": 7,
            "y": -6,
            "z": 2,
            "elements": [
                "minecraft:hardened_clay@0"
            ]
        },
        {
            "x": -6,
            "y": -1,
            "z": 4,
            "elements": [
                "botania:petalblock@0"
            ]
        },
        {
            "x": -6,
            "y": -3,
            "z": 3,
            "elements": [
                "minecraft:hardened_clay@0"
            ]
        },
        {
            "x": -6,
            "y": -5,
            "z": 2,
            "elements": [
                "minecraft:hardened_clay@0"
            ]
        },
        {
            "x": -6,
            "y": -7,
            "z": 1,
            "elements": [
                "botania:petalblock@12"
            ]
        },
        {
            "x": 7,
            "y": -1,
            "z": 4,
            "elements": [
                "botania:petalblock@0"
            ]
        },
        {
            "x": 7,
            "y": -3,
            "z": 3,
            "elements": [
                "minecraft:hardened_clay@0"
            ]
        },
        {
            "x": 7,
            "y": -5,
            "z": 2,
            "elements": [
                "minecraft:hardened_clay@0"
            ]
        },
        {
            "x": 7,
            "y": -7,
            "z": 1,
            "elements": [
                "botania:petalblock@12"
            ]
        },
        {
            "x": -6,
            "y": 0,
            "z": 4,
            "elements": [
                "botania:petalblock@0"
            ]
        },
        {
            "x": -6,
            "y": -2,
            "z": 3,
            "elements": [
                "botania:petalblock@8"
            ]
        },
        {
            "x": -5,
            "y": 0,
            "z": 4,
            "elements": [
                "botania:petalblock@0"
            ]
        },
        {
            "x": -6,
            "y": -4,
            "z": 2,
            "elements": [
                "minecraft:hardened_clay@0"
            ]
        },
        {
            "x": -4,
            "y": 0,
            "z": 4,
            "elements": [
                "botania:petalblock@0"
            ]
        },
        {
            "x": -6,
            "y": -6,
            "z": 1,
            "elements": [
                "minecraft:hardened_clay@0"
            ]
        },
        {
            "x": -3,
            "y": 0,
            "z": 4,
            "elements": [
                "botania:petalblock@0"
            ]
        },
        {
            "x": -2,
            "y": 0,
            "z": 4,
            "elements": [
                "botania:petalblock@0"
            ]
        },
        {
            "x": -1,
            "y": 0,
            "z": 4,
            "elements": [
                "botania:petalblock@0"
            ]
        },
        {
            "x": 0,
            "y": 0,
            "z": 4,
            "elements": [
                "botania:petalblock@0"
            ]
        },
        {
            "x": 1,
            "y": 0,
            "z": 4,
            "elements": [
                "botania:petalblock@0"
            ]
        },
        {
            "x": 2,
            "y": 0,
            "z": 4,
            "elements": [
                "botania:petalblock@0"
            ]
        },
        {
            "x": 3,
            "y": 0,
            "z": 4,
            "elements": [
                "botania:petalblock@0"
            ]
        },
        {
            "x": 4,
            "y": 0,
            "z": 4,
            "elements": [
                "botania:petalblock@0"
            ]
        },
        {
            "x": 5,
            "y": 0,
            "z": 4,
            "elements": [
                "botania:petalblock@0"
            ]
        },
        {
            "x": 6,
            "y": 0,
            "z": 4,
            "elements": [
                "botania:petalblock@0"
            ]
        },
        {
            "x": 7,
            "y": 0,
            "z": 4,
            "elements": [
                "botania:petalblock@0"
            ]
        },
        {
            "x": 7,
            "y": -2,
            "z": 3,
            "elements": [
                "botania:petalblock@8"
            ]
        },
        {
            "x": 7,
            "y": -4,
            "z": 2,
            "elements": [
                "minecraft:hardened_clay@0"
            ]
        },
        {
            "x": 7,
            "y": -6,
            "z": 1,
            "elements": [
                "minecraft:hardened_clay@0"
            ]
        },
        {
            "x": -6,
            "y": -1,
            "z": 3,
            "elements": [
                "botania:petalblock@0"
            ]
        },
        {
            "x": -6,
            "y": -3,
            "z": 2,
            "elements": [
                "minecraft:hardened_clay@0"
            ]
        },
        {
            "x": -6,
            "y": -5,
            "z": 1,
            "elements": [
                "minecraft:hardened_clay@0"
            ]
        },
        {
            "x": 7,
            "y": -1,
            "z": 3,
            "elements": [
                "botania:petalblock@0"
            ]
        },
        {
            "x": 7,
            "y": -3,
            "z": 2,
            "elements": [
                "minecraft:hardened_clay@0"
            ]
        },
        {
            "x": 7,
            "y": -5,
            "z": 1,
            "elements": [
                "minecraft:hardened_clay@0"
            ]
        },
        {
            "x": -6,
            "y": 0,
            "z": 3,
            "elements": [
                "botania:petalblock@0"
            ]
        },
        {
            "x": -6,
            "y": -2,
            "z": 2,
            "elements": [
                "botania:petalblock@8"
            ]
        },
        {
            "x": -5,
            "y": 0,
            "z": 3,
            "elements": [
                "botania:petalblock@0"
            ]
        },
        {
            "x": -6,
            "y": -4,
            "z": 1,
            "elements": [
                "minecraft:hardened_clay@0"
            ]
        },
        {
            "x": -4,
            "y": 0,
            "z": 3,
            "elements": [
                "botania:petalblock@0"
            ]
        },
        {
            "x": -3,
            "y": 0,
            "z": 3,
            "elements": [
                "botania:petalblock@0"
            ]
        },
        {
            "x": -2,
            "y": 0,
            "z": 3,
            "elements": [
                "botania:petalblock@0"
            ]
        },
        {
            "x": -1,
            "y": 0,
            "z": 3,
            "elements": [
                "botania:petalblock@14"
            ]
        },
        {
            "x": 0,
            "y": 0,
            "z": 3,
            "elements": [
                "botania:petalblock@14"
            ]
        },
        {
            "x": 1,
            "y": 0,
            "z": 3,
            "elements": [
                "botania:petalblock@0"
            ]
        },
        {
            "x": 2,
            "y": 0,
            "z": 3,
            "elements": [
                "botania:petalblock@0"
            ]
        },
        {
            "x": 3,
            "y": 0,
            "z": 3,
            "elements": [
                "botania:petalblock@0"
            ]
        },
        {
            "x": 4,
            "y": 0,
            "z": 3,
            "elements": [
                "botania:petalblock@0"
            ]
        },
        {
            "x": 5,
            "y": 0,
            "z": 3,
            "elements": [
                "botania:petalblock@0"
            ]
        },
        {
            "x": 6,
            "y": 0,
            "z": 3,
            "elements": [
                "botania:petalblock@0"
            ]
        },
        {
            "x": 7,
            "y": 0,
            "z": 3,
            "elements": [
                "botania:petalblock@0"
            ]
        },
        {
            "x": 7,
            "y": -2,
            "z": 2,
            "elements": [
                "botania:petalblock@8"
            ]
        },
        {
            "x": 7,
            "y": -4,
            "z": 1,
            "elements": [
                "minecraft:hardened_clay@0"
            ]
        },
        {
            "x": -6,
            "y": -1,
            "z": 2,
            "elements": [
                "botania:petalblock@0"
            ]
        },
        {
            "x": -6,
            "y": -3,
            "z": 1,
            "elements": [
                "botania:petalblock@8"
            ]
        },
        {
            "x": 7,
            "y": -1,
            "z": 2,
            "elements": [
                "botania:petalblock@0"
            ]
        },
        {
            "x": 7,
            "y": -3,
            "z": 1,
            "elements": [
                "botania:petalblock@8"
            ]
        },
        {
            "x": -6,
            "y": 0,
            "z": 2,
            "elements": [
                "botania:petalblock@0"
            ]
        },
        {
            "x": -6,
            "y": -2,
            "z": 1,
            "elements": [
                "botania:petalblock@0"
            ]
        },
        {
            "x": -5,
            "y": 0,
            "z": 2,
            "elements": [
                "botania:petalblock@0"
            ]
        },
        {
            "x": -4,
            "y": 0,
            "z": 2,
            "elements": [
                "botania:petalblock@0"
            ]
        },
        {
            "x": -3,
            "y": 0,
            "z": 2,
            "elements": [
                "botania:petalblock@0"
            ]
        },
        {
            "x": -2,
            "y": 0,
            "z": 2,
            "elements": [
                "botania:petalblock@0"
            ]
        },
        {
            "x": -1,
            "y": 0,
            "z": 2,
            "elements": [
                "botania:petalblock@14"
            ]
        },
        {
            "x": 0,
            "y": 0,
            "z": 2,
            "elements": [
                "botania:petalblock@14"
            ]
        },
        {
            "x": 1,
            "y": 0,
            "z": 2,
            "elements": [
                "botania:petalblock@0"
            ]
        },
        {
            "x": 2,
            "y": 0,
            "z": 2,
            "elements": [
                "botania:petalblock@0"
            ]
        },
        {
            "x": 3,
            "y": 0,
            "z": 2,
            "elements": [
                "botania:petalblock@0"
            ]
        },
        {
            "x": 4,
            "y": 0,
            "z": 2,
            "elements": [
                "botania:petalblock@0"
            ]
        },
        {
            "x": 5,
            "y": 0,
            "z": 2,
            "elements": [
                "botania:petalblock@0"
            ]
        },
        {
            "x": 6,
            "y": 0,
            "z": 2,
            "elements": [
                "botania:petalblock@0"
            ]
        },
        {
            "x": 7,
            "y": 0,
            "z": 2,
            "elements": [
                "botania:petalblock@0"
            ]
        },
        {
            "x": 7,
            "y": -2,
            "z": 1,
            "elements": [
                "botania:petalblock@0"
            ]
        },
        {
            "x": -6,
            "y": -1,
            "z": 1,
            "elements": [
                "botania:petalblock@0"
            ]
        },
        {
            "x": 7,
            "y": -1,
            "z": 1,
            "elements": [
                "botania:petalblock@0"
            ]
        },
        {
            "x": -6,
            "y": 0,
            "z": 1,
            "elements": [
                "botania:petalblock@0"
            ]
        },
        {
            "x": -5,
            "y": 0,
            "z": 1,
            "elements": [
                "botania:petalblock@0"
            ]
        },
        {
            "x": -4,
            "y": 0,
            "z": 1,
            "elements": [
                "botania:petalblock@0"
            ]
        },
        {
            "x": -3,
            "y": 0,
            "z": 1,
            "elements": [
                "botania:petalblock@0"
            ]
        },
        {
            "x": -2,
            "y": 0,
            "z": 1,
            "elements": [
                "botania:petalblock@0"
            ]
        },
        {
            "x": -1,
            "y": 0,
            "z": 1,
            "elements": [
                "botania:petalblock@0"
            ]
        },
        {
            "x": 0,
            "y": 0,
            "z": 1,
            "elements": [
                "botania:petalblock@0"
            ]
        },
        {
            "x": 1,
            "y": 0,
            "z": 1,
            "elements": [
                "botania:petalblock@0"
            ]
        },
        {
            "x": 2,
            "y": 0,
            "z": 1,
            "elements": [
                "botania:petalblock@0"
            ]
        },
        {
            "x": 3,
            "y": 0,
            "z": 1,
            "elements": [
                "botania:petalblock@0"
            ]
        },
        {
            "x": 4,
            "y": 0,
            "z": 1,
            "elements": [
                "botania:petalblock@0"
            ]
        },
        {
            "x": 5,
            "y": 0,
            "z": 1,
            "elements": [
                "botania:petalblock@14"
            ]
        },
        {
            "x": 6,
            "y": 0,
            "z": 1,
            "elements": [
                "botania:petalblock@0"
            ]
        },
        {
            "x": 7,
            "y": 0,
            "z": 1,
            "elements": [
                "botania:petalblock@0"
            ]
        },
        {
            "x": -6,
            "y": -7,
            "z": 13,
            "elements": [
                "botania:petalblock@12"
            ]
        },
        {
            "x": -5,
            "y": -7,
            "z": 13,
            "elements": [
                "botania:petalblock@12"
            ]
        },
        {
            "x": -4,
            "y": -7,
            "z": 13,
            "elements": [
                "botania:petalblock@12"
            ]
        },
        {
            "x": -3,
            "y": -7,
            "z": 13,
            "elements": [
                "botania:petalblock@12"
            ]
        },
        {
            "x": -2,
            "y": -7,
            "z": 13,
            "elements": [
                "botania:petalblock@12"
            ]
        },
        {
            "x": -1,
            "y": -7,
            "z": 13,
            "elements": [
                "botania:petalblock@12"
            ]
        },
        {
            "x": 0,
            "y": -7,
            "z": 13,
            "elements": [
                "botania:petalblock@12"
            ]
        },
        {
            "x": 1,
            "y": -7,
            "z": 13,
            "elements": [
                "botania:petalblock@12"
            ]
        },
        {
            "x": 2,
            "y": -7,
            "z": 13,
            "elements": [
                "botania:petalblock@12"
            ]
        },
        {
            "x": 3,
            "y": -7,
            "z": 13,
            "elements": [
                "botania:petalblock@12"
            ]
        },
        {
            "x": 4,
            "y": -7,
            "z": 13,
            "elements": [
                "botania:petalblock@12"
            ]
        },
        {
            "x": 5,
            "y": -7,
            "z": 13,
            "elements": [
                "botania:petalblock@12"
            ]
        },
        {
            "x": 6,
            "y": -7,
            "z": 13,
            "elements": [
                "botania:petalblock@12"
            ]
        },
        {
            "x": 7,
            "y": -7,
            "z": 13,
            "elements": [
                "botania:petalblock@12"
            ]
        }
    ]}